


Start downloading works_by_ids in 4 thread(s) at [Fri Mar 29 09:35:39 2024]



[Fri Mar 29 09:35:39 2024] Problem with adding article with id = W2477573939
Traceback (most recent call last):
  File "c:\users\asus\onedrive\документы\github\articles-analysis\programs\downloading_referenced_works.py", line 383, in download_work_by_id
    cursor.execute(f"""
sqlite3.IntegrityError: UNIQUE constraint failed: articles.id

[Fri Mar 29 09:35:39 2024] Problem with adding article with id = W2561493030
Traceback (most recent call last):
  File "c:\users\asus\onedrive\документы\github\articles-analysis\programs\downloading_referenced_works.py", line 383, in download_work_by_id
    cursor.execute(f"""
sqlite3.IntegrityError: UNIQUE constraint failed: articles.id

[Fri Mar 29 09:35:39 2024] Problem with adding article with id = W3147328630
Traceback (most recent call last):
  File "c:\users\asus\onedrive\документы\github\articles-analysis\programs\downloading_referenced_works.py", line 383, in download_work_by_id
    cursor.execute(f"""
sqlite3.IntegrityError: UNIQUE constraint failed: articles.id

[Fri Mar 29 09:35:39 2024] Problem with adding article with id = W2787340887
Traceback (most recent call last):
  File "c:\users\asus\onedrive\документы\github\articles-analysis\programs\downloading_referenced_works.py", line 383, in download_work_by_id
    cursor.execute(f"""
sqlite3.IntegrityError: UNIQUE constraint failed: articles.id

[Fri Mar 29 09:35:40 2024] Problem with getting article with id = W2027637594
urllib3.exceptions.ResponseError: too many 429 error responses

The above exception was the direct cause of the following exception:

Traceback (most recent call last):
  File "C:\Users\Asus\AppData\Local\Programs\Spyder\pkgs\requests\adapters.py", line 486, in send
    resp = conn.urlopen(
  File "C:\Users\Asus\AppData\Local\Programs\Spyder\pkgs\urllib3\connectionpool.py", line 938, in urlopen
    retries = retries.increment(method, url, response=response, _pool=self)
  File "C:\Users\Asus\AppData\Local\Programs\Spyder\pkgs\urllib3\util\retry.py", line 515, in increment
    raise MaxRetryError(_pool, url, reason) from reason  # type: ignore[arg-type]
urllib3.exceptions.MaxRetryError: HTTPSConnectionPool(host='api.openalex.org', port=443): Max retries exceeded with url: /works/W2027637594 (Caused by ResponseError('too many 429 error responses'))

During handling of the above exception, another exception occurred:

Traceback (most recent call last):
  File "c:\users\asus\onedrive\документы\github\articles-analysis\programs\downloading_referenced_works.py", line 357, in download_work_by_id
    work = Works()[id_]
  File "C:\Users\Asus\AppData\Local\Programs\Spyder\Python\lib\site-packages\pyalex\api.py", line 225, in __getitem__
    return self._get_from_url(
  File "C:\Users\Asus\AppData\Local\Programs\Spyder\Python\lib\site-packages\pyalex\api.py", line 257, in _get_from_url
    res = _get_requests_session().get(url, auth=OpenAlexAuth(config))
  File "C:\Users\Asus\AppData\Local\Programs\Spyder\pkgs\requests\sessions.py", line 602, in get
    return self.request("GET", url, **kwargs)
  File "C:\Users\Asus\AppData\Local\Programs\Spyder\pkgs\requests\sessions.py", line 589, in request
    resp = self.send(prep, **send_kwargs)
  File "C:\Users\Asus\AppData\Local\Programs\Spyder\pkgs\requests\sessions.py", line 703, in send
    r = adapter.send(request, **kwargs)
  File "C:\Users\Asus\AppData\Local\Programs\Spyder\pkgs\requests\adapters.py", line 510, in send
    raise RetryError(e, request=request)
requests.exceptions.RetryError: HTTPSConnectionPool(host='api.openalex.org', port=443): Max retries exceeded with url: /works/W2027637594 (Caused by ResponseError('too many 429 error responses'))

[Fri Mar 29 09:35:40 2024] Problem with getting article with id = W1515875011
urllib3.exceptions.ResponseError: too many 429 error responses

The above exception was the direct cause of the following exception:

Traceback (most recent call last):
  File "C:\Users\Asus\AppData\Local\Programs\Spyder\pkgs\requests\adapters.py", line 486, in send
    resp = conn.urlopen(
  File "C:\Users\Asus\AppData\Local\Programs\Spyder\pkgs\urllib3\connectionpool.py", line 938, in urlopen
    retries = retries.increment(method, url, response=response, _pool=self)
  File "C:\Users\Asus\AppData\Local\Programs\Spyder\pkgs\urllib3\util\retry.py", line 515, in increment
    raise MaxRetryError(_pool, url, reason) from reason  # type: ignore[arg-type]
urllib3.exceptions.MaxRetryError: HTTPSConnectionPool(host='api.openalex.org', port=443): Max retries exceeded with url: /works/W1515875011 (Caused by ResponseError('too many 429 error responses'))

During handling of the above exception, another exception occurred:

Traceback (most recent call last):
  File "c:\users\asus\onedrive\документы\github\articles-analysis\programs\downloading_referenced_works.py", line 357, in download_work_by_id
    work = Works()[id_]
  File "C:\Users\Asus\AppData\Local\Programs\Spyder\Python\lib\site-packages\pyalex\api.py", line 225, in __getitem__
    return self._get_from_url(
  File "C:\Users\Asus\AppData\Local\Programs\Spyder\Python\lib\site-packages\pyalex\api.py", line 257, in _get_from_url
    res = _get_requests_session().get(url, auth=OpenAlexAuth(config))
  File "C:\Users\Asus\AppData\Local\Programs\Spyder\pkgs\requests\sessions.py", line 602, in get
    return self.request("GET", url, **kwargs)
  File "C:\Users\Asus\AppData\Local\Programs\Spyder\pkgs\requests\sessions.py", line 589, in request
    resp = self.send(prep, **send_kwargs)
  File "C:\Users\Asus\AppData\Local\Programs\Spyder\pkgs\requests\sessions.py", line 703, in send
    r = adapter.send(request, **kwargs)
  File "C:\Users\Asus\AppData\Local\Programs\Spyder\pkgs\requests\adapters.py", line 510, in send
    raise RetryError(e, request=request)
requests.exceptions.RetryError: HTTPSConnectionPool(host='api.openalex.org', port=443): Max retries exceeded with url: /works/W1515875011 (Caused by ResponseError('too many 429 error responses'))

[Fri Mar 29 09:35:40 2024] Problem with adding article with id = W2461965465
Traceback (most recent call last):
  File "c:\users\asus\onedrive\документы\github\articles-analysis\programs\downloading_referenced_works.py", line 383, in download_work_by_id
    cursor.execute(f"""
sqlite3.IntegrityError: UNIQUE constraint failed: articles.id

[Fri Mar 29 09:35:40 2024] Problem with adding article with id = W2493980134
Traceback (most recent call last):
  File "c:\users\asus\onedrive\документы\github\articles-analysis\programs\downloading_referenced_works.py", line 383, in download_work_by_id
    cursor.execute(f"""
sqlite3.IntegrityError: UNIQUE constraint failed: articles.id

[Fri Mar 29 09:35:41 2024] Problem with adding article with id = W2511216682
Traceback (most recent call last):
  File "c:\users\asus\onedrive\документы\github\articles-analysis\programs\downloading_referenced_works.py", line 383, in download_work_by_id
    cursor.execute(f"""
sqlite3.IntegrityError: UNIQUE constraint failed: articles.id

[Fri Mar 29 09:35:41 2024] Problem with adding article with id = W2189413629
Traceback (most recent call last):
  File "c:\users\asus\onedrive\документы\github\articles-analysis\programs\downloading_referenced_works.py", line 383, in download_work_by_id
    cursor.execute(f"""
sqlite3.IntegrityError: UNIQUE constraint failed: articles.id

[Fri Mar 29 09:35:41 2024] Problem with adding article with id = W2523799298
Traceback (most recent call last):
  File "c:\users\asus\onedrive\документы\github\articles-analysis\programs\downloading_referenced_works.py", line 383, in download_work_by_id
    cursor.execute(f"""
sqlite3.IntegrityError: UNIQUE constraint failed: articles.id

[Fri Mar 29 09:35:41 2024] Problem with adding article with id = W1593439217
Traceback (most recent call last):
  File "c:\users\asus\onedrive\документы\github\articles-analysis\programs\downloading_referenced_works.py", line 383, in download_work_by_id
    cursor.execute(f"""
sqlite3.IntegrityError: UNIQUE constraint failed: articles.id

[Fri Mar 29 09:35:42 2024] Problem with adding article with id = W2140575920
Traceback (most recent call last):
  File "c:\users\asus\onedrive\документы\github\articles-analysis\programs\downloading_referenced_works.py", line 383, in download_work_by_id
    cursor.execute(f"""
sqlite3.IntegrityError: UNIQUE constraint failed: articles.id

[Fri Mar 29 09:35:42 2024] Problem with adding article with id = W2489664852
Traceback (most recent call last):
  File "c:\users\asus\onedrive\документы\github\articles-analysis\programs\downloading_referenced_works.py", line 383, in download_work_by_id
    cursor.execute(f"""
sqlite3.IntegrityError: UNIQUE constraint failed: articles.id

[Fri Mar 29 09:35:42 2024] Problem with adding article with id = W2475131279
Traceback (most recent call last):
  File "c:\users\asus\onedrive\документы\github\articles-analysis\programs\downloading_referenced_works.py", line 383, in download_work_by_id
    cursor.execute(f"""
sqlite3.IntegrityError: UNIQUE constraint failed: articles.id

[Fri Mar 29 09:35:42 2024] Problem with adding article with id = W2061603740
Traceback (most recent call last):
  File "c:\users\asus\onedrive\документы\github\articles-analysis\programs\downloading_referenced_works.py", line 383, in download_work_by_id
    cursor.execute(f"""
sqlite3.IntegrityError: UNIQUE constraint failed: articles.id

[Fri Mar 29 09:35:42 2024] Problem with getting article with id = W2498149278
urllib3.exceptions.ResponseError: too many 429 error responses

The above exception was the direct cause of the following exception:

Traceback (most recent call last):
  File "C:\Users\Asus\AppData\Local\Programs\Spyder\pkgs\requests\adapters.py", line 486, in send
    resp = conn.urlopen(
  File "C:\Users\Asus\AppData\Local\Programs\Spyder\pkgs\urllib3\connectionpool.py", line 938, in urlopen
    retries = retries.increment(method, url, response=response, _pool=self)
  File "C:\Users\Asus\AppData\Local\Programs\Spyder\pkgs\urllib3\util\retry.py", line 515, in increment
    raise MaxRetryError(_pool, url, reason) from reason  # type: ignore[arg-type]
urllib3.exceptions.MaxRetryError: HTTPSConnectionPool(host='api.openalex.org', port=443): Max retries exceeded with url: /works/W4285719527 (Caused by ResponseError('too many 429 error responses'))

During handling of the above exception, another exception occurred:

Traceback (most recent call last):
  File "c:\users\asus\onedrive\документы\github\articles-analysis\programs\downloading_referenced_works.py", line 357, in download_work_by_id
    work = Works()[id_]
  File "C:\Users\Asus\AppData\Local\Programs\Spyder\Python\lib\site-packages\pyalex\api.py", line 225, in __getitem__
    return self._get_from_url(
  File "C:\Users\Asus\AppData\Local\Programs\Spyder\Python\lib\site-packages\pyalex\api.py", line 257, in _get_from_url
    res = _get_requests_session().get(url, auth=OpenAlexAuth(config))
  File "C:\Users\Asus\AppData\Local\Programs\Spyder\pkgs\requests\sessions.py", line 602, in get
    return self.request("GET", url, **kwargs)
  File "C:\Users\Asus\AppData\Local\Programs\Spyder\pkgs\requests\sessions.py", line 589, in request
    resp = self.send(prep, **send_kwargs)
  File "C:\Users\Asus\AppData\Local\Programs\Spyder\pkgs\requests\sessions.py", line 725, in send
    history = [resp for resp in gen]
  File "C:\Users\Asus\AppData\Local\Programs\Spyder\pkgs\requests\sessions.py", line 725, in <listcomp>
    history = [resp for resp in gen]
  File "C:\Users\Asus\AppData\Local\Programs\Spyder\pkgs\requests\sessions.py", line 266, in resolve_redirects
    resp = self.send(
  File "C:\Users\Asus\AppData\Local\Programs\Spyder\pkgs\requests\sessions.py", line 703, in send
    r = adapter.send(request, **kwargs)
  File "C:\Users\Asus\AppData\Local\Programs\Spyder\pkgs\requests\adapters.py", line 510, in send
    raise RetryError(e, request=request)
requests.exceptions.RetryError: HTTPSConnectionPool(host='api.openalex.org', port=443): Max retries exceeded with url: /works/W4285719527 (Caused by ResponseError('too many 429 error responses'))

[Fri Mar 29 09:35:43 2024] Problem with adding article with id = W2494569332
Traceback (most recent call last):
  File "c:\users\asus\onedrive\документы\github\articles-analysis\programs\downloading_referenced_works.py", line 383, in download_work_by_id
    cursor.execute(f"""
sqlite3.IntegrityError: UNIQUE constraint failed: articles.id

[Fri Mar 29 09:35:43 2024] Problem with adding article with id = W3150313206
Traceback (most recent call last):
  File "c:\users\asus\onedrive\документы\github\articles-analysis\programs\downloading_referenced_works.py", line 383, in download_work_by_id
    cursor.execute(f"""
sqlite3.IntegrityError: UNIQUE constraint failed: articles.id

[Fri Mar 29 09:35:43 2024] Problem with adding article with id = W2233585419
Traceback (most recent call last):
  File "c:\users\asus\onedrive\документы\github\articles-analysis\programs\downloading_referenced_works.py", line 383, in download_work_by_id
    cursor.execute(f"""
sqlite3.IntegrityError: UNIQUE constraint failed: articles.id

[Fri Mar 29 09:35:43 2024] Problem with adding article with id = W2963343006
Traceback (most recent call last):
  File "c:\users\asus\onedrive\документы\github\articles-analysis\programs\downloading_referenced_works.py", line 383, in download_work_by_id
    cursor.execute(f"""
sqlite3.IntegrityError: UNIQUE constraint failed: articles.id

[Fri Mar 29 09:35:43 2024] Problem with adding article with id = W2462377275
Traceback (most recent call last):
  File "c:\users\asus\onedrive\документы\github\articles-analysis\programs\downloading_referenced_works.py", line 383, in download_work_by_id
    cursor.execute(f"""
sqlite3.IntegrityError: UNIQUE constraint failed: articles.id

[Fri Mar 29 09:35:44 2024] Problem with adding article with id = W304688757
Traceback (most recent call last):
  File "c:\users\asus\onedrive\документы\github\articles-analysis\programs\downloading_referenced_works.py", line 383, in download_work_by_id
    cursor.execute(f"""
sqlite3.IntegrityError: UNIQUE constraint failed: articles.id

[Fri Mar 29 09:35:44 2024] Problem with adding article with id = W2503658146
Traceback (most recent call last):
  File "c:\users\asus\onedrive\документы\github\articles-analysis\programs\downloading_referenced_works.py", line 383, in download_work_by_id
    cursor.execute(f"""
sqlite3.IntegrityError: UNIQUE constraint failed: articles.id

[Fri Mar 29 09:35:44 2024] Problem with adding article with id = W264180933
Traceback (most recent call last):
  File "c:\users\asus\onedrive\документы\github\articles-analysis\programs\downloading_referenced_works.py", line 383, in download_work_by_id
    cursor.execute(f"""
sqlite3.IntegrityError: UNIQUE constraint failed: articles.id

[Fri Mar 29 09:35:44 2024] Problem with adding article with id = W2524230988
Traceback (most recent call last):
  File "c:\users\asus\onedrive\документы\github\articles-analysis\programs\downloading_referenced_works.py", line 383, in download_work_by_id
    cursor.execute(f"""
sqlite3.IntegrityError: UNIQUE constraint failed: articles.id

[Fri Mar 29 09:35:44 2024] Problem with adding article with id = W2552219910
Traceback (most recent call last):
  File "c:\users\asus\onedrive\документы\github\articles-analysis\programs\downloading_referenced_works.py", line 383, in download_work_by_id
    cursor.execute(f"""
sqlite3.IntegrityError: UNIQUE constraint failed: articles.id

[Fri Mar 29 09:35:45 2024] Problem with adding article with id = W3148050337
Traceback (most recent call last):
  File "c:\users\asus\onedrive\документы\github\articles-analysis\programs\downloading_referenced_works.py", line 383, in download_work_by_id
    cursor.execute(f"""
sqlite3.IntegrityError: UNIQUE constraint failed: articles.id

[Fri Mar 29 09:35:45 2024] Problem with adding article with id = W174935651
Traceback (most recent call last):
  File "c:\users\asus\onedrive\документы\github\articles-analysis\programs\downloading_referenced_works.py", line 383, in download_work_by_id
    cursor.execute(f"""
sqlite3.IntegrityError: UNIQUE constraint failed: articles.id

[Fri Mar 29 09:35:45 2024] Problem with adding article with id = W3144705666
Traceback (most recent call last):
  File "c:\users\asus\onedrive\документы\github\articles-analysis\programs\downloading_referenced_works.py", line 383, in download_work_by_id
    cursor.execute(f"""
sqlite3.IntegrityError: UNIQUE constraint failed: articles.id

[Fri Mar 29 09:35:45 2024] Problem with adding article with id = W2525564926
Traceback (most recent call last):
  File "c:\users\asus\onedrive\документы\github\articles-analysis\programs\downloading_referenced_works.py", line 383, in download_work_by_id
    cursor.execute(f"""
sqlite3.IntegrityError: UNIQUE constraint failed: articles.id

[Fri Mar 29 09:35:45 2024] Problem with adding article with id = W2718850971
Traceback (most recent call last):
  File "c:\users\asus\onedrive\документы\github\articles-analysis\programs\downloading_referenced_works.py", line 383, in download_work_by_id
    cursor.execute(f"""
sqlite3.IntegrityError: UNIQUE constraint failed: articles.id

[Fri Mar 29 09:35:46 2024] Problem with getting article with id = W1805198230
Traceback (most recent call last):
  File "c:\users\asus\onedrive\документы\github\articles-analysis\programs\downloading_referenced_works.py", line 357, in download_work_by_id
    work = Works()[id_]
  File "C:\Users\Asus\AppData\Local\Programs\Spyder\Python\lib\site-packages\pyalex\api.py", line 225, in __getitem__
    return self._get_from_url(
  File "C:\Users\Asus\AppData\Local\Programs\Spyder\Python\lib\site-packages\pyalex\api.py", line 267, in _get_from_url
    res.raise_for_status()
  File "C:\Users\Asus\AppData\Local\Programs\Spyder\pkgs\requests\models.py", line 1021, in raise_for_status
    raise HTTPError(http_error_msg, response=self)
requests.exceptions.HTTPError: 404 Client Error: NOT FOUND for url: https://api.openalex.org/works/W1805198230

[Fri Mar 29 09:35:46 2024] Problem with adding article with id = W1785356470
Traceback (most recent call last):
  File "c:\users\asus\onedrive\документы\github\articles-analysis\programs\downloading_referenced_works.py", line 383, in download_work_by_id
    cursor.execute(f"""
sqlite3.IntegrityError: UNIQUE constraint failed: articles.id

[Fri Mar 29 09:35:46 2024] Problem with adding article with id = W2491008898
Traceback (most recent call last):
  File "c:\users\asus\onedrive\документы\github\articles-analysis\programs\downloading_referenced_works.py", line 383, in download_work_by_id
    cursor.execute(f"""
sqlite3.IntegrityError: UNIQUE constraint failed: articles.id

[Fri Mar 29 09:35:47 2024] Problem with getting article with id = W3023071679
urllib3.exceptions.ResponseError: too many 429 error responses

The above exception was the direct cause of the following exception:

Traceback (most recent call last):
  File "C:\Users\Asus\AppData\Local\Programs\Spyder\pkgs\requests\adapters.py", line 486, in send
    resp = conn.urlopen(
  File "C:\Users\Asus\AppData\Local\Programs\Spyder\pkgs\urllib3\connectionpool.py", line 938, in urlopen
    retries = retries.increment(method, url, response=response, _pool=self)
  File "C:\Users\Asus\AppData\Local\Programs\Spyder\pkgs\urllib3\util\retry.py", line 515, in increment
    raise MaxRetryError(_pool, url, reason) from reason  # type: ignore[arg-type]
urllib3.exceptions.MaxRetryError: HTTPSConnectionPool(host='api.openalex.org', port=443): Max retries exceeded with url: /works/W2079735306 (Caused by ResponseError('too many 429 error responses'))

During handling of the above exception, another exception occurred:

Traceback (most recent call last):
  File "c:\users\asus\onedrive\документы\github\articles-analysis\programs\downloading_referenced_works.py", line 357, in download_work_by_id
    work = Works()[id_]
  File "C:\Users\Asus\AppData\Local\Programs\Spyder\Python\lib\site-packages\pyalex\api.py", line 225, in __getitem__
    return self._get_from_url(
  File "C:\Users\Asus\AppData\Local\Programs\Spyder\Python\lib\site-packages\pyalex\api.py", line 257, in _get_from_url
    res = _get_requests_session().get(url, auth=OpenAlexAuth(config))
  File "C:\Users\Asus\AppData\Local\Programs\Spyder\pkgs\requests\sessions.py", line 602, in get
    return self.request("GET", url, **kwargs)
  File "C:\Users\Asus\AppData\Local\Programs\Spyder\pkgs\requests\sessions.py", line 589, in request
    resp = self.send(prep, **send_kwargs)
  File "C:\Users\Asus\AppData\Local\Programs\Spyder\pkgs\requests\sessions.py", line 725, in send
    history = [resp for resp in gen]
  File "C:\Users\Asus\AppData\Local\Programs\Spyder\pkgs\requests\sessions.py", line 725, in <listcomp>
    history = [resp for resp in gen]
  File "C:\Users\Asus\AppData\Local\Programs\Spyder\pkgs\requests\sessions.py", line 266, in resolve_redirects
    resp = self.send(
  File "C:\Users\Asus\AppData\Local\Programs\Spyder\pkgs\requests\sessions.py", line 703, in send
    r = adapter.send(request, **kwargs)
  File "C:\Users\Asus\AppData\Local\Programs\Spyder\pkgs\requests\adapters.py", line 510, in send
    raise RetryError(e, request=request)
requests.exceptions.RetryError: HTTPSConnectionPool(host='api.openalex.org', port=443): Max retries exceeded with url: /works/W2079735306 (Caused by ResponseError('too many 429 error responses'))

[Fri Mar 29 09:35:47 2024] Problem with adding article with id = W2070708314
Traceback (most recent call last):
  File "c:\users\asus\onedrive\документы\github\articles-analysis\programs\downloading_referenced_works.py", line 383, in download_work_by_id
    cursor.execute(f"""
sqlite3.IntegrityError: UNIQUE constraint failed: articles.id

[Fri Mar 29 09:35:47 2024] Problem with adding article with id = W2515541239
Traceback (most recent call last):
  File "c:\users\asus\onedrive\документы\github\articles-analysis\programs\downloading_referenced_works.py", line 383, in download_work_by_id
    cursor.execute(f"""
sqlite3.IntegrityError: UNIQUE constraint failed: articles.id

[Fri Mar 29 09:35:47 2024] Problem with adding article with id = W2142830664
Traceback (most recent call last):
  File "c:\users\asus\onedrive\документы\github\articles-analysis\programs\downloading_referenced_works.py", line 383, in download_work_by_id
    cursor.execute(f"""
sqlite3.IntegrityError: UNIQUE constraint failed: articles.id

[Fri Mar 29 09:35:47 2024] Problem with adding article with id = W2002252750
Traceback (most recent call last):
  File "c:\users\asus\onedrive\документы\github\articles-analysis\programs\downloading_referenced_works.py", line 383, in download_work_by_id
    cursor.execute(f"""
sqlite3.IntegrityError: UNIQUE constraint failed: articles.id

[Fri Mar 29 09:35:47 2024] Problem with adding article with id = W2076476263
Traceback (most recent call last):
  File "c:\users\asus\onedrive\документы\github\articles-analysis\programs\downloading_referenced_works.py", line 383, in download_work_by_id
    cursor.execute(f"""
sqlite3.IntegrityError: UNIQUE constraint failed: articles.id

[Fri Mar 29 09:35:47 2024] Problem with adding article with id = W1568459055
Traceback (most recent call last):
  File "c:\users\asus\onedrive\документы\github\articles-analysis\programs\downloading_referenced_works.py", line 383, in download_work_by_id
    cursor.execute(f"""
sqlite3.IntegrityError: UNIQUE constraint failed: articles.id

[Fri Mar 29 09:35:48 2024] Problem with adding article with id = W3183085784
Traceback (most recent call last):
  File "c:\users\asus\onedrive\документы\github\articles-analysis\programs\downloading_referenced_works.py", line 383, in download_work_by_id
    cursor.execute(f"""
sqlite3.IntegrityError: UNIQUE constraint failed: articles.id

[Fri Mar 29 09:35:48 2024] Problem with getting article with id = W1889084719
Traceback (most recent call last):
  File "c:\users\asus\onedrive\документы\github\articles-analysis\programs\downloading_referenced_works.py", line 357, in download_work_by_id
    work = Works()[id_]
  File "C:\Users\Asus\AppData\Local\Programs\Spyder\Python\lib\site-packages\pyalex\api.py", line 225, in __getitem__
    return self._get_from_url(
  File "C:\Users\Asus\AppData\Local\Programs\Spyder\Python\lib\site-packages\pyalex\api.py", line 267, in _get_from_url
    res.raise_for_status()
  File "C:\Users\Asus\AppData\Local\Programs\Spyder\pkgs\requests\models.py", line 1021, in raise_for_status
    raise HTTPError(http_error_msg, response=self)
requests.exceptions.HTTPError: 404 Client Error: NOT FOUND for url: https://api.openalex.org/works/W1889084719

[Fri Mar 29 09:35:48 2024] Problem with adding article with id = W1880349703
Traceback (most recent call last):
  File "c:\users\asus\onedrive\документы\github\articles-analysis\programs\downloading_referenced_works.py", line 383, in download_work_by_id
    cursor.execute(f"""
sqlite3.IntegrityError: UNIQUE constraint failed: articles.id

[Fri Mar 29 09:35:48 2024] Problem with adding article with id = W2187024871
Traceback (most recent call last):
  File "c:\users\asus\onedrive\документы\github\articles-analysis\programs\downloading_referenced_works.py", line 383, in download_work_by_id
    cursor.execute(f"""
sqlite3.IntegrityError: UNIQUE constraint failed: articles.id

[Fri Mar 29 09:35:49 2024] Problem with adding article with id = W2527399824
Traceback (most recent call last):
  File "c:\users\asus\onedrive\документы\github\articles-analysis\programs\downloading_referenced_works.py", line 383, in download_work_by_id
    cursor.execute(f"""
sqlite3.IntegrityError: UNIQUE constraint failed: articles.id

[Fri Mar 29 09:35:49 2024] Problem with getting article with id = W2188595097
urllib3.exceptions.ResponseError: too many 429 error responses

The above exception was the direct cause of the following exception:

Traceback (most recent call last):
  File "C:\Users\Asus\AppData\Local\Programs\Spyder\pkgs\requests\adapters.py", line 486, in send
    resp = conn.urlopen(
  File "C:\Users\Asus\AppData\Local\Programs\Spyder\pkgs\urllib3\connectionpool.py", line 938, in urlopen
    retries = retries.increment(method, url, response=response, _pool=self)
  File "C:\Users\Asus\AppData\Local\Programs\Spyder\pkgs\urllib3\util\retry.py", line 515, in increment
    raise MaxRetryError(_pool, url, reason) from reason  # type: ignore[arg-type]
urllib3.exceptions.MaxRetryError: HTTPSConnectionPool(host='api.openalex.org', port=443): Max retries exceeded with url: /works/W2188595097 (Caused by ResponseError('too many 429 error responses'))

During handling of the above exception, another exception occurred:

Traceback (most recent call last):
  File "c:\users\asus\onedrive\документы\github\articles-analysis\programs\downloading_referenced_works.py", line 357, in download_work_by_id
    work = Works()[id_]
  File "C:\Users\Asus\AppData\Local\Programs\Spyder\Python\lib\site-packages\pyalex\api.py", line 225, in __getitem__
    return self._get_from_url(
  File "C:\Users\Asus\AppData\Local\Programs\Spyder\Python\lib\site-packages\pyalex\api.py", line 257, in _get_from_url
    res = _get_requests_session().get(url, auth=OpenAlexAuth(config))
  File "C:\Users\Asus\AppData\Local\Programs\Spyder\pkgs\requests\sessions.py", line 602, in get
    return self.request("GET", url, **kwargs)
  File "C:\Users\Asus\AppData\Local\Programs\Spyder\pkgs\requests\sessions.py", line 589, in request
    resp = self.send(prep, **send_kwargs)
  File "C:\Users\Asus\AppData\Local\Programs\Spyder\pkgs\requests\sessions.py", line 703, in send
    r = adapter.send(request, **kwargs)
  File "C:\Users\Asus\AppData\Local\Programs\Spyder\pkgs\requests\adapters.py", line 510, in send
    raise RetryError(e, request=request)
requests.exceptions.RetryError: HTTPSConnectionPool(host='api.openalex.org', port=443): Max retries exceeded with url: /works/W2188595097 (Caused by ResponseError('too many 429 error responses'))

[Fri Mar 29 09:35:49 2024] Problem with getting article with id = W2318954973
urllib3.exceptions.ResponseError: too many 429 error responses

The above exception was the direct cause of the following exception:

Traceback (most recent call last):
  File "C:\Users\Asus\AppData\Local\Programs\Spyder\pkgs\requests\adapters.py", line 486, in send
    resp = conn.urlopen(
  File "C:\Users\Asus\AppData\Local\Programs\Spyder\pkgs\urllib3\connectionpool.py", line 938, in urlopen
    retries = retries.increment(method, url, response=response, _pool=self)
  File "C:\Users\Asus\AppData\Local\Programs\Spyder\pkgs\urllib3\util\retry.py", line 515, in increment
    raise MaxRetryError(_pool, url, reason) from reason  # type: ignore[arg-type]
urllib3.exceptions.MaxRetryError: HTTPSConnectionPool(host='api.openalex.org', port=443): Max retries exceeded with url: /works/W4308276990 (Caused by ResponseError('too many 429 error responses'))

During handling of the above exception, another exception occurred:

Traceback (most recent call last):
  File "c:\users\asus\onedrive\документы\github\articles-analysis\programs\downloading_referenced_works.py", line 357, in download_work_by_id
    work = Works()[id_]
  File "C:\Users\Asus\AppData\Local\Programs\Spyder\Python\lib\site-packages\pyalex\api.py", line 225, in __getitem__
    return self._get_from_url(
  File "C:\Users\Asus\AppData\Local\Programs\Spyder\Python\lib\site-packages\pyalex\api.py", line 257, in _get_from_url
    res = _get_requests_session().get(url, auth=OpenAlexAuth(config))
  File "C:\Users\Asus\AppData\Local\Programs\Spyder\pkgs\requests\sessions.py", line 602, in get
    return self.request("GET", url, **kwargs)
  File "C:\Users\Asus\AppData\Local\Programs\Spyder\pkgs\requests\sessions.py", line 589, in request
    resp = self.send(prep, **send_kwargs)
  File "C:\Users\Asus\AppData\Local\Programs\Spyder\pkgs\requests\sessions.py", line 725, in send
    history = [resp for resp in gen]
  File "C:\Users\Asus\AppData\Local\Programs\Spyder\pkgs\requests\sessions.py", line 725, in <listcomp>
    history = [resp for resp in gen]
  File "C:\Users\Asus\AppData\Local\Programs\Spyder\pkgs\requests\sessions.py", line 266, in resolve_redirects
    resp = self.send(
  File "C:\Users\Asus\AppData\Local\Programs\Spyder\pkgs\requests\sessions.py", line 703, in send
    r = adapter.send(request, **kwargs)
  File "C:\Users\Asus\AppData\Local\Programs\Spyder\pkgs\requests\adapters.py", line 510, in send
    raise RetryError(e, request=request)
requests.exceptions.RetryError: HTTPSConnectionPool(host='api.openalex.org', port=443): Max retries exceeded with url: /works/W4308276990 (Caused by ResponseError('too many 429 error responses'))

[Fri Mar 29 09:35:49 2024] Problem with getting article with id = W1530972001
Traceback (most recent call last):
  File "c:\users\asus\onedrive\документы\github\articles-analysis\programs\downloading_referenced_works.py", line 357, in download_work_by_id
    work = Works()[id_]
  File "C:\Users\Asus\AppData\Local\Programs\Spyder\Python\lib\site-packages\pyalex\api.py", line 225, in __getitem__
    return self._get_from_url(
  File "C:\Users\Asus\AppData\Local\Programs\Spyder\Python\lib\site-packages\pyalex\api.py", line 267, in _get_from_url
    res.raise_for_status()
  File "C:\Users\Asus\AppData\Local\Programs\Spyder\pkgs\requests\models.py", line 1021, in raise_for_status
    raise HTTPError(http_error_msg, response=self)
requests.exceptions.HTTPError: 404 Client Error: NOT FOUND for url: https://api.openalex.org/works/W1530972001

[Fri Mar 29 09:35:50 2024] Problem with adding article with id = W2523870396
Traceback (most recent call last):
  File "c:\users\asus\onedrive\документы\github\articles-analysis\programs\downloading_referenced_works.py", line 383, in download_work_by_id
    cursor.execute(f"""
sqlite3.IntegrityError: UNIQUE constraint failed: articles.id

[Fri Mar 29 09:35:50 2024] Problem with adding article with id = W2185613887
Traceback (most recent call last):
  File "c:\users\asus\onedrive\документы\github\articles-analysis\programs\downloading_referenced_works.py", line 383, in download_work_by_id
    cursor.execute(f"""
sqlite3.IntegrityError: UNIQUE constraint failed: articles.id

[Fri Mar 29 09:35:50 2024] Problem with adding article with id = W2990984158
Traceback (most recent call last):
  File "c:\users\asus\onedrive\документы\github\articles-analysis\programs\downloading_referenced_works.py", line 383, in download_work_by_id
    cursor.execute(f"""
sqlite3.IntegrityError: UNIQUE constraint failed: articles.id

[Fri Mar 29 09:35:50 2024] Problem with adding article with id = W2182463137
Traceback (most recent call last):
  File "c:\users\asus\onedrive\документы\github\articles-analysis\programs\downloading_referenced_works.py", line 383, in download_work_by_id
    cursor.execute(f"""
sqlite3.IntegrityError: UNIQUE constraint failed: articles.id

[Fri Mar 29 09:35:50 2024] Problem with getting article with id = W3120035378
urllib3.exceptions.ResponseError: too many 429 error responses

The above exception was the direct cause of the following exception:

Traceback (most recent call last):
  File "C:\Users\Asus\AppData\Local\Programs\Spyder\pkgs\requests\adapters.py", line 486, in send
    resp = conn.urlopen(
  File "C:\Users\Asus\AppData\Local\Programs\Spyder\pkgs\urllib3\connectionpool.py", line 938, in urlopen
    retries = retries.increment(method, url, response=response, _pool=self)
  File "C:\Users\Asus\AppData\Local\Programs\Spyder\pkgs\urllib3\util\retry.py", line 515, in increment
    raise MaxRetryError(_pool, url, reason) from reason  # type: ignore[arg-type]
urllib3.exceptions.MaxRetryError: HTTPSConnectionPool(host='api.openalex.org', port=443): Max retries exceeded with url: /works/W3120035378 (Caused by ResponseError('too many 429 error responses'))

During handling of the above exception, another exception occurred:

Traceback (most recent call last):
  File "c:\users\asus\onedrive\документы\github\articles-analysis\programs\downloading_referenced_works.py", line 357, in download_work_by_id
    work = Works()[id_]
  File "C:\Users\Asus\AppData\Local\Programs\Spyder\Python\lib\site-packages\pyalex\api.py", line 225, in __getitem__
    return self._get_from_url(
  File "C:\Users\Asus\AppData\Local\Programs\Spyder\Python\lib\site-packages\pyalex\api.py", line 257, in _get_from_url
    res = _get_requests_session().get(url, auth=OpenAlexAuth(config))
  File "C:\Users\Asus\AppData\Local\Programs\Spyder\pkgs\requests\sessions.py", line 602, in get
    return self.request("GET", url, **kwargs)
  File "C:\Users\Asus\AppData\Local\Programs\Spyder\pkgs\requests\sessions.py", line 589, in request
    resp = self.send(prep, **send_kwargs)
  File "C:\Users\Asus\AppData\Local\Programs\Spyder\pkgs\requests\sessions.py", line 703, in send
    r = adapter.send(request, **kwargs)
  File "C:\Users\Asus\AppData\Local\Programs\Spyder\pkgs\requests\adapters.py", line 510, in send
    raise RetryError(e, request=request)
requests.exceptions.RetryError: HTTPSConnectionPool(host='api.openalex.org', port=443): Max retries exceeded with url: /works/W3120035378 (Caused by ResponseError('too many 429 error responses'))

[Fri Mar 29 09:35:50 2024] Problem with getting article with id = W2514552777
urllib3.exceptions.ResponseError: too many 429 error responses

The above exception was the direct cause of the following exception:

Traceback (most recent call last):
  File "C:\Users\Asus\AppData\Local\Programs\Spyder\pkgs\requests\adapters.py", line 486, in send
    resp = conn.urlopen(
  File "C:\Users\Asus\AppData\Local\Programs\Spyder\pkgs\urllib3\connectionpool.py", line 938, in urlopen
    retries = retries.increment(method, url, response=response, _pool=self)
  File "C:\Users\Asus\AppData\Local\Programs\Spyder\pkgs\urllib3\util\retry.py", line 515, in increment
    raise MaxRetryError(_pool, url, reason) from reason  # type: ignore[arg-type]
urllib3.exceptions.MaxRetryError: HTTPSConnectionPool(host='api.openalex.org', port=443): Max retries exceeded with url: /works/W2514552777 (Caused by ResponseError('too many 429 error responses'))

During handling of the above exception, another exception occurred:

Traceback (most recent call last):
  File "c:\users\asus\onedrive\документы\github\articles-analysis\programs\downloading_referenced_works.py", line 357, in download_work_by_id
    work = Works()[id_]
  File "C:\Users\Asus\AppData\Local\Programs\Spyder\Python\lib\site-packages\pyalex\api.py", line 225, in __getitem__
    return self._get_from_url(
  File "C:\Users\Asus\AppData\Local\Programs\Spyder\Python\lib\site-packages\pyalex\api.py", line 257, in _get_from_url
    res = _get_requests_session().get(url, auth=OpenAlexAuth(config))
  File "C:\Users\Asus\AppData\Local\Programs\Spyder\pkgs\requests\sessions.py", line 602, in get
    return self.request("GET", url, **kwargs)
  File "C:\Users\Asus\AppData\Local\Programs\Spyder\pkgs\requests\sessions.py", line 589, in request
    resp = self.send(prep, **send_kwargs)
  File "C:\Users\Asus\AppData\Local\Programs\Spyder\pkgs\requests\sessions.py", line 703, in send
    r = adapter.send(request, **kwargs)
  File "C:\Users\Asus\AppData\Local\Programs\Spyder\pkgs\requests\adapters.py", line 510, in send
    raise RetryError(e, request=request)
requests.exceptions.RetryError: HTTPSConnectionPool(host='api.openalex.org', port=443): Max retries exceeded with url: /works/W2514552777 (Caused by ResponseError('too many 429 error responses'))

[Fri Mar 29 09:35:50 2024] Problem with adding article with id = W2002489263
Traceback (most recent call last):
  File "c:\users\asus\onedrive\документы\github\articles-analysis\programs\downloading_referenced_works.py", line 383, in download_work_by_id
    cursor.execute(f"""
sqlite3.IntegrityError: UNIQUE constraint failed: articles.id

[Fri Mar 29 09:35:50 2024] Problem with adding article with id = W1591196465
Traceback (most recent call last):
  File "c:\users\asus\onedrive\документы\github\articles-analysis\programs\downloading_referenced_works.py", line 383, in download_work_by_id
    cursor.execute(f"""
sqlite3.IntegrityError: UNIQUE constraint failed: articles.id

[Fri Mar 29 09:35:51 2024] Problem with adding article with id = W202987794
Traceback (most recent call last):
  File "c:\users\asus\onedrive\документы\github\articles-analysis\programs\downloading_referenced_works.py", line 383, in download_work_by_id
    cursor.execute(f"""
sqlite3.IntegrityError: UNIQUE constraint failed: articles.id

[Fri Mar 29 09:35:51 2024] Problem with adding article with id = W2395505383
Traceback (most recent call last):
  File "c:\users\asus\onedrive\документы\github\articles-analysis\programs\downloading_referenced_works.py", line 383, in download_work_by_id
    cursor.execute(f"""
sqlite3.IntegrityError: UNIQUE constraint failed: articles.id

[Fri Mar 29 09:35:51 2024] Problem with adding article with id = W1546659586
Traceback (most recent call last):
  File "c:\users\asus\onedrive\документы\github\articles-analysis\programs\downloading_referenced_works.py", line 383, in download_work_by_id
    cursor.execute(f"""
sqlite3.IntegrityError: UNIQUE constraint failed: articles.id

[Fri Mar 29 09:35:51 2024] Problem with adding article with id = W2082445158
Traceback (most recent call last):
  File "c:\users\asus\onedrive\документы\github\articles-analysis\programs\downloading_referenced_works.py", line 383, in download_work_by_id
    cursor.execute(f"""
sqlite3.IntegrityError: UNIQUE constraint failed: articles.id

[Fri Mar 29 09:35:52 2024] Problem with adding article with id = W3152166083
Traceback (most recent call last):
  File "c:\users\asus\onedrive\документы\github\articles-analysis\programs\downloading_referenced_works.py", line 383, in download_work_by_id
    cursor.execute(f"""
sqlite3.IntegrityError: UNIQUE constraint failed: articles.id

[Fri Mar 29 09:35:52 2024] Problem with adding article with id = W2480933358
Traceback (most recent call last):
  File "c:\users\asus\onedrive\документы\github\articles-analysis\programs\downloading_referenced_works.py", line 383, in download_work_by_id
    cursor.execute(f"""
sqlite3.IntegrityError: UNIQUE constraint failed: articles.id

[Fri Mar 29 09:35:52 2024] Problem with adding article with id = W2188330357
Traceback (most recent call last):
  File "c:\users\asus\onedrive\документы\github\articles-analysis\programs\downloading_referenced_works.py", line 383, in download_work_by_id
    cursor.execute(f"""
sqlite3.IntegrityError: UNIQUE constraint failed: articles.id

[Fri Mar 29 09:35:52 2024] Problem with adding article with id = W2003801089
Traceback (most recent call last):
  File "c:\users\asus\onedrive\документы\github\articles-analysis\programs\downloading_referenced_works.py", line 383, in download_work_by_id
    cursor.execute(f"""
sqlite3.IntegrityError: UNIQUE constraint failed: articles.id

[Fri Mar 29 09:35:52 2024] Problem with getting article with id = W4388866125
Traceback (most recent call last):
  File "c:\users\asus\onedrive\документы\github\articles-analysis\programs\downloading_referenced_works.py", line 357, in download_work_by_id
    work = Works()[id_]
  File "C:\Users\Asus\AppData\Local\Programs\Spyder\Python\lib\site-packages\pyalex\api.py", line 225, in __getitem__
    return self._get_from_url(
  File "C:\Users\Asus\AppData\Local\Programs\Spyder\Python\lib\site-packages\pyalex\api.py", line 267, in _get_from_url
    res.raise_for_status()
  File "C:\Users\Asus\AppData\Local\Programs\Spyder\pkgs\requests\models.py", line 1021, in raise_for_status
    raise HTTPError(http_error_msg, response=self)
requests.exceptions.HTTPError: 404 Client Error: NOT FOUND for url: https://api.openalex.org/works/W4388866125

[Fri Mar 29 09:35:53 2024] Problem with getting article with id = W3093304401
urllib3.exceptions.ResponseError: too many 429 error responses

The above exception was the direct cause of the following exception:

Traceback (most recent call last):
  File "C:\Users\Asus\AppData\Local\Programs\Spyder\pkgs\requests\adapters.py", line 486, in send
    resp = conn.urlopen(
  File "C:\Users\Asus\AppData\Local\Programs\Spyder\pkgs\urllib3\connectionpool.py", line 938, in urlopen
    retries = retries.increment(method, url, response=response, _pool=self)
  File "C:\Users\Asus\AppData\Local\Programs\Spyder\pkgs\urllib3\util\retry.py", line 515, in increment
    raise MaxRetryError(_pool, url, reason) from reason  # type: ignore[arg-type]
urllib3.exceptions.MaxRetryError: HTTPSConnectionPool(host='api.openalex.org', port=443): Max retries exceeded with url: /works/W3093304401 (Caused by ResponseError('too many 429 error responses'))

During handling of the above exception, another exception occurred:

Traceback (most recent call last):
  File "c:\users\asus\onedrive\документы\github\articles-analysis\programs\downloading_referenced_works.py", line 357, in download_work_by_id
    work = Works()[id_]
  File "C:\Users\Asus\AppData\Local\Programs\Spyder\Python\lib\site-packages\pyalex\api.py", line 225, in __getitem__
    return self._get_from_url(
  File "C:\Users\Asus\AppData\Local\Programs\Spyder\Python\lib\site-packages\pyalex\api.py", line 257, in _get_from_url
    res = _get_requests_session().get(url, auth=OpenAlexAuth(config))
  File "C:\Users\Asus\AppData\Local\Programs\Spyder\pkgs\requests\sessions.py", line 602, in get
    return self.request("GET", url, **kwargs)
  File "C:\Users\Asus\AppData\Local\Programs\Spyder\pkgs\requests\sessions.py", line 589, in request
    resp = self.send(prep, **send_kwargs)
  File "C:\Users\Asus\AppData\Local\Programs\Spyder\pkgs\requests\sessions.py", line 703, in send
    r = adapter.send(request, **kwargs)
  File "C:\Users\Asus\AppData\Local\Programs\Spyder\pkgs\requests\adapters.py", line 510, in send
    raise RetryError(e, request=request)
requests.exceptions.RetryError: HTTPSConnectionPool(host='api.openalex.org', port=443): Max retries exceeded with url: /works/W3093304401 (Caused by ResponseError('too many 429 error responses'))

[Fri Mar 29 09:35:53 2024] Problem with adding article with id = W2030690537
Traceback (most recent call last):
  File "c:\users\asus\onedrive\документы\github\articles-analysis\programs\downloading_referenced_works.py", line 383, in download_work_by_id
    cursor.execute(f"""
sqlite3.IntegrityError: UNIQUE constraint failed: articles.id

[Fri Mar 29 09:35:53 2024] Problem with adding article with id = W350429439
Traceback (most recent call last):
  File "c:\users\asus\onedrive\документы\github\articles-analysis\programs\downloading_referenced_works.py", line 383, in download_work_by_id
    cursor.execute(f"""
sqlite3.IntegrityError: UNIQUE constraint failed: articles.id

[Fri Mar 29 09:35:53 2024] Problem with adding article with id = W2339435684
Traceback (most recent call last):
  File "c:\users\asus\onedrive\документы\github\articles-analysis\programs\downloading_referenced_works.py", line 383, in download_work_by_id
    cursor.execute(f"""
sqlite3.IntegrityError: UNIQUE constraint failed: articles.id

[Fri Mar 29 09:35:53 2024] Problem with adding article with id = W2526232674
Traceback (most recent call last):
  File "c:\users\asus\onedrive\документы\github\articles-analysis\programs\downloading_referenced_works.py", line 383, in download_work_by_id
    cursor.execute(f"""
sqlite3.IntegrityError: UNIQUE constraint failed: articles.id

[Fri Mar 29 09:35:53 2024] Problem with adding article with id = W2486289195
Traceback (most recent call last):
  File "c:\users\asus\onedrive\документы\github\articles-analysis\programs\downloading_referenced_works.py", line 383, in download_work_by_id
    cursor.execute(f"""
sqlite3.IntegrityError: UNIQUE constraint failed: articles.id

[Fri Mar 29 09:35:54 2024] Problem with adding article with id = W3111858832
Traceback (most recent call last):
  File "c:\users\asus\onedrive\документы\github\articles-analysis\programs\downloading_referenced_works.py", line 383, in download_work_by_id
    cursor.execute(f"""
sqlite3.IntegrityError: UNIQUE constraint failed: articles.id

[Fri Mar 29 09:35:54 2024] Problem with getting article with id = W2866749660
Traceback (most recent call last):
  File "c:\users\asus\onedrive\документы\github\articles-analysis\programs\downloading_referenced_works.py", line 357, in download_work_by_id
    work = Works()[id_]
  File "C:\Users\Asus\AppData\Local\Programs\Spyder\Python\lib\site-packages\pyalex\api.py", line 225, in __getitem__
    return self._get_from_url(
  File "C:\Users\Asus\AppData\Local\Programs\Spyder\Python\lib\site-packages\pyalex\api.py", line 267, in _get_from_url
    res.raise_for_status()
  File "C:\Users\Asus\AppData\Local\Programs\Spyder\pkgs\requests\models.py", line 1021, in raise_for_status
    raise HTTPError(http_error_msg, response=self)
requests.exceptions.HTTPError: 404 Client Error: NOT FOUND for url: https://api.openalex.org/works/W2866749660

[Fri Mar 29 09:35:54 2024] Problem with adding article with id = W2526791468
Traceback (most recent call last):
  File "c:\users\asus\onedrive\документы\github\articles-analysis\programs\downloading_referenced_works.py", line 383, in download_work_by_id
    cursor.execute(f"""
sqlite3.IntegrityError: UNIQUE constraint failed: articles.id

[Fri Mar 29 09:35:54 2024] Problem with adding article with id = W2523320359
Traceback (most recent call last):
  File "c:\users\asus\onedrive\документы\github\articles-analysis\programs\downloading_referenced_works.py", line 383, in download_work_by_id
    cursor.execute(f"""
sqlite3.IntegrityError: UNIQUE constraint failed: articles.id

[Fri Mar 29 09:35:55 2024] Problem with adding article with id = W2472423805
Traceback (most recent call last):
  File "c:\users\asus\onedrive\документы\github\articles-analysis\programs\downloading_referenced_works.py", line 383, in download_work_by_id
    cursor.execute(f"""
sqlite3.IntegrityError: UNIQUE constraint failed: articles.id

[Fri Mar 29 09:35:55 2024] Problem with adding article with id = W2522724121
Traceback (most recent call last):
  File "c:\users\asus\onedrive\документы\github\articles-analysis\programs\downloading_referenced_works.py", line 383, in download_work_by_id
    cursor.execute(f"""
sqlite3.IntegrityError: UNIQUE constraint failed: articles.id

[Fri Mar 29 09:35:55 2024] Problem with adding article with id = W3140594797
Traceback (most recent call last):
  File "c:\users\asus\onedrive\документы\github\articles-analysis\programs\downloading_referenced_works.py", line 383, in download_work_by_id
    cursor.execute(f"""
sqlite3.IntegrityError: UNIQUE constraint failed: articles.id

[Fri Mar 29 09:35:55 2024] Problem with adding article with id = W2099616619
Traceback (most recent call last):
  File "c:\users\asus\onedrive\документы\github\articles-analysis\programs\downloading_referenced_works.py", line 383, in download_work_by_id
    cursor.execute(f"""
sqlite3.IntegrityError: UNIQUE constraint failed: articles.id

[Fri Mar 29 09:35:56 2024] Problem with adding article with id = W2412444599
Traceback (most recent call last):
  File "c:\users\asus\onedrive\документы\github\articles-analysis\programs\downloading_referenced_works.py", line 383, in download_work_by_id
    cursor.execute(f"""
sqlite3.IntegrityError: UNIQUE constraint failed: articles.id

[Fri Mar 29 09:35:56 2024] Problem with adding article with id = W2024712037
Traceback (most recent call last):
  File "c:\users\asus\onedrive\документы\github\articles-analysis\programs\downloading_referenced_works.py", line 383, in download_work_by_id
    cursor.execute(f"""
sqlite3.IntegrityError: UNIQUE constraint failed: articles.id

[Fri Mar 29 09:35:56 2024] Problem with adding article with id = W3183770276
Traceback (most recent call last):
  File "c:\users\asus\onedrive\документы\github\articles-analysis\programs\downloading_referenced_works.py", line 383, in download_work_by_id
    cursor.execute(f"""
sqlite3.IntegrityError: UNIQUE constraint failed: articles.id

[Fri Mar 29 09:35:56 2024] Problem with adding article with id = W2069275950
Traceback (most recent call last):
  File "c:\users\asus\onedrive\документы\github\articles-analysis\programs\downloading_referenced_works.py", line 383, in download_work_by_id
    cursor.execute(f"""
sqlite3.IntegrityError: UNIQUE constraint failed: articles.id

[Fri Mar 29 09:35:56 2024] Problem with adding article with id = W2189255995
Traceback (most recent call last):
  File "c:\users\asus\onedrive\документы\github\articles-analysis\programs\downloading_referenced_works.py", line 383, in download_work_by_id
    cursor.execute(f"""
sqlite3.IntegrityError: UNIQUE constraint failed: articles.id

[Fri Mar 29 09:35:56 2024] Problem with adding article with id = W1989963329
Traceback (most recent call last):
  File "c:\users\asus\onedrive\документы\github\articles-analysis\programs\downloading_referenced_works.py", line 383, in download_work_by_id
    cursor.execute(f"""
sqlite3.IntegrityError: UNIQUE constraint failed: articles.id

[Fri Mar 29 09:35:57 2024] Problem with adding article with id = W2523476899
Traceback (most recent call last):
  File "c:\users\asus\onedrive\документы\github\articles-analysis\programs\downloading_referenced_works.py", line 383, in download_work_by_id
    cursor.execute(f"""
sqlite3.IntegrityError: UNIQUE constraint failed: articles.id

[Fri Mar 29 09:35:57 2024] Problem with adding article with id = W1975473662
Traceback (most recent call last):
  File "c:\users\asus\onedrive\документы\github\articles-analysis\programs\downloading_referenced_works.py", line 383, in download_work_by_id
    cursor.execute(f"""
sqlite3.IntegrityError: UNIQUE constraint failed: articles.id

[Fri Mar 29 09:35:57 2024] Problem with adding article with id = W2489772053
Traceback (most recent call last):
  File "c:\users\asus\onedrive\документы\github\articles-analysis\programs\downloading_referenced_works.py", line 383, in download_work_by_id
    cursor.execute(f"""
sqlite3.IntegrityError: UNIQUE constraint failed: articles.id

[Fri Mar 29 09:35:57 2024] Problem with adding article with id = W2889828091
Traceback (most recent call last):
  File "c:\users\asus\onedrive\документы\github\articles-analysis\programs\downloading_referenced_works.py", line 383, in download_work_by_id
    cursor.execute(f"""
sqlite3.IntegrityError: UNIQUE constraint failed: articles.id

[Fri Mar 29 09:35:58 2024] Problem with adding article with id = W3141595788
Traceback (most recent call last):
  File "c:\users\asus\onedrive\документы\github\articles-analysis\programs\downloading_referenced_works.py", line 383, in download_work_by_id
    cursor.execute(f"""
sqlite3.IntegrityError: UNIQUE constraint failed: articles.id

[Fri Mar 29 09:35:58 2024] Problem with getting article with id = W2336972710
urllib3.exceptions.ResponseError: too many 429 error responses

The above exception was the direct cause of the following exception:

Traceback (most recent call last):
  File "C:\Users\Asus\AppData\Local\Programs\Spyder\pkgs\requests\adapters.py", line 486, in send
    resp = conn.urlopen(
  File "C:\Users\Asus\AppData\Local\Programs\Spyder\pkgs\urllib3\connectionpool.py", line 938, in urlopen
    retries = retries.increment(method, url, response=response, _pool=self)
  File "C:\Users\Asus\AppData\Local\Programs\Spyder\pkgs\urllib3\util\retry.py", line 515, in increment
    raise MaxRetryError(_pool, url, reason) from reason  # type: ignore[arg-type]
urllib3.exceptions.MaxRetryError: HTTPSConnectionPool(host='api.openalex.org', port=443): Max retries exceeded with url: /works/W4285719527 (Caused by ResponseError('too many 429 error responses'))

During handling of the above exception, another exception occurred:

Traceback (most recent call last):
  File "c:\users\asus\onedrive\документы\github\articles-analysis\programs\downloading_referenced_works.py", line 357, in download_work_by_id
    work = Works()[id_]
  File "C:\Users\Asus\AppData\Local\Programs\Spyder\Python\lib\site-packages\pyalex\api.py", line 225, in __getitem__
    return self._get_from_url(
  File "C:\Users\Asus\AppData\Local\Programs\Spyder\Python\lib\site-packages\pyalex\api.py", line 257, in _get_from_url
    res = _get_requests_session().get(url, auth=OpenAlexAuth(config))
  File "C:\Users\Asus\AppData\Local\Programs\Spyder\pkgs\requests\sessions.py", line 602, in get
    return self.request("GET", url, **kwargs)
  File "C:\Users\Asus\AppData\Local\Programs\Spyder\pkgs\requests\sessions.py", line 589, in request
    resp = self.send(prep, **send_kwargs)
  File "C:\Users\Asus\AppData\Local\Programs\Spyder\pkgs\requests\sessions.py", line 725, in send
    history = [resp for resp in gen]
  File "C:\Users\Asus\AppData\Local\Programs\Spyder\pkgs\requests\sessions.py", line 725, in <listcomp>
    history = [resp for resp in gen]
  File "C:\Users\Asus\AppData\Local\Programs\Spyder\pkgs\requests\sessions.py", line 266, in resolve_redirects
    resp = self.send(
  File "C:\Users\Asus\AppData\Local\Programs\Spyder\pkgs\requests\sessions.py", line 703, in send
    r = adapter.send(request, **kwargs)
  File "C:\Users\Asus\AppData\Local\Programs\Spyder\pkgs\requests\adapters.py", line 510, in send
    raise RetryError(e, request=request)
requests.exceptions.RetryError: HTTPSConnectionPool(host='api.openalex.org', port=443): Max retries exceeded with url: /works/W4285719527 (Caused by ResponseError('too many 429 error responses'))

[Fri Mar 29 09:35:58 2024] Problem with adding article with id = W2340552785
Traceback (most recent call last):
  File "c:\users\asus\onedrive\документы\github\articles-analysis\programs\downloading_referenced_works.py", line 383, in download_work_by_id
    cursor.execute(f"""
sqlite3.IntegrityError: UNIQUE constraint failed: articles.id

[Fri Mar 29 09:35:58 2024] Problem with adding article with id = W2921359128
Traceback (most recent call last):
  File "c:\users\asus\onedrive\документы\github\articles-analysis\programs\downloading_referenced_works.py", line 383, in download_work_by_id
    cursor.execute(f"""
sqlite3.IntegrityError: UNIQUE constraint failed: articles.id

[Fri Mar 29 09:35:58 2024] Problem with adding article with id = W2429491789
Traceback (most recent call last):
  File "c:\users\asus\onedrive\документы\github\articles-analysis\programs\downloading_referenced_works.py", line 383, in download_work_by_id
    cursor.execute(f"""
sqlite3.IntegrityError: UNIQUE constraint failed: articles.id

[Fri Mar 29 09:35:59 2024] Problem with adding article with id = W2739947085
Traceback (most recent call last):
  File "c:\users\asus\onedrive\документы\github\articles-analysis\programs\downloading_referenced_works.py", line 383, in download_work_by_id
    cursor.execute(f"""
sqlite3.IntegrityError: UNIQUE constraint failed: articles.id

[Fri Mar 29 09:35:59 2024] Problem with adding article with id = W2093762777
Traceback (most recent call last):
  File "c:\users\asus\onedrive\документы\github\articles-analysis\programs\downloading_referenced_works.py", line 383, in download_work_by_id
    cursor.execute(f"""
sqlite3.IntegrityError: UNIQUE constraint failed: articles.id

[Fri Mar 29 09:35:59 2024] Problem with adding article with id = W3147457421
Traceback (most recent call last):
  File "c:\users\asus\onedrive\документы\github\articles-analysis\programs\downloading_referenced_works.py", line 383, in download_work_by_id
    cursor.execute(f"""
sqlite3.IntegrityError: UNIQUE constraint failed: articles.id

[Fri Mar 29 09:35:59 2024] Problem with adding article with id = W2469832478
Traceback (most recent call last):
  File "c:\users\asus\onedrive\документы\github\articles-analysis\programs\downloading_referenced_works.py", line 383, in download_work_by_id
    cursor.execute(f"""
sqlite3.IntegrityError: UNIQUE constraint failed: articles.id

[Fri Mar 29 09:35:59 2024] Problem with adding article with id = W2503518177
Traceback (most recent call last):
  File "c:\users\asus\onedrive\документы\github\articles-analysis\programs\downloading_referenced_works.py", line 383, in download_work_by_id
    cursor.execute(f"""
sqlite3.IntegrityError: UNIQUE constraint failed: articles.id

[Fri Mar 29 09:36:00 2024] Problem with adding article with id = W2601262601
Traceback (most recent call last):
  File "c:\users\asus\onedrive\документы\github\articles-analysis\programs\downloading_referenced_works.py", line 383, in download_work_by_id
    cursor.execute(f"""
sqlite3.IntegrityError: UNIQUE constraint failed: articles.id

[Fri Mar 29 09:36:00 2024] Problem with adding article with id = W2116887046
Traceback (most recent call last):
  File "c:\users\asus\onedrive\документы\github\articles-analysis\programs\downloading_referenced_works.py", line 383, in download_work_by_id
    cursor.execute(f"""
sqlite3.IntegrityError: UNIQUE constraint failed: articles.id

[Fri Mar 29 09:36:01 2024] Problem with adding article with id = W2179463945
Traceback (most recent call last):
  File "c:\users\asus\onedrive\документы\github\articles-analysis\programs\downloading_referenced_works.py", line 383, in download_work_by_id
    cursor.execute(f"""
sqlite3.IntegrityError: UNIQUE constraint failed: articles.id

