[Wed Apr  3 16:47:36 2024]   Start downloading works_by_ids for level_1 in 4 thread(s)

[Wed Apr  3 16:48:16 2024]   Problem with adding article with id = W2483050148
Traceback (most recent call last):
  File "c:\users\asus\onedrive\документы\github\articles-analysis\programs\downloading_referenced_works.py", line 289, in download_work_by_id
    cursor.execute(f"""
sqlite3.IntegrityError: UNIQUE constraint failed: articles.id


[Wed Apr  3 16:49:06 2024]   count: 500, speed: 0.179 sec/article, request: 97.6%, db: 2.0, other: 0.4%

[Wed Apr  3 16:50:47 2024]   count: 500, speed: 0.201 sec/article, request: 97.3%, db: 2.1, other: 0.6%

[Wed Apr  3 16:52:16 2024]   count: 500, speed: 0.178 sec/article, request: 97.9%, db: 1.7, other: 0.4%

[Wed Apr  3 16:52:18 2024]   Problem with adding article with id = W2475393353
Traceback (most recent call last):
  File "c:\users\asus\onedrive\документы\github\articles-analysis\programs\downloading_referenced_works.py", line 289, in download_work_by_id
    cursor.execute(f"""
sqlite3.IntegrityError: UNIQUE constraint failed: articles.id


[Wed Apr  3 16:53:47 2024]   count: 500, speed: 0.182 sec/article, request: 97.2%, db: 2.1, other: 0.7%

[Wed Apr  3 16:55:16 2024]   count: 500, speed: 0.177 sec/article, request: 97.6%, db: 1.9, other: 0.5%

[Wed Apr  3 16:56:43 2024]   count: 500, speed: 0.175 sec/article, request: 97.5%, db: 2.0, other: 0.5%

[Wed Apr  3 16:57:15 2024]   Problem with adding article with id = W2520376867
Traceback (most recent call last):
  File "c:\users\asus\onedrive\документы\github\articles-analysis\programs\downloading_referenced_works.py", line 289, in download_work_by_id
    cursor.execute(f"""
sqlite3.IntegrityError: UNIQUE constraint failed: articles.id


[Wed Apr  3 16:57:28 2024]   Problem with adding article with id = W2093762777
Traceback (most recent call last):
  File "c:\users\asus\onedrive\документы\github\articles-analysis\programs\downloading_referenced_works.py", line 289, in download_work_by_id
    cursor.execute(f"""
sqlite3.IntegrityError: UNIQUE constraint failed: articles.id


[Wed Apr  3 16:58:14 2024]   count: 500, speed: 0.173 sec/article, request: 97.7%, db: 1.8, other: 0.5%

[Wed Apr  3 16:58:24 2024]   Problem with adding article with id = W2221753820
Traceback (most recent call last):
  File "c:\users\asus\onedrive\документы\github\articles-analysis\programs\downloading_referenced_works.py", line 289, in download_work_by_id
    cursor.execute(f"""
sqlite3.IntegrityError: UNIQUE constraint failed: articles.id


[Wed Apr  3 16:58:33 2024]   Problem with getting article with id = W3101456301
urllib3.exceptions.ProtocolError: ('Connection aborted.', TimeoutError(10060, 'Попытка установить соединение была безуспешной, т.к. от другого компьютера за требуемое время не получен нужный отклик, или было разорвано уже установленное соединение из-за неверного отклика уже подключенного компьютера', None, 10060, None))

The above exception was the direct cause of the following exception:

Traceback (most recent call last):
  File "C:\Users\Asus\AppData\Local\Programs\Spyder\pkgs\requests\adapters.py", line 486, in send
    resp = conn.urlopen(
  File "C:\Users\Asus\AppData\Local\Programs\Spyder\pkgs\urllib3\connectionpool.py", line 847, in urlopen
    retries = retries.increment(
  File "C:\Users\Asus\AppData\Local\Programs\Spyder\pkgs\urllib3\util\retry.py", line 515, in increment
    raise MaxRetryError(_pool, url, reason) from reason  # type: ignore[arg-type]
urllib3.exceptions.MaxRetryError: HTTPSConnectionPool(host='api.openalex.org', port=443): Max retries exceeded with url: /works/W3101456301 (Caused by ProtocolError('Connection aborted.', TimeoutError(10060, 'Попытка установить соединение была безуспешной, т.к. от другого компьютера за требуемое время не получен нужный отклик, или было разорвано уже установленное соединение из-за неверного отклика уже подключенного компьютера', None, 10060, None)))

During handling of the above exception, another exception occurred:

Traceback (most recent call last):
  File "c:\users\asus\onedrive\документы\github\articles-analysis\programs\downloading_referenced_works.py", line 265, in download_work_by_id
    work = Works()[id_]
  File "C:\Users\Asus\AppData\Local\Programs\Spyder\Python\lib\site-packages\pyalex\api.py", line 225, in __getitem__
    return self._get_from_url(
  File "C:\Users\Asus\AppData\Local\Programs\Spyder\Python\lib\site-packages\pyalex\api.py", line 257, in _get_from_url
    res = _get_requests_session().get(url, auth=OpenAlexAuth(config))
  File "C:\Users\Asus\AppData\Local\Programs\Spyder\pkgs\requests\sessions.py", line 602, in get
    return self.request("GET", url, **kwargs)
  File "C:\Users\Asus\AppData\Local\Programs\Spyder\pkgs\requests\sessions.py", line 589, in request
    resp = self.send(prep, **send_kwargs)
  File "C:\Users\Asus\AppData\Local\Programs\Spyder\pkgs\requests\sessions.py", line 703, in send
    r = adapter.send(request, **kwargs)
  File "C:\Users\Asus\AppData\Local\Programs\Spyder\pkgs\requests\adapters.py", line 519, in send
    raise ConnectionError(e, request=request)
requests.exceptions.ConnectionError: HTTPSConnectionPool(host='api.openalex.org', port=443): Max retries exceeded with url: /works/W3101456301 (Caused by ProtocolError('Connection aborted.', TimeoutError(10060, 'Попытка установить соединение была безуспешной, т.к. от другого компьютера за требуемое время не получен нужный отклик, или было разорвано уже установленное соединение из-за неверного отклика уже подключенного компьютера', None, 10060, None)))


[Wed Apr  3 16:59:51 2024]   count: 500, speed: 0.203 sec/article, request: 88.9%, db: 1.6, other: 9.5%

[Wed Apr  3 16:59:59 2024]   Problem with adding article with id = W2461965465
Traceback (most recent call last):
  File "c:\users\asus\onedrive\документы\github\articles-analysis\programs\downloading_referenced_works.py", line 289, in download_work_by_id
    cursor.execute(f"""
sqlite3.IntegrityError: UNIQUE constraint failed: articles.id


[Wed Apr  3 17:00:49 2024]   Problem with adding article with id = W2467252295
Traceback (most recent call last):
  File "c:\users\asus\onedrive\документы\github\articles-analysis\programs\downloading_referenced_works.py", line 289, in download_work_by_id
    cursor.execute(f"""
sqlite3.IntegrityError: UNIQUE constraint failed: articles.id


[Wed Apr  3 17:01:18 2024]   count: 500, speed: 0.175 sec/article, request: 98.0%, db: 1.6, other: 0.4%

[Wed Apr  3 17:02:22 2024]   Problem with adding article with id = W2521818335
Traceback (most recent call last):
  File "c:\users\asus\onedrive\документы\github\articles-analysis\programs\downloading_referenced_works.py", line 289, in download_work_by_id
    cursor.execute(f"""
sqlite3.IntegrityError: UNIQUE constraint failed: articles.id


[Wed Apr  3 17:02:56 2024]   Problem with getting article with id = W1976400977
urllib3.exceptions.ProtocolError: ('Connection aborted.', TimeoutError(10060, 'Попытка установить соединение была безуспешной, т.к. от другого компьютера за требуемое время не получен нужный отклик, или было разорвано уже установленное соединение из-за неверного отклика уже подключенного компьютера', None, 10060, None))

The above exception was the direct cause of the following exception:

Traceback (most recent call last):
  File "C:\Users\Asus\AppData\Local\Programs\Spyder\pkgs\requests\adapters.py", line 486, in send
    resp = conn.urlopen(
  File "C:\Users\Asus\AppData\Local\Programs\Spyder\pkgs\urllib3\connectionpool.py", line 847, in urlopen
    retries = retries.increment(
  File "C:\Users\Asus\AppData\Local\Programs\Spyder\pkgs\urllib3\util\retry.py", line 515, in increment
    raise MaxRetryError(_pool, url, reason) from reason  # type: ignore[arg-type]
urllib3.exceptions.MaxRetryError: HTTPSConnectionPool(host='api.openalex.org', port=443): Max retries exceeded with url: /works/W1976400977 (Caused by ProtocolError('Connection aborted.', TimeoutError(10060, 'Попытка установить соединение была безуспешной, т.к. от другого компьютера за требуемое время не получен нужный отклик, или было разорвано уже установленное соединение из-за неверного отклика уже подключенного компьютера', None, 10060, None)))

During handling of the above exception, another exception occurred:

Traceback (most recent call last):
  File "c:\users\asus\onedrive\документы\github\articles-analysis\programs\downloading_referenced_works.py", line 265, in download_work_by_id
    work = Works()[id_]
  File "C:\Users\Asus\AppData\Local\Programs\Spyder\Python\lib\site-packages\pyalex\api.py", line 225, in __getitem__
    return self._get_from_url(
  File "C:\Users\Asus\AppData\Local\Programs\Spyder\Python\lib\site-packages\pyalex\api.py", line 257, in _get_from_url
    res = _get_requests_session().get(url, auth=OpenAlexAuth(config))
  File "C:\Users\Asus\AppData\Local\Programs\Spyder\pkgs\requests\sessions.py", line 602, in get
    return self.request("GET", url, **kwargs)
  File "C:\Users\Asus\AppData\Local\Programs\Spyder\pkgs\requests\sessions.py", line 589, in request
    resp = self.send(prep, **send_kwargs)
  File "C:\Users\Asus\AppData\Local\Programs\Spyder\pkgs\requests\sessions.py", line 703, in send
    r = adapter.send(request, **kwargs)
  File "C:\Users\Asus\AppData\Local\Programs\Spyder\pkgs\requests\adapters.py", line 519, in send
    raise ConnectionError(e, request=request)
requests.exceptions.ConnectionError: HTTPSConnectionPool(host='api.openalex.org', port=443): Max retries exceeded with url: /works/W1976400977 (Caused by ProtocolError('Connection aborted.', TimeoutError(10060, 'Попытка установить соединение была безуспешной, т.к. от другого компьютера за требуемое время не получен нужный отклик, или было разорвано уже установленное соединение из-за неверного отклика уже подключенного компьютера', None, 10060, None)))


[Wed Apr  3 17:02:57 2024]   Problem with getting article with id = W3098434369
urllib3.exceptions.ProtocolError: ('Connection aborted.', TimeoutError(10060, 'Попытка установить соединение была безуспешной, т.к. от другого компьютера за требуемое время не получен нужный отклик, или было разорвано уже установленное соединение из-за неверного отклика уже подключенного компьютера', None, 10060, None))

The above exception was the direct cause of the following exception:

Traceback (most recent call last):
  File "C:\Users\Asus\AppData\Local\Programs\Spyder\pkgs\requests\adapters.py", line 486, in send
    resp = conn.urlopen(
  File "C:\Users\Asus\AppData\Local\Programs\Spyder\pkgs\urllib3\connectionpool.py", line 847, in urlopen
    retries = retries.increment(
  File "C:\Users\Asus\AppData\Local\Programs\Spyder\pkgs\urllib3\util\retry.py", line 515, in increment
    raise MaxRetryError(_pool, url, reason) from reason  # type: ignore[arg-type]
urllib3.exceptions.MaxRetryError: HTTPSConnectionPool(host='api.openalex.org', port=443): Max retries exceeded with url: /works/W3098434369 (Caused by ProtocolError('Connection aborted.', TimeoutError(10060, 'Попытка установить соединение была безуспешной, т.к. от другого компьютера за требуемое время не получен нужный отклик, или было разорвано уже установленное соединение из-за неверного отклика уже подключенного компьютера', None, 10060, None)))

During handling of the above exception, another exception occurred:

Traceback (most recent call last):
  File "c:\users\asus\onedrive\документы\github\articles-analysis\programs\downloading_referenced_works.py", line 265, in download_work_by_id
    work = Works()[id_]
  File "C:\Users\Asus\AppData\Local\Programs\Spyder\Python\lib\site-packages\pyalex\api.py", line 225, in __getitem__
    return self._get_from_url(
  File "C:\Users\Asus\AppData\Local\Programs\Spyder\Python\lib\site-packages\pyalex\api.py", line 257, in _get_from_url
    res = _get_requests_session().get(url, auth=OpenAlexAuth(config))
  File "C:\Users\Asus\AppData\Local\Programs\Spyder\pkgs\requests\sessions.py", line 602, in get
    return self.request("GET", url, **kwargs)
  File "C:\Users\Asus\AppData\Local\Programs\Spyder\pkgs\requests\sessions.py", line 589, in request
    resp = self.send(prep, **send_kwargs)
  File "C:\Users\Asus\AppData\Local\Programs\Spyder\pkgs\requests\sessions.py", line 703, in send
    r = adapter.send(request, **kwargs)
  File "C:\Users\Asus\AppData\Local\Programs\Spyder\pkgs\requests\adapters.py", line 519, in send
    raise ConnectionError(e, request=request)
requests.exceptions.ConnectionError: HTTPSConnectionPool(host='api.openalex.org', port=443): Max retries exceeded with url: /works/W3098434369 (Caused by ProtocolError('Connection aborted.', TimeoutError(10060, 'Попытка установить соединение была безуспешной, т.к. от другого компьютера за требуемое время не получен нужный отклик, или было разорвано уже установленное соединение из-за неверного отклика уже подключенного компьютера', None, 10060, None)))


[Wed Apr  3 17:03:02 2024]   Problem with getting article with id = W2963877677
urllib3.exceptions.ProtocolError: ('Connection aborted.', TimeoutError(10060, 'Попытка установить соединение была безуспешной, т.к. от другого компьютера за требуемое время не получен нужный отклик, или было разорвано уже установленное соединение из-за неверного отклика уже подключенного компьютера', None, 10060, None))

The above exception was the direct cause of the following exception:

Traceback (most recent call last):
  File "C:\Users\Asus\AppData\Local\Programs\Spyder\pkgs\requests\adapters.py", line 486, in send
    resp = conn.urlopen(
  File "C:\Users\Asus\AppData\Local\Programs\Spyder\pkgs\urllib3\connectionpool.py", line 847, in urlopen
    retries = retries.increment(
  File "C:\Users\Asus\AppData\Local\Programs\Spyder\pkgs\urllib3\util\retry.py", line 515, in increment
    raise MaxRetryError(_pool, url, reason) from reason  # type: ignore[arg-type]
urllib3.exceptions.MaxRetryError: HTTPSConnectionPool(host='api.openalex.org', port=443): Max retries exceeded with url: /works/W2963877677 (Caused by ProtocolError('Connection aborted.', TimeoutError(10060, 'Попытка установить соединение была безуспешной, т.к. от другого компьютера за требуемое время не получен нужный отклик, или было разорвано уже установленное соединение из-за неверного отклика уже подключенного компьютера', None, 10060, None)))

During handling of the above exception, another exception occurred:

Traceback (most recent call last):
  File "c:\users\asus\onedrive\документы\github\articles-analysis\programs\downloading_referenced_works.py", line 265, in download_work_by_id
    work = Works()[id_]
  File "C:\Users\Asus\AppData\Local\Programs\Spyder\Python\lib\site-packages\pyalex\api.py", line 225, in __getitem__
    return self._get_from_url(
  File "C:\Users\Asus\AppData\Local\Programs\Spyder\Python\lib\site-packages\pyalex\api.py", line 257, in _get_from_url
    res = _get_requests_session().get(url, auth=OpenAlexAuth(config))
  File "C:\Users\Asus\AppData\Local\Programs\Spyder\pkgs\requests\sessions.py", line 602, in get
    return self.request("GET", url, **kwargs)
  File "C:\Users\Asus\AppData\Local\Programs\Spyder\pkgs\requests\sessions.py", line 589, in request
    resp = self.send(prep, **send_kwargs)
  File "C:\Users\Asus\AppData\Local\Programs\Spyder\pkgs\requests\sessions.py", line 703, in send
    r = adapter.send(request, **kwargs)
  File "C:\Users\Asus\AppData\Local\Programs\Spyder\pkgs\requests\adapters.py", line 519, in send
    raise ConnectionError(e, request=request)
requests.exceptions.ConnectionError: HTTPSConnectionPool(host='api.openalex.org', port=443): Max retries exceeded with url: /works/W2963877677 (Caused by ProtocolError('Connection aborted.', TimeoutError(10060, 'Попытка установить соединение была безуспешной, т.к. от другого компьютера за требуемое время не получен нужный отклик, или было разорвано уже установленное соединение из-за неверного отклика уже подключенного компьютера', None, 10060, None)))


[Wed Apr  3 17:03:52 2024]   Problem with getting article with id = W1514678916
Traceback (most recent call last):
  File "C:\Users\Asus\AppData\Local\Programs\Spyder\pkgs\urllib3\connection.py", line 198, in _new_conn
    sock = connection.create_connection(
  File "C:\Users\Asus\AppData\Local\Programs\Spyder\pkgs\urllib3\util\connection.py", line 85, in create_connection
    raise err
  File "C:\Users\Asus\AppData\Local\Programs\Spyder\pkgs\urllib3\util\connection.py", line 73, in create_connection
    sock.connect(sa)
TimeoutError: [WinError 10060] Попытка установить соединение была безуспешной, т.к. от другого компьютера за требуемое время не получен нужный отклик, или было разорвано уже установленное соединение из-за неверного отклика уже подключенного компьютера

The above exception was the direct cause of the following exception:

Traceback (most recent call last):
  File "C:\Users\Asus\AppData\Local\Programs\Spyder\pkgs\urllib3\connectionpool.py", line 793, in urlopen
    response = self._make_request(
  File "C:\Users\Asus\AppData\Local\Programs\Spyder\pkgs\urllib3\connectionpool.py", line 491, in _make_request
    raise new_e
  File "C:\Users\Asus\AppData\Local\Programs\Spyder\pkgs\urllib3\connectionpool.py", line 467, in _make_request
    self._validate_conn(conn)
  File "C:\Users\Asus\AppData\Local\Programs\Spyder\pkgs\urllib3\connectionpool.py", line 1099, in _validate_conn
    conn.connect()
  File "C:\Users\Asus\AppData\Local\Programs\Spyder\pkgs\urllib3\connection.py", line 616, in connect
    self.sock = sock = self._new_conn()
  File "C:\Users\Asus\AppData\Local\Programs\Spyder\pkgs\urllib3\connection.py", line 213, in _new_conn
    raise NewConnectionError(
urllib3.exceptions.NewConnectionError: <urllib3.connection.HTTPSConnection object at 0x000001E462C56190>: Failed to establish a new connection: [WinError 10060] Попытка установить соединение была безуспешной, т.к. от другого компьютера за требуемое время не получен нужный отклик, или было разорвано уже установленное соединение из-за неверного отклика уже подключенного компьютера

The above exception was the direct cause of the following exception:

Traceback (most recent call last):
  File "C:\Users\Asus\AppData\Local\Programs\Spyder\pkgs\requests\adapters.py", line 486, in send
    resp = conn.urlopen(
  File "C:\Users\Asus\AppData\Local\Programs\Spyder\pkgs\urllib3\connectionpool.py", line 847, in urlopen
    retries = retries.increment(
  File "C:\Users\Asus\AppData\Local\Programs\Spyder\pkgs\urllib3\util\retry.py", line 515, in increment
    raise MaxRetryError(_pool, url, reason) from reason  # type: ignore[arg-type]
urllib3.exceptions.MaxRetryError: HTTPSConnectionPool(host='api.openalex.org', port=443): Max retries exceeded with url: /works/W1514678916 (Caused by NewConnectionError('<urllib3.connection.HTTPSConnection object at 0x000001E462C56190>: Failed to establish a new connection: [WinError 10060] Попытка установить соединение была безуспешной, т.к. от другого компьютера за требуемое время не получен нужный отклик, или было разорвано уже установленное соединение из-за неверного отклика уже подключенного компьютера'))

During handling of the above exception, another exception occurred:

Traceback (most recent call last):
  File "c:\users\asus\onedrive\документы\github\articles-analysis\programs\downloading_referenced_works.py", line 265, in download_work_by_id
    work = Works()[id_]
  File "C:\Users\Asus\AppData\Local\Programs\Spyder\Python\lib\site-packages\pyalex\api.py", line 225, in __getitem__
    return self._get_from_url(
  File "C:\Users\Asus\AppData\Local\Programs\Spyder\Python\lib\site-packages\pyalex\api.py", line 257, in _get_from_url
    res = _get_requests_session().get(url, auth=OpenAlexAuth(config))
  File "C:\Users\Asus\AppData\Local\Programs\Spyder\pkgs\requests\sessions.py", line 602, in get
    return self.request("GET", url, **kwargs)
  File "C:\Users\Asus\AppData\Local\Programs\Spyder\pkgs\requests\sessions.py", line 589, in request
    resp = self.send(prep, **send_kwargs)
  File "C:\Users\Asus\AppData\Local\Programs\Spyder\pkgs\requests\sessions.py", line 703, in send
    r = adapter.send(request, **kwargs)
  File "C:\Users\Asus\AppData\Local\Programs\Spyder\pkgs\requests\adapters.py", line 519, in send
    raise ConnectionError(e, request=request)
requests.exceptions.ConnectionError: HTTPSConnectionPool(host='api.openalex.org', port=443): Max retries exceeded with url: /works/W1514678916 (Caused by NewConnectionError('<urllib3.connection.HTTPSConnection object at 0x000001E462C56190>: Failed to establish a new connection: [WinError 10060] Попытка установить соединение была безуспешной, т.к. от другого компьютера за требуемое время не получен нужный отклик, или было разорвано уже установленное соединение из-за неверного отклика уже подключенного компьютера'))


[Wed Apr  3 17:04:20 2024]   Problem with getting article with id = W2151157215
Traceback (most recent call last):
  File "C:\Users\Asus\AppData\Local\Programs\Spyder\pkgs\urllib3\connection.py", line 198, in _new_conn
    sock = connection.create_connection(
  File "C:\Users\Asus\AppData\Local\Programs\Spyder\pkgs\urllib3\util\connection.py", line 85, in create_connection
    raise err
  File "C:\Users\Asus\AppData\Local\Programs\Spyder\pkgs\urllib3\util\connection.py", line 73, in create_connection
    sock.connect(sa)
TimeoutError: [WinError 10060] Попытка установить соединение была безуспешной, т.к. от другого компьютера за требуемое время не получен нужный отклик, или было разорвано уже установленное соединение из-за неверного отклика уже подключенного компьютера

The above exception was the direct cause of the following exception:

Traceback (most recent call last):
  File "C:\Users\Asus\AppData\Local\Programs\Spyder\pkgs\urllib3\connectionpool.py", line 793, in urlopen
    response = self._make_request(
  File "C:\Users\Asus\AppData\Local\Programs\Spyder\pkgs\urllib3\connectionpool.py", line 491, in _make_request
    raise new_e
  File "C:\Users\Asus\AppData\Local\Programs\Spyder\pkgs\urllib3\connectionpool.py", line 467, in _make_request
    self._validate_conn(conn)
  File "C:\Users\Asus\AppData\Local\Programs\Spyder\pkgs\urllib3\connectionpool.py", line 1099, in _validate_conn
    conn.connect()
  File "C:\Users\Asus\AppData\Local\Programs\Spyder\pkgs\urllib3\connection.py", line 616, in connect
    self.sock = sock = self._new_conn()
  File "C:\Users\Asus\AppData\Local\Programs\Spyder\pkgs\urllib3\connection.py", line 213, in _new_conn
    raise NewConnectionError(
urllib3.exceptions.NewConnectionError: <urllib3.connection.HTTPSConnection object at 0x000001E462DBFA60>: Failed to establish a new connection: [WinError 10060] Попытка установить соединение была безуспешной, т.к. от другого компьютера за требуемое время не получен нужный отклик, или было разорвано уже установленное соединение из-за неверного отклика уже подключенного компьютера

The above exception was the direct cause of the following exception:

Traceback (most recent call last):
  File "C:\Users\Asus\AppData\Local\Programs\Spyder\pkgs\requests\adapters.py", line 486, in send
    resp = conn.urlopen(
  File "C:\Users\Asus\AppData\Local\Programs\Spyder\pkgs\urllib3\connectionpool.py", line 847, in urlopen
    retries = retries.increment(
  File "C:\Users\Asus\AppData\Local\Programs\Spyder\pkgs\urllib3\util\retry.py", line 515, in increment
    raise MaxRetryError(_pool, url, reason) from reason  # type: ignore[arg-type]
urllib3.exceptions.MaxRetryError: HTTPSConnectionPool(host='api.openalex.org', port=443): Max retries exceeded with url: /works/W2151157215 (Caused by NewConnectionError('<urllib3.connection.HTTPSConnection object at 0x000001E462DBFA60>: Failed to establish a new connection: [WinError 10060] Попытка установить соединение была безуспешной, т.к. от другого компьютера за требуемое время не получен нужный отклик, или было разорвано уже установленное соединение из-за неверного отклика уже подключенного компьютера'))

During handling of the above exception, another exception occurred:

Traceback (most recent call last):
  File "c:\users\asus\onedrive\документы\github\articles-analysis\programs\downloading_referenced_works.py", line 265, in download_work_by_id
    work = Works()[id_]
  File "C:\Users\Asus\AppData\Local\Programs\Spyder\Python\lib\site-packages\pyalex\api.py", line 225, in __getitem__
    return self._get_from_url(
  File "C:\Users\Asus\AppData\Local\Programs\Spyder\Python\lib\site-packages\pyalex\api.py", line 257, in _get_from_url
    res = _get_requests_session().get(url, auth=OpenAlexAuth(config))
  File "C:\Users\Asus\AppData\Local\Programs\Spyder\pkgs\requests\sessions.py", line 602, in get
    return self.request("GET", url, **kwargs)
  File "C:\Users\Asus\AppData\Local\Programs\Spyder\pkgs\requests\sessions.py", line 589, in request
    resp = self.send(prep, **send_kwargs)
  File "C:\Users\Asus\AppData\Local\Programs\Spyder\pkgs\requests\sessions.py", line 703, in send
    r = adapter.send(request, **kwargs)
  File "C:\Users\Asus\AppData\Local\Programs\Spyder\pkgs\requests\adapters.py", line 519, in send
    raise ConnectionError(e, request=request)
requests.exceptions.ConnectionError: HTTPSConnectionPool(host='api.openalex.org', port=443): Max retries exceeded with url: /works/W2151157215 (Caused by NewConnectionError('<urllib3.connection.HTTPSConnection object at 0x000001E462DBFA60>: Failed to establish a new connection: [WinError 10060] Попытка установить соединение была безуспешной, т.к. от другого компьютера за требуемое время не получен нужный отклик, или было разорвано уже установленное соединение из-за неверного отклика уже подключенного компьютера'))


[Wed Apr  3 17:04:21 2024]   Problem with getting article with id = W2302080786
Traceback (most recent call last):
  File "C:\Users\Asus\AppData\Local\Programs\Spyder\pkgs\urllib3\connection.py", line 198, in _new_conn
    sock = connection.create_connection(
  File "C:\Users\Asus\AppData\Local\Programs\Spyder\pkgs\urllib3\util\connection.py", line 85, in create_connection
    raise err
  File "C:\Users\Asus\AppData\Local\Programs\Spyder\pkgs\urllib3\util\connection.py", line 73, in create_connection
    sock.connect(sa)
TimeoutError: [WinError 10060] Попытка установить соединение была безуспешной, т.к. от другого компьютера за требуемое время не получен нужный отклик, или было разорвано уже установленное соединение из-за неверного отклика уже подключенного компьютера

The above exception was the direct cause of the following exception:

Traceback (most recent call last):
  File "C:\Users\Asus\AppData\Local\Programs\Spyder\pkgs\urllib3\connectionpool.py", line 793, in urlopen
    response = self._make_request(
  File "C:\Users\Asus\AppData\Local\Programs\Spyder\pkgs\urllib3\connectionpool.py", line 491, in _make_request
    raise new_e
  File "C:\Users\Asus\AppData\Local\Programs\Spyder\pkgs\urllib3\connectionpool.py", line 467, in _make_request
    self._validate_conn(conn)
  File "C:\Users\Asus\AppData\Local\Programs\Spyder\pkgs\urllib3\connectionpool.py", line 1099, in _validate_conn
    conn.connect()
  File "C:\Users\Asus\AppData\Local\Programs\Spyder\pkgs\urllib3\connection.py", line 616, in connect
    self.sock = sock = self._new_conn()
  File "C:\Users\Asus\AppData\Local\Programs\Spyder\pkgs\urllib3\connection.py", line 213, in _new_conn
    raise NewConnectionError(
urllib3.exceptions.NewConnectionError: <urllib3.connection.HTTPSConnection object at 0x000001E462D4DB80>: Failed to establish a new connection: [WinError 10060] Попытка установить соединение была безуспешной, т.к. от другого компьютера за требуемое время не получен нужный отклик, или было разорвано уже установленное соединение из-за неверного отклика уже подключенного компьютера

The above exception was the direct cause of the following exception:

Traceback (most recent call last):
  File "C:\Users\Asus\AppData\Local\Programs\Spyder\pkgs\requests\adapters.py", line 486, in send
    resp = conn.urlopen(
  File "C:\Users\Asus\AppData\Local\Programs\Spyder\pkgs\urllib3\connectionpool.py", line 847, in urlopen
    retries = retries.increment(
  File "C:\Users\Asus\AppData\Local\Programs\Spyder\pkgs\urllib3\util\retry.py", line 515, in increment
    raise MaxRetryError(_pool, url, reason) from reason  # type: ignore[arg-type]
urllib3.exceptions.MaxRetryError: HTTPSConnectionPool(host='api.openalex.org', port=443): Max retries exceeded with url: /works/W2302080786 (Caused by NewConnectionError('<urllib3.connection.HTTPSConnection object at 0x000001E462D4DB80>: Failed to establish a new connection: [WinError 10060] Попытка установить соединение была безуспешной, т.к. от другого компьютера за требуемое время не получен нужный отклик, или было разорвано уже установленное соединение из-за неверного отклика уже подключенного компьютера'))

During handling of the above exception, another exception occurred:

Traceback (most recent call last):
  File "c:\users\asus\onedrive\документы\github\articles-analysis\programs\downloading_referenced_works.py", line 265, in download_work_by_id
    work = Works()[id_]
  File "C:\Users\Asus\AppData\Local\Programs\Spyder\Python\lib\site-packages\pyalex\api.py", line 225, in __getitem__
    return self._get_from_url(
  File "C:\Users\Asus\AppData\Local\Programs\Spyder\Python\lib\site-packages\pyalex\api.py", line 257, in _get_from_url
    res = _get_requests_session().get(url, auth=OpenAlexAuth(config))
  File "C:\Users\Asus\AppData\Local\Programs\Spyder\pkgs\requests\sessions.py", line 602, in get
    return self.request("GET", url, **kwargs)
  File "C:\Users\Asus\AppData\Local\Programs\Spyder\pkgs\requests\sessions.py", line 589, in request
    resp = self.send(prep, **send_kwargs)
  File "C:\Users\Asus\AppData\Local\Programs\Spyder\pkgs\requests\sessions.py", line 703, in send
    r = adapter.send(request, **kwargs)
  File "C:\Users\Asus\AppData\Local\Programs\Spyder\pkgs\requests\adapters.py", line 519, in send
    raise ConnectionError(e, request=request)
requests.exceptions.ConnectionError: HTTPSConnectionPool(host='api.openalex.org', port=443): Max retries exceeded with url: /works/W2302080786 (Caused by NewConnectionError('<urllib3.connection.HTTPSConnection object at 0x000001E462D4DB80>: Failed to establish a new connection: [WinError 10060] Попытка установить соединение была безуспешной, т.к. от другого компьютера за требуемое время не получен нужный отклик, или было разорвано уже установленное соединение из-за неверного отклика уже подключенного компьютера'))


[Wed Apr  3 17:04:26 2024]   Problem with getting article with id = W2962756223
Traceback (most recent call last):
  File "C:\Users\Asus\AppData\Local\Programs\Spyder\pkgs\urllib3\connection.py", line 198, in _new_conn
    sock = connection.create_connection(
  File "C:\Users\Asus\AppData\Local\Programs\Spyder\pkgs\urllib3\util\connection.py", line 85, in create_connection
    raise err
  File "C:\Users\Asus\AppData\Local\Programs\Spyder\pkgs\urllib3\util\connection.py", line 73, in create_connection
    sock.connect(sa)
TimeoutError: [WinError 10060] Попытка установить соединение была безуспешной, т.к. от другого компьютера за требуемое время не получен нужный отклик, или было разорвано уже установленное соединение из-за неверного отклика уже подключенного компьютера

The above exception was the direct cause of the following exception:

Traceback (most recent call last):
  File "C:\Users\Asus\AppData\Local\Programs\Spyder\pkgs\urllib3\connectionpool.py", line 793, in urlopen
    response = self._make_request(
  File "C:\Users\Asus\AppData\Local\Programs\Spyder\pkgs\urllib3\connectionpool.py", line 491, in _make_request
    raise new_e
  File "C:\Users\Asus\AppData\Local\Programs\Spyder\pkgs\urllib3\connectionpool.py", line 467, in _make_request
    self._validate_conn(conn)
  File "C:\Users\Asus\AppData\Local\Programs\Spyder\pkgs\urllib3\connectionpool.py", line 1099, in _validate_conn
    conn.connect()
  File "C:\Users\Asus\AppData\Local\Programs\Spyder\pkgs\urllib3\connection.py", line 616, in connect
    self.sock = sock = self._new_conn()
  File "C:\Users\Asus\AppData\Local\Programs\Spyder\pkgs\urllib3\connection.py", line 213, in _new_conn
    raise NewConnectionError(
urllib3.exceptions.NewConnectionError: <urllib3.connection.HTTPSConnection object at 0x000001E462D3E100>: Failed to establish a new connection: [WinError 10060] Попытка установить соединение была безуспешной, т.к. от другого компьютера за требуемое время не получен нужный отклик, или было разорвано уже установленное соединение из-за неверного отклика уже подключенного компьютера

The above exception was the direct cause of the following exception:

Traceback (most recent call last):
  File "C:\Users\Asus\AppData\Local\Programs\Spyder\pkgs\requests\adapters.py", line 486, in send
    resp = conn.urlopen(
  File "C:\Users\Asus\AppData\Local\Programs\Spyder\pkgs\urllib3\connectionpool.py", line 847, in urlopen
    retries = retries.increment(
  File "C:\Users\Asus\AppData\Local\Programs\Spyder\pkgs\urllib3\util\retry.py", line 515, in increment
    raise MaxRetryError(_pool, url, reason) from reason  # type: ignore[arg-type]
urllib3.exceptions.MaxRetryError: HTTPSConnectionPool(host='api.openalex.org', port=443): Max retries exceeded with url: /works/W2962756223 (Caused by NewConnectionError('<urllib3.connection.HTTPSConnection object at 0x000001E462D3E100>: Failed to establish a new connection: [WinError 10060] Попытка установить соединение была безуспешной, т.к. от другого компьютера за требуемое время не получен нужный отклик, или было разорвано уже установленное соединение из-за неверного отклика уже подключенного компьютера'))

During handling of the above exception, another exception occurred:

Traceback (most recent call last):
  File "c:\users\asus\onedrive\документы\github\articles-analysis\programs\downloading_referenced_works.py", line 265, in download_work_by_id
    work = Works()[id_]
  File "C:\Users\Asus\AppData\Local\Programs\Spyder\Python\lib\site-packages\pyalex\api.py", line 225, in __getitem__
    return self._get_from_url(
  File "C:\Users\Asus\AppData\Local\Programs\Spyder\Python\lib\site-packages\pyalex\api.py", line 257, in _get_from_url
    res = _get_requests_session().get(url, auth=OpenAlexAuth(config))
  File "C:\Users\Asus\AppData\Local\Programs\Spyder\pkgs\requests\sessions.py", line 602, in get
    return self.request("GET", url, **kwargs)
  File "C:\Users\Asus\AppData\Local\Programs\Spyder\pkgs\requests\sessions.py", line 589, in request
    resp = self.send(prep, **send_kwargs)
  File "C:\Users\Asus\AppData\Local\Programs\Spyder\pkgs\requests\sessions.py", line 703, in send
    r = adapter.send(request, **kwargs)
  File "C:\Users\Asus\AppData\Local\Programs\Spyder\pkgs\requests\adapters.py", line 519, in send
    raise ConnectionError(e, request=request)
requests.exceptions.ConnectionError: HTTPSConnectionPool(host='api.openalex.org', port=443): Max retries exceeded with url: /works/W2962756223 (Caused by NewConnectionError('<urllib3.connection.HTTPSConnection object at 0x000001E462D3E100>: Failed to establish a new connection: [WinError 10060] Попытка установить соединение была безуспешной, т.к. от другого компьютера за требуемое время не получен нужный отклик, или было разорвано уже установленное соединение из-за неверного отклика уже подключенного компьютера'))


[Wed Apr  3 17:05:01 2024]   count: 500, speed: 0.445 sec/article, request: 50.9%, db: 0.6, other: 48.5%

[Wed Apr  3 17:06:28 2024]   count: 500, speed: 0.174 sec/article, request: 97.9%, db: 1.7, other: 0.4%

[Wed Apr  3 17:06:44 2024]   Problem with adding article with id = W2286058889
Traceback (most recent call last):
  File "c:\users\asus\onedrive\документы\github\articles-analysis\programs\downloading_referenced_works.py", line 289, in download_work_by_id
    cursor.execute(f"""
sqlite3.IntegrityError: UNIQUE constraint failed: articles.id


[Wed Apr  3 17:07:22 2024]   Problem with adding article with id = W2468144410
Traceback (most recent call last):
  File "c:\users\asus\onedrive\документы\github\articles-analysis\programs\downloading_referenced_works.py", line 289, in download_work_by_id
    cursor.execute(f"""
sqlite3.IntegrityError: UNIQUE constraint failed: articles.id


[Wed Apr  3 17:07:40 2024]   Problem with adding article with id = W2490895042
Traceback (most recent call last):
  File "c:\users\asus\onedrive\документы\github\articles-analysis\programs\downloading_referenced_works.py", line 289, in download_work_by_id
    cursor.execute(f"""
sqlite3.IntegrityError: UNIQUE constraint failed: articles.id


[Wed Apr  3 17:07:55 2024]   count: 500, speed: 0.172 sec/article, request: 98.1%, db: 1.6, other: 0.3%

[Wed Apr  3 17:08:43 2024]   Problem with adding article with id = W2602060569
Traceback (most recent call last):
  File "c:\users\asus\onedrive\документы\github\articles-analysis\programs\downloading_referenced_works.py", line 289, in download_work_by_id
    cursor.execute(f"""
sqlite3.IntegrityError: UNIQUE constraint failed: articles.id


[Wed Apr  3 17:08:51 2024]   Problem with adding article with id = W237826247
Traceback (most recent call last):
  File "c:\users\asus\onedrive\документы\github\articles-analysis\programs\downloading_referenced_works.py", line 289, in download_work_by_id
    cursor.execute(f"""
sqlite3.IntegrityError: UNIQUE constraint failed: articles.id


[Wed Apr  3 17:09:22 2024]   count: 500, speed: 0.176 sec/article, request: 97.5%, db: 2.0, other: 0.5%

[Wed Apr  3 17:09:36 2024]   Problem with adding article with id = W2601746524
Traceback (most recent call last):
  File "c:\users\asus\onedrive\документы\github\articles-analysis\programs\downloading_referenced_works.py", line 289, in download_work_by_id
    cursor.execute(f"""
sqlite3.IntegrityError: UNIQUE constraint failed: articles.id


[Wed Apr  3 17:09:59 2024]   Problem with adding article with id = W2549691471
Traceback (most recent call last):
  File "c:\users\asus\onedrive\документы\github\articles-analysis\programs\downloading_referenced_works.py", line 289, in download_work_by_id
    cursor.execute(f"""
sqlite3.IntegrityError: UNIQUE constraint failed: articles.id


[Wed Apr  3 17:10:55 2024]   count: 500, speed: 0.186 sec/article, request: 96.4%, db: 2.7, other: 0.9%

[Wed Apr  3 17:11:02 2024]   Problem with adding article with id = W2499489672
Traceback (most recent call last):
  File "c:\users\asus\onedrive\документы\github\articles-analysis\programs\downloading_referenced_works.py", line 289, in download_work_by_id
    cursor.execute(f"""
sqlite3.IntegrityError: UNIQUE constraint failed: articles.id


[Wed Apr  3 17:11:19 2024]   Problem with adding article with id = W2561493030
Traceback (most recent call last):
  File "c:\users\asus\onedrive\документы\github\articles-analysis\programs\downloading_referenced_works.py", line 289, in download_work_by_id
    cursor.execute(f"""
sqlite3.IntegrityError: UNIQUE constraint failed: articles.id


[Wed Apr  3 17:11:30 2024]   Problem with adding article with id = W52024650
Traceback (most recent call last):
  File "c:\users\asus\onedrive\документы\github\articles-analysis\programs\downloading_referenced_works.py", line 289, in download_work_by_id
    cursor.execute(f"""
sqlite3.IntegrityError: UNIQUE constraint failed: articles.id


[Wed Apr  3 17:12:26 2024]   count: 500, speed: 0.181 sec/article, request: 96.6%, db: 2.5, other: 0.9%

[Wed Apr  3 17:12:49 2024]   Problem with adding article with id = W2470660452
Traceback (most recent call last):
  File "c:\users\asus\onedrive\документы\github\articles-analysis\programs\downloading_referenced_works.py", line 289, in download_work_by_id
    cursor.execute(f"""
sqlite3.IntegrityError: UNIQUE constraint failed: articles.id


[Wed Apr  3 17:14:00 2024]   count: 500, speed: 0.188 sec/article, request: 96.3%, db: 2.8, other: 0.9%

[Wed Apr  3 17:14:06 2024]   Problem with adding article with id = W2585176927
Traceback (most recent call last):
  File "c:\users\asus\onedrive\документы\github\articles-analysis\programs\downloading_referenced_works.py", line 289, in download_work_by_id
    cursor.execute(f"""
sqlite3.IntegrityError: UNIQUE constraint failed: articles.id


[Wed Apr  3 17:14:22 2024]   Problem with adding article with id = W1980073965
Traceback (most recent call last):
  File "c:\users\asus\onedrive\документы\github\articles-analysis\programs\downloading_referenced_works.py", line 289, in download_work_by_id
    cursor.execute(f"""
sqlite3.IntegrityError: UNIQUE constraint failed: articles.id


[Wed Apr  3 17:14:34 2024]   Problem with adding article with id = W2515044715
Traceback (most recent call last):
  File "c:\users\asus\onedrive\документы\github\articles-analysis\programs\downloading_referenced_works.py", line 289, in download_work_by_id
    cursor.execute(f"""
sqlite3.IntegrityError: UNIQUE constraint failed: articles.id


[Wed Apr  3 17:15:33 2024]   count: 500, speed: 0.185 sec/article, request: 96.3%, db: 2.6, other: 1.1%

[Wed Apr  3 17:17:07 2024]   Problem with adding article with id = W2522363950
Traceback (most recent call last):
  File "c:\users\asus\onedrive\документы\github\articles-analysis\programs\downloading_referenced_works.py", line 289, in download_work_by_id
    cursor.execute(f"""
sqlite3.IntegrityError: UNIQUE constraint failed: articles.id


[Wed Apr  3 17:17:12 2024]   count: 500, speed: 0.186 sec/article, request: 96.9%, db: 2.4, other: 0.7%

[Wed Apr  3 17:17:22 2024]   Problem with getting article with id = W2145820903
urllib3.exceptions.ProtocolError: ('Connection aborted.', TimeoutError(10060, 'Попытка установить соединение была безуспешной, т.к. от другого компьютера за требуемое время не получен нужный отклик, или было разорвано уже установленное соединение из-за неверного отклика уже подключенного компьютера', None, 10060, None))

The above exception was the direct cause of the following exception:

Traceback (most recent call last):
  File "C:\Users\Asus\AppData\Local\Programs\Spyder\pkgs\requests\adapters.py", line 486, in send
    resp = conn.urlopen(
  File "C:\Users\Asus\AppData\Local\Programs\Spyder\pkgs\urllib3\connectionpool.py", line 847, in urlopen
    retries = retries.increment(
  File "C:\Users\Asus\AppData\Local\Programs\Spyder\pkgs\urllib3\util\retry.py", line 515, in increment
    raise MaxRetryError(_pool, url, reason) from reason  # type: ignore[arg-type]
urllib3.exceptions.MaxRetryError: HTTPSConnectionPool(host='api.openalex.org', port=443): Max retries exceeded with url: /works/W2145820903 (Caused by ProtocolError('Connection aborted.', TimeoutError(10060, 'Попытка установить соединение была безуспешной, т.к. от другого компьютера за требуемое время не получен нужный отклик, или было разорвано уже установленное соединение из-за неверного отклика уже подключенного компьютера', None, 10060, None)))

During handling of the above exception, another exception occurred:

Traceback (most recent call last):
  File "c:\users\asus\onedrive\документы\github\articles-analysis\programs\downloading_referenced_works.py", line 265, in download_work_by_id
    work = Works()[id_]
  File "C:\Users\Asus\AppData\Local\Programs\Spyder\Python\lib\site-packages\pyalex\api.py", line 225, in __getitem__
    return self._get_from_url(
  File "C:\Users\Asus\AppData\Local\Programs\Spyder\Python\lib\site-packages\pyalex\api.py", line 257, in _get_from_url
    res = _get_requests_session().get(url, auth=OpenAlexAuth(config))
  File "C:\Users\Asus\AppData\Local\Programs\Spyder\pkgs\requests\sessions.py", line 602, in get
    return self.request("GET", url, **kwargs)
  File "C:\Users\Asus\AppData\Local\Programs\Spyder\pkgs\requests\sessions.py", line 589, in request
    resp = self.send(prep, **send_kwargs)
  File "C:\Users\Asus\AppData\Local\Programs\Spyder\pkgs\requests\sessions.py", line 703, in send
    r = adapter.send(request, **kwargs)
  File "C:\Users\Asus\AppData\Local\Programs\Spyder\pkgs\requests\adapters.py", line 519, in send
    raise ConnectionError(e, request=request)
requests.exceptions.ConnectionError: HTTPSConnectionPool(host='api.openalex.org', port=443): Max retries exceeded with url: /works/W2145820903 (Caused by ProtocolError('Connection aborted.', TimeoutError(10060, 'Попытка установить соединение была безуспешной, т.к. от другого компьютера за требуемое время не получен нужный отклик, или было разорвано уже установленное соединение из-за неверного отклика уже подключенного компьютера', None, 10060, None)))


[Wed Apr  3 17:18:47 2024]   count: 500, speed: 0.203 sec/article, request: 88.0%, db: 2.6, other: 9.4%

[Wed Apr  3 17:19:16 2024]   Problem with adding article with id = W2513006269
Traceback (most recent call last):
  File "c:\users\asus\onedrive\документы\github\articles-analysis\programs\downloading_referenced_works.py", line 289, in download_work_by_id
    cursor.execute(f"""
sqlite3.IntegrityError: UNIQUE constraint failed: articles.id


[Wed Apr  3 17:20:03 2024]   Problem with adding article with id = W2798635129
Traceback (most recent call last):
  File "c:\users\asus\onedrive\документы\github\articles-analysis\programs\downloading_referenced_works.py", line 289, in download_work_by_id
    cursor.execute(f"""
sqlite3.IntegrityError: UNIQUE constraint failed: articles.id


[Wed Apr  3 17:20:17 2024]   count: 500, speed: 0.181 sec/article, request: 97.0%, db: 2.1, other: 0.9%

[Wed Apr  3 17:21:52 2024]   count: 500, speed: 0.189 sec/article, request: 96.6%, db: 2.6, other: 0.8%

[Wed Apr  3 17:22:48 2024]   Problem with adding article with id = W2482445997
Traceback (most recent call last):
  File "c:\users\asus\onedrive\документы\github\articles-analysis\programs\downloading_referenced_works.py", line 289, in download_work_by_id
    cursor.execute(f"""
sqlite3.IntegrityError: UNIQUE constraint failed: articles.id


[Wed Apr  3 17:23:06 2024]   Problem with adding article with id = W2514009898
Traceback (most recent call last):
  File "c:\users\asus\onedrive\документы\github\articles-analysis\programs\downloading_referenced_works.py", line 289, in download_work_by_id
    cursor.execute(f"""
sqlite3.IntegrityError: UNIQUE constraint failed: articles.id


[Wed Apr  3 17:23:24 2024]   count: 500, speed: 0.184 sec/article, request: 96.0%, db: 3.0, other: 1.0%

[Wed Apr  3 17:23:40 2024]   Problem with adding article with id = W2518472289
Traceback (most recent call last):
  File "c:\users\asus\onedrive\документы\github\articles-analysis\programs\downloading_referenced_works.py", line 289, in download_work_by_id
    cursor.execute(f"""
sqlite3.IntegrityError: UNIQUE constraint failed: articles.id


[Wed Apr  3 17:23:52 2024]   Problem with adding article with id = W2484247661
Traceback (most recent call last):
  File "c:\users\asus\onedrive\документы\github\articles-analysis\programs\downloading_referenced_works.py", line 289, in download_work_by_id
    cursor.execute(f"""
sqlite3.IntegrityError: UNIQUE constraint failed: articles.id


[Wed Apr  3 17:24:56 2024]   count: 500, speed: 0.184 sec/article, request: 96.7%, db: 2.5, other: 0.8%

[Wed Apr  3 17:25:50 2024]   Problem with adding article with id = W191136218
Traceback (most recent call last):
  File "c:\users\asus\onedrive\документы\github\articles-analysis\programs\downloading_referenced_works.py", line 289, in download_work_by_id
    cursor.execute(f"""
sqlite3.IntegrityError: UNIQUE constraint failed: articles.id


[Wed Apr  3 17:26:26 2024]   count: 500, speed: 0.18 sec/article, request: 96.4%, db: 2.7, other: 0.9%

[Wed Apr  3 17:27:06 2024]   Problem with adding article with id = W3010157316
Traceback (most recent call last):
  File "c:\users\asus\onedrive\документы\github\articles-analysis\programs\downloading_referenced_works.py", line 289, in download_work_by_id
    cursor.execute(f"""
sqlite3.IntegrityError: UNIQUE constraint failed: articles.id


[Wed Apr  3 17:27:54 2024]   count: 500, speed: 0.177 sec/article, request: 97.0%, db: 2.2, other: 0.8%

[Wed Apr  3 17:28:45 2024]   Problem with adding article with id = W3146280828
Traceback (most recent call last):
  File "c:\users\asus\onedrive\документы\github\articles-analysis\programs\downloading_referenced_works.py", line 289, in download_work_by_id
    cursor.execute(f"""
sqlite3.IntegrityError: UNIQUE constraint failed: articles.id


[Wed Apr  3 17:29:29 2024]   count: 500, speed: 0.189 sec/article, request: 94.2%, db: 4.8, other: 1.0%

[Wed Apr  3 17:30:01 2024]   Problem with adding article with id = W2070708314
Traceback (most recent call last):
  File "c:\users\asus\onedrive\документы\github\articles-analysis\programs\downloading_referenced_works.py", line 289, in download_work_by_id
    cursor.execute(f"""
sqlite3.IntegrityError: UNIQUE constraint failed: articles.id


[Wed Apr  3 17:30:55 2024]   count: 500, speed: 0.171 sec/article, request: 97.0%, db: 2.2, other: 0.8%

[Wed Apr  3 17:32:06 2024]   Problem with adding article with id = W2300568780
Traceback (most recent call last):
  File "c:\users\asus\onedrive\документы\github\articles-analysis\programs\downloading_referenced_works.py", line 289, in download_work_by_id
    cursor.execute(f"""
sqlite3.IntegrityError: UNIQUE constraint failed: articles.id


[Wed Apr  3 17:32:20 2024]   Problem with adding article with id = W2417411764
Traceback (most recent call last):
  File "c:\users\asus\onedrive\документы\github\articles-analysis\programs\downloading_referenced_works.py", line 289, in download_work_by_id
    cursor.execute(f"""
sqlite3.IntegrityError: UNIQUE constraint failed: articles.id


[Wed Apr  3 17:32:22 2024]   count: 500, speed: 0.176 sec/article, request: 97.0%, db: 2.4, other: 0.6%

[Wed Apr  3 17:32:39 2024]   Problem with adding article with id = W2531282327
Traceback (most recent call last):
  File "c:\users\asus\onedrive\документы\github\articles-analysis\programs\downloading_referenced_works.py", line 289, in download_work_by_id
    cursor.execute(f"""
sqlite3.IntegrityError: UNIQUE constraint failed: articles.id


[Wed Apr  3 17:33:55 2024]   count: 500, speed: 0.185 sec/article, request: 96.0%, db: 3.2, other: 0.8%

[Wed Apr  3 17:34:48 2024]   Problem with adding article with id = W2891212941
Traceback (most recent call last):
  File "c:\users\asus\onedrive\документы\github\articles-analysis\programs\downloading_referenced_works.py", line 289, in download_work_by_id
    cursor.execute(f"""
sqlite3.IntegrityError: UNIQUE constraint failed: articles.id


