


Start downloading works_by_ids in 4 thread(s) at [Fri Mar 29 13:31:12 2024]



[Fri Mar 29 13:31:16 2024] Problem with adding article with id = W2513624866
Traceback (most recent call last):
  File "/home/george/Документы/harddrive/articles-analysis/programs/downloading_referenced_works.py", line 383, in download_work_by_id
    cursor.execute(f"""
sqlite3.IntegrityError: UNIQUE constraint failed: articles.id

[Fri Mar 29 13:31:18 2024] Problem with adding article with id = W1993647687
Traceback (most recent call last):
  File "/home/george/Документы/harddrive/articles-analysis/programs/downloading_referenced_works.py", line 383, in download_work_by_id
    cursor.execute(f"""
sqlite3.IntegrityError: UNIQUE constraint failed: articles.id

[Fri Mar 29 13:31:20 2024] Problem with adding article with id = W151371647
Traceback (most recent call last):
  File "/home/george/Документы/harddrive/articles-analysis/programs/downloading_referenced_works.py", line 383, in download_work_by_id
    cursor.execute(f"""
sqlite3.IntegrityError: UNIQUE constraint failed: articles.id

[Fri Mar 29 13:31:21 2024] Problem with adding article with id = W2527474788
Traceback (most recent call last):
  File "/home/george/Документы/harddrive/articles-analysis/programs/downloading_referenced_works.py", line 383, in download_work_by_id
    cursor.execute(f"""
sqlite3.IntegrityError: UNIQUE constraint failed: articles.id

[Fri Mar 29 13:31:25 2024] Problem with adding article with id = W3141088523
Traceback (most recent call last):
  File "/home/george/Документы/harddrive/articles-analysis/programs/downloading_referenced_works.py", line 383, in download_work_by_id
    cursor.execute(f"""
sqlite3.IntegrityError: UNIQUE constraint failed: articles.id

[Fri Mar 29 13:31:27 2024] Problem with getting article with id = W2163749592
Traceback (most recent call last):
  File "/home/george/Документы/harddrive/articles-analysis/programs/downloading_referenced_works.py", line 357, in download_work_by_id
    work = Works()[id_]
  File "/usr/local/lib/python3.10/dist-packages/pyalex/api.py", line 225, in __getitem__
    return self._get_from_url(
  File "/usr/local/lib/python3.10/dist-packages/pyalex/api.py", line 267, in _get_from_url
    res.raise_for_status()
  File "/usr/lib/python3/dist-packages/requests/models.py", line 943, in raise_for_status
    raise HTTPError(http_error_msg, response=self)
requests.exceptions.HTTPError: 404 Client Error: NOT FOUND for url: https://api.openalex.org/works/W2163749592

[Fri Mar 29 13:31:29 2024] Problem with adding article with id = W2517496203
Traceback (most recent call last):
  File "/home/george/Документы/harddrive/articles-analysis/programs/downloading_referenced_works.py", line 383, in download_work_by_id
    cursor.execute(f"""
sqlite3.IntegrityError: UNIQUE constraint failed: articles.id

[Fri Mar 29 13:31:30 2024] Problem with getting article with id = W2273810905
Traceback (most recent call last):
  File "/home/george/Документы/harddrive/articles-analysis/programs/downloading_referenced_works.py", line 357, in download_work_by_id
    work = Works()[id_]
  File "/usr/local/lib/python3.10/dist-packages/pyalex/api.py", line 225, in __getitem__
    return self._get_from_url(
  File "/usr/local/lib/python3.10/dist-packages/pyalex/api.py", line 267, in _get_from_url
    res.raise_for_status()
  File "/usr/lib/python3/dist-packages/requests/models.py", line 943, in raise_for_status
    raise HTTPError(http_error_msg, response=self)
requests.exceptions.HTTPError: 404 Client Error: NOT FOUND for url: https://api.openalex.org/works/W2273810905

[Fri Mar 29 13:31:33 2024] Problem with adding article with id = W2047920195
Traceback (most recent call last):
  File "/home/george/Документы/harddrive/articles-analysis/programs/downloading_referenced_works.py", line 383, in download_work_by_id
    cursor.execute(f"""
sqlite3.IntegrityError: UNIQUE constraint failed: articles.id

[Fri Mar 29 13:31:38 2024] Problem with adding article with id = W2463375402
Traceback (most recent call last):
  File "/home/george/Документы/harddrive/articles-analysis/programs/downloading_referenced_works.py", line 383, in download_work_by_id
    cursor.execute(f"""
sqlite3.IntegrityError: UNIQUE constraint failed: articles.id

[Fri Mar 29 13:31:41 2024] Problem with adding article with id = W2478845612
Traceback (most recent call last):
  File "/home/george/Документы/harddrive/articles-analysis/programs/downloading_referenced_works.py", line 383, in download_work_by_id
    cursor.execute(f"""
sqlite3.IntegrityError: UNIQUE constraint failed: articles.id

[Fri Mar 29 13:31:53 2024] Problem with adding article with id = W2480363210
Traceback (most recent call last):
  File "/home/george/Документы/harddrive/articles-analysis/programs/downloading_referenced_works.py", line 383, in download_work_by_id
    cursor.execute(f"""
sqlite3.IntegrityError: UNIQUE constraint failed: articles.id

[Fri Mar 29 13:31:55 2024] Problem with adding article with id = W2613753425
Traceback (most recent call last):
  File "/home/george/Документы/harddrive/articles-analysis/programs/downloading_referenced_works.py", line 383, in download_work_by_id
    cursor.execute(f"""
sqlite3.IntegrityError: UNIQUE constraint failed: articles.id

[Fri Mar 29 13:32:39 2024] count: 500, speed: 0.171 sec/article, request: 62.2%, db: 28.8, other: 9.0%
[Fri Mar 29 13:38:26 2024] count: 500, speed: 0.688 sec/article, request: 63.0%, db: 29.6, other: 7.4%
[Fri Mar 29 13:44:42 2024] count: 500, speed: 0.756 sec/article, request: 62.2%, db: 29.8, other: 8.0%
[Fri Mar 29 13:50:40 2024] count: 500, speed: 0.716 sec/article, request: 61.8%, db: 29.6, other: 8.6%
[Fri Mar 29 13:51:46 2024] Problem with adding article with id = W2514388202
Traceback (most recent call last):
  File "/home/george/Документы/harddrive/articles-analysis/programs/downloading_referenced_works.py", line 383, in download_work_by_id
    cursor.execute(f"""
sqlite3.IntegrityError: UNIQUE constraint failed: articles.id

[Fri Mar 29 13:56:11 2024] count: 500, speed: 0.661 sec/article, request: 71.1%, db: 23.9, other: 5.0%
[Fri Mar 29 14:01:30 2024] count: 500, speed: 0.641 sec/article, request: 70.8%, db: 23.3, other: 5.9%
[Fri Mar 29 14:05:16 2024] Problem with adding article with id = W2497598214
Traceback (most recent call last):
  File "/home/george/Документы/harddrive/articles-analysis/programs/downloading_referenced_works.py", line 383, in download_work_by_id
    cursor.execute(f"""
sqlite3.IntegrityError: UNIQUE constraint failed: articles.id

[Fri Mar 29 14:06:53 2024] count: 500, speed: 0.646 sec/article, request: 62.3%, db: 29.9, other: 7.8%
[Fri Mar 29 14:12:25 2024] count: 500, speed: 0.661 sec/article, request: 67.5%, db: 26.1, other: 6.4%
[Fri Mar 29 14:17:29 2024] count: 500, speed: 0.612 sec/article, request: 67.4%, db: 26.3, other: 6.3%
[Fri Mar 29 14:22:53 2024] count: 500, speed: 0.647 sec/article, request: 63.7%, db: 29.1, other: 7.2%
[Fri Mar 29 14:28:11 2024] Problem with getting article with id = W4214514434
Traceback (most recent call last):
  File "/usr/lib/python3/dist-packages/urllib3/connection.py", line 169, in _new_conn
    conn = connection.create_connection(
  File "/usr/lib/python3/dist-packages/urllib3/util/connection.py", line 73, in create_connection
    for res in socket.getaddrinfo(host, port, family, socket.SOCK_STREAM):
  File "/usr/lib/python3.10/socket.py", line 955, in getaddrinfo
    for res in _socket.getaddrinfo(host, port, family, type, proto, flags):
socket.gaierror: [Errno -2] Name or service not known

During handling of the above exception, another exception occurred:

Traceback (most recent call last):
  File "/usr/lib/python3/dist-packages/urllib3/connectionpool.py", line 700, in urlopen
    httplib_response = self._make_request(
  File "/usr/lib/python3/dist-packages/urllib3/connectionpool.py", line 383, in _make_request
    self._validate_conn(conn)
  File "/usr/lib/python3/dist-packages/urllib3/connectionpool.py", line 1017, in _validate_conn
    conn.connect()
  File "/usr/lib/python3/dist-packages/urllib3/connection.py", line 353, in connect
    conn = self._new_conn()
  File "/usr/lib/python3/dist-packages/urllib3/connection.py", line 181, in _new_conn
    raise NewConnectionError(
urllib3.exceptions.NewConnectionError: <urllib3.connection.HTTPSConnection object at 0x7f6748894ee0>: Failed to establish a new connection: [Errno -2] Name or service not known

During handling of the above exception, another exception occurred:

Traceback (most recent call last):
  File "/usr/lib/python3/dist-packages/requests/adapters.py", line 439, in send
    resp = conn.urlopen(
  File "/usr/lib/python3/dist-packages/urllib3/connectionpool.py", line 756, in urlopen
    retries = retries.increment(
  File "/usr/lib/python3/dist-packages/urllib3/util/retry.py", line 574, in increment
    raise MaxRetryError(_pool, url, error or ResponseError(cause))
urllib3.exceptions.MaxRetryError: HTTPSConnectionPool(host='api.openalex.org', port=443): Max retries exceeded with url: /works/W4214514434 (Caused by NewConnectionError('<urllib3.connection.HTTPSConnection object at 0x7f6748894ee0>: Failed to establish a new connection: [Errno -2] Name or service not known'))

During handling of the above exception, another exception occurred:

Traceback (most recent call last):
  File "/home/george/Документы/harddrive/articles-analysis/programs/downloading_referenced_works.py", line 357, in download_work_by_id
    work = Works()[id_]
  File "/usr/local/lib/python3.10/dist-packages/pyalex/api.py", line 225, in __getitem__
    return self._get_from_url(
  File "/usr/local/lib/python3.10/dist-packages/pyalex/api.py", line 257, in _get_from_url
    res = _get_requests_session().get(url, auth=OpenAlexAuth(config))
  File "/usr/lib/python3/dist-packages/requests/sessions.py", line 557, in get
    return self.request('GET', url, **kwargs)
  File "/usr/lib/python3/dist-packages/requests/sessions.py", line 544, in request
    resp = self.send(prep, **send_kwargs)
  File "/usr/lib/python3/dist-packages/requests/sessions.py", line 657, in send
    r = adapter.send(request, **kwargs)
  File "/usr/lib/python3/dist-packages/requests/adapters.py", line 516, in send
    raise ConnectionError(e, request=request)
requests.exceptions.ConnectionError: HTTPSConnectionPool(host='api.openalex.org', port=443): Max retries exceeded with url: /works/W4214514434 (Caused by NewConnectionError('<urllib3.connection.HTTPSConnection object at 0x7f6748894ee0>: Failed to establish a new connection: [Errno -2] Name or service not known'))

[Fri Mar 29 14:28:11 2024] Problem with getting article with id = W3102886894
Traceback (most recent call last):
  File "/usr/lib/python3/dist-packages/urllib3/connection.py", line 169, in _new_conn
    conn = connection.create_connection(
  File "/usr/lib/python3/dist-packages/urllib3/util/connection.py", line 73, in create_connection
    for res in socket.getaddrinfo(host, port, family, socket.SOCK_STREAM):
  File "/usr/lib/python3.10/socket.py", line 955, in getaddrinfo
    for res in _socket.getaddrinfo(host, port, family, type, proto, flags):
socket.gaierror: [Errno -2] Name or service not known

During handling of the above exception, another exception occurred:

Traceback (most recent call last):
  File "/usr/lib/python3/dist-packages/urllib3/connectionpool.py", line 700, in urlopen
    httplib_response = self._make_request(
  File "/usr/lib/python3/dist-packages/urllib3/connectionpool.py", line 383, in _make_request
    self._validate_conn(conn)
  File "/usr/lib/python3/dist-packages/urllib3/connectionpool.py", line 1017, in _validate_conn
    conn.connect()
  File "/usr/lib/python3/dist-packages/urllib3/connection.py", line 353, in connect
    conn = self._new_conn()
  File "/usr/lib/python3/dist-packages/urllib3/connection.py", line 181, in _new_conn
    raise NewConnectionError(
urllib3.exceptions.NewConnectionError: <urllib3.connection.HTTPSConnection object at 0x7f6748895a80>: Failed to establish a new connection: [Errno -2] Name or service not known

During handling of the above exception, another exception occurred:

Traceback (most recent call last):
  File "/usr/lib/python3/dist-packages/requests/adapters.py", line 439, in send
    resp = conn.urlopen(
  File "/usr/lib/python3/dist-packages/urllib3/connectionpool.py", line 756, in urlopen
    retries = retries.increment(
  File "/usr/lib/python3/dist-packages/urllib3/util/retry.py", line 574, in increment
    raise MaxRetryError(_pool, url, error or ResponseError(cause))
urllib3.exceptions.MaxRetryError: HTTPSConnectionPool(host='api.openalex.org', port=443): Max retries exceeded with url: /works/W3102886894 (Caused by NewConnectionError('<urllib3.connection.HTTPSConnection object at 0x7f6748895a80>: Failed to establish a new connection: [Errno -2] Name or service not known'))

During handling of the above exception, another exception occurred:

Traceback (most recent call last):
  File "/home/george/Документы/harddrive/articles-analysis/programs/downloading_referenced_works.py", line 357, in download_work_by_id
    work = Works()[id_]
  File "/usr/local/lib/python3.10/dist-packages/pyalex/api.py", line 225, in __getitem__
    return self._get_from_url(
  File "/usr/local/lib/python3.10/dist-packages/pyalex/api.py", line 257, in _get_from_url
    res = _get_requests_session().get(url, auth=OpenAlexAuth(config))
  File "/usr/lib/python3/dist-packages/requests/sessions.py", line 557, in get
    return self.request('GET', url, **kwargs)
  File "/usr/lib/python3/dist-packages/requests/sessions.py", line 544, in request
    resp = self.send(prep, **send_kwargs)
  File "/usr/lib/python3/dist-packages/requests/sessions.py", line 657, in send
    r = adapter.send(request, **kwargs)
  File "/usr/lib/python3/dist-packages/requests/adapters.py", line 516, in send
    raise ConnectionError(e, request=request)
requests.exceptions.ConnectionError: HTTPSConnectionPool(host='api.openalex.org', port=443): Max retries exceeded with url: /works/W3102886894 (Caused by NewConnectionError('<urllib3.connection.HTTPSConnection object at 0x7f6748895a80>: Failed to establish a new connection: [Errno -2] Name or service not known'))

[Fri Mar 29 14:28:11 2024] Problem with getting article with id = W2949845543
Traceback (most recent call last):
  File "/usr/lib/python3/dist-packages/urllib3/connection.py", line 169, in _new_conn
    conn = connection.create_connection(
  File "/usr/lib/python3/dist-packages/urllib3/util/connection.py", line 73, in create_connection
    for res in socket.getaddrinfo(host, port, family, socket.SOCK_STREAM):
  File "/usr/lib/python3.10/socket.py", line 955, in getaddrinfo
    for res in _socket.getaddrinfo(host, port, family, type, proto, flags):
socket.gaierror: [Errno -2] Name or service not known

During handling of the above exception, another exception occurred:

Traceback (most recent call last):
  File "/usr/lib/python3/dist-packages/urllib3/connectionpool.py", line 700, in urlopen
    httplib_response = self._make_request(
  File "/usr/lib/python3/dist-packages/urllib3/connectionpool.py", line 383, in _make_request
    self._validate_conn(conn)
  File "/usr/lib/python3/dist-packages/urllib3/connectionpool.py", line 1017, in _validate_conn
    conn.connect()
  File "/usr/lib/python3/dist-packages/urllib3/connection.py", line 353, in connect
    conn = self._new_conn()
  File "/usr/lib/python3/dist-packages/urllib3/connection.py", line 181, in _new_conn
    raise NewConnectionError(
urllib3.exceptions.NewConnectionError: <urllib3.connection.HTTPSConnection object at 0x7f67487a47f0>: Failed to establish a new connection: [Errno -2] Name or service not known

During handling of the above exception, another exception occurred:

Traceback (most recent call last):
  File "/usr/lib/python3/dist-packages/requests/adapters.py", line 439, in send
    resp = conn.urlopen(
  File "/usr/lib/python3/dist-packages/urllib3/connectionpool.py", line 756, in urlopen
    retries = retries.increment(
  File "/usr/lib/python3/dist-packages/urllib3/util/retry.py", line 574, in increment
    raise MaxRetryError(_pool, url, error or ResponseError(cause))
urllib3.exceptions.MaxRetryError: HTTPSConnectionPool(host='api.openalex.org', port=443): Max retries exceeded with url: /works/W2949845543 (Caused by NewConnectionError('<urllib3.connection.HTTPSConnection object at 0x7f67487a47f0>: Failed to establish a new connection: [Errno -2] Name or service not known'))

During handling of the above exception, another exception occurred:

Traceback (most recent call last):
  File "/home/george/Документы/harddrive/articles-analysis/programs/downloading_referenced_works.py", line 357, in download_work_by_id
    work = Works()[id_]
  File "/usr/local/lib/python3.10/dist-packages/pyalex/api.py", line 225, in __getitem__
    return self._get_from_url(
  File "/usr/local/lib/python3.10/dist-packages/pyalex/api.py", line 257, in _get_from_url
    res = _get_requests_session().get(url, auth=OpenAlexAuth(config))
  File "/usr/lib/python3/dist-packages/requests/sessions.py", line 557, in get
    return self.request('GET', url, **kwargs)
  File "/usr/lib/python3/dist-packages/requests/sessions.py", line 544, in request
    resp = self.send(prep, **send_kwargs)
  File "/usr/lib/python3/dist-packages/requests/sessions.py", line 657, in send
    r = adapter.send(request, **kwargs)
  File "/usr/lib/python3/dist-packages/requests/adapters.py", line 516, in send
    raise ConnectionError(e, request=request)
requests.exceptions.ConnectionError: HTTPSConnectionPool(host='api.openalex.org', port=443): Max retries exceeded with url: /works/W2949845543 (Caused by NewConnectionError('<urllib3.connection.HTTPSConnection object at 0x7f67487a47f0>: Failed to establish a new connection: [Errno -2] Name or service not known'))

[Fri Mar 29 14:28:12 2024] Problem with getting article with id = W2077152574
Traceback (most recent call last):
  File "/usr/lib/python3/dist-packages/urllib3/connection.py", line 169, in _new_conn
    conn = connection.create_connection(
  File "/usr/lib/python3/dist-packages/urllib3/util/connection.py", line 73, in create_connection
    for res in socket.getaddrinfo(host, port, family, socket.SOCK_STREAM):
  File "/usr/lib/python3.10/socket.py", line 955, in getaddrinfo
    for res in _socket.getaddrinfo(host, port, family, type, proto, flags):
socket.gaierror: [Errno -2] Name or service not known

During handling of the above exception, another exception occurred:

Traceback (most recent call last):
  File "/usr/lib/python3/dist-packages/urllib3/connectionpool.py", line 700, in urlopen
    httplib_response = self._make_request(
  File "/usr/lib/python3/dist-packages/urllib3/connectionpool.py", line 383, in _make_request
    self._validate_conn(conn)
  File "/usr/lib/python3/dist-packages/urllib3/connectionpool.py", line 1017, in _validate_conn
    conn.connect()
  File "/usr/lib/python3/dist-packages/urllib3/connection.py", line 353, in connect
    conn = self._new_conn()
  File "/usr/lib/python3/dist-packages/urllib3/connection.py", line 181, in _new_conn
    raise NewConnectionError(
urllib3.exceptions.NewConnectionError: <urllib3.connection.HTTPSConnection object at 0x7f6748894e20>: Failed to establish a new connection: [Errno -2] Name or service not known

During handling of the above exception, another exception occurred:

Traceback (most recent call last):
  File "/usr/lib/python3/dist-packages/requests/adapters.py", line 439, in send
    resp = conn.urlopen(
  File "/usr/lib/python3/dist-packages/urllib3/connectionpool.py", line 756, in urlopen
    retries = retries.increment(
  File "/usr/lib/python3/dist-packages/urllib3/util/retry.py", line 574, in increment
    raise MaxRetryError(_pool, url, error or ResponseError(cause))
urllib3.exceptions.MaxRetryError: HTTPSConnectionPool(host='api.openalex.org', port=443): Max retries exceeded with url: /works/W2077152574 (Caused by NewConnectionError('<urllib3.connection.HTTPSConnection object at 0x7f6748894e20>: Failed to establish a new connection: [Errno -2] Name or service not known'))

During handling of the above exception, another exception occurred:

Traceback (most recent call last):
  File "/home/george/Документы/harddrive/articles-analysis/programs/downloading_referenced_works.py", line 357, in download_work_by_id
    work = Works()[id_]
  File "/usr/local/lib/python3.10/dist-packages/pyalex/api.py", line 225, in __getitem__
    return self._get_from_url(
  File "/usr/local/lib/python3.10/dist-packages/pyalex/api.py", line 257, in _get_from_url
    res = _get_requests_session().get(url, auth=OpenAlexAuth(config))
  File "/usr/lib/python3/dist-packages/requests/sessions.py", line 557, in get
    return self.request('GET', url, **kwargs)
  File "/usr/lib/python3/dist-packages/requests/sessions.py", line 544, in request
    resp = self.send(prep, **send_kwargs)
  File "/usr/lib/python3/dist-packages/requests/sessions.py", line 657, in send
    r = adapter.send(request, **kwargs)
  File "/usr/lib/python3/dist-packages/requests/adapters.py", line 516, in send
    raise ConnectionError(e, request=request)
requests.exceptions.ConnectionError: HTTPSConnectionPool(host='api.openalex.org', port=443): Max retries exceeded with url: /works/W2077152574 (Caused by NewConnectionError('<urllib3.connection.HTTPSConnection object at 0x7f6748894e20>: Failed to establish a new connection: [Errno -2] Name or service not known'))

[Fri Mar 29 14:28:12 2024] Problem with getting article with id = W2097132843
Traceback (most recent call last):
  File "/usr/lib/python3/dist-packages/urllib3/connection.py", line 169, in _new_conn
    conn = connection.create_connection(
  File "/usr/lib/python3/dist-packages/urllib3/util/connection.py", line 73, in create_connection
    for res in socket.getaddrinfo(host, port, family, socket.SOCK_STREAM):
  File "/usr/lib/python3.10/socket.py", line 955, in getaddrinfo
    for res in _socket.getaddrinfo(host, port, family, type, proto, flags):
socket.gaierror: [Errno -2] Name or service not known

During handling of the above exception, another exception occurred:

Traceback (most recent call last):
  File "/usr/lib/python3/dist-packages/urllib3/connectionpool.py", line 700, in urlopen
    httplib_response = self._make_request(
  File "/usr/lib/python3/dist-packages/urllib3/connectionpool.py", line 383, in _make_request
    self._validate_conn(conn)
  File "/usr/lib/python3/dist-packages/urllib3/connectionpool.py", line 1017, in _validate_conn
    conn.connect()
  File "/usr/lib/python3/dist-packages/urllib3/connection.py", line 353, in connect
    conn = self._new_conn()
  File "/usr/lib/python3/dist-packages/urllib3/connection.py", line 181, in _new_conn
    raise NewConnectionError(
urllib3.exceptions.NewConnectionError: <urllib3.connection.HTTPSConnection object at 0x7f67487a4a00>: Failed to establish a new connection: [Errno -2] Name or service not known

During handling of the above exception, another exception occurred:

Traceback (most recent call last):
  File "/usr/lib/python3/dist-packages/requests/adapters.py", line 439, in send
    resp = conn.urlopen(
  File "/usr/lib/python3/dist-packages/urllib3/connectionpool.py", line 756, in urlopen
    retries = retries.increment(
  File "/usr/lib/python3/dist-packages/urllib3/util/retry.py", line 574, in increment
    raise MaxRetryError(_pool, url, error or ResponseError(cause))
urllib3.exceptions.MaxRetryError: HTTPSConnectionPool(host='api.openalex.org', port=443): Max retries exceeded with url: /works/W2097132843 (Caused by NewConnectionError('<urllib3.connection.HTTPSConnection object at 0x7f67487a4a00>: Failed to establish a new connection: [Errno -2] Name or service not known'))

During handling of the above exception, another exception occurred:

Traceback (most recent call last):
  File "/home/george/Документы/harddrive/articles-analysis/programs/downloading_referenced_works.py", line 357, in download_work_by_id
    work = Works()[id_]
  File "/usr/local/lib/python3.10/dist-packages/pyalex/api.py", line 225, in __getitem__
    return self._get_from_url(
  File "/usr/local/lib/python3.10/dist-packages/pyalex/api.py", line 257, in _get_from_url
    res = _get_requests_session().get(url, auth=OpenAlexAuth(config))
  File "/usr/lib/python3/dist-packages/requests/sessions.py", line 557, in get
    return self.request('GET', url, **kwargs)
  File "/usr/lib/python3/dist-packages/requests/sessions.py", line 544, in request
    resp = self.send(prep, **send_kwargs)
  File "/usr/lib/python3/dist-packages/requests/sessions.py", line 657, in send
    r = adapter.send(request, **kwargs)
  File "/usr/lib/python3/dist-packages/requests/adapters.py", line 516, in send
    raise ConnectionError(e, request=request)
requests.exceptions.ConnectionError: HTTPSConnectionPool(host='api.openalex.org', port=443): Max retries exceeded with url: /works/W2097132843 (Caused by NewConnectionError('<urllib3.connection.HTTPSConnection object at 0x7f67487a4a00>: Failed to establish a new connection: [Errno -2] Name or service not known'))

[Fri Mar 29 14:28:12 2024] Problem with getting article with id = W2013741932
Traceback (most recent call last):
  File "/usr/lib/python3/dist-packages/urllib3/connection.py", line 169, in _new_conn
    conn = connection.create_connection(
  File "/usr/lib/python3/dist-packages/urllib3/util/connection.py", line 73, in create_connection
    for res in socket.getaddrinfo(host, port, family, socket.SOCK_STREAM):
  File "/usr/lib/python3.10/socket.py", line 955, in getaddrinfo
    for res in _socket.getaddrinfo(host, port, family, type, proto, flags):
socket.gaierror: [Errno -2] Name or service not known

During handling of the above exception, another exception occurred:

Traceback (most recent call last):
  File "/usr/lib/python3/dist-packages/urllib3/connectionpool.py", line 700, in urlopen
    httplib_response = self._make_request(
  File "/usr/lib/python3/dist-packages/urllib3/connectionpool.py", line 383, in _make_request
    self._validate_conn(conn)
  File "/usr/lib/python3/dist-packages/urllib3/connectionpool.py", line 1017, in _validate_conn
    conn.connect()
  File "/usr/lib/python3/dist-packages/urllib3/connection.py", line 353, in connect
    conn = self._new_conn()
  File "/usr/lib/python3/dist-packages/urllib3/connection.py", line 181, in _new_conn
    raise NewConnectionError(
urllib3.exceptions.NewConnectionError: <urllib3.connection.HTTPSConnection object at 0x7f6748895a20>: Failed to establish a new connection: [Errno -2] Name or service not known

During handling of the above exception, another exception occurred:

Traceback (most recent call last):
  File "/usr/lib/python3/dist-packages/requests/adapters.py", line 439, in send
    resp = conn.urlopen(
  File "/usr/lib/python3/dist-packages/urllib3/connectionpool.py", line 756, in urlopen
    retries = retries.increment(
  File "/usr/lib/python3/dist-packages/urllib3/util/retry.py", line 574, in increment
    raise MaxRetryError(_pool, url, error or ResponseError(cause))
urllib3.exceptions.MaxRetryError: HTTPSConnectionPool(host='api.openalex.org', port=443): Max retries exceeded with url: /works/W2013741932 (Caused by NewConnectionError('<urllib3.connection.HTTPSConnection object at 0x7f6748895a20>: Failed to establish a new connection: [Errno -2] Name or service not known'))

During handling of the above exception, another exception occurred:

Traceback (most recent call last):
  File "/home/george/Документы/harddrive/articles-analysis/programs/downloading_referenced_works.py", line 357, in download_work_by_id
    work = Works()[id_]
  File "/usr/local/lib/python3.10/dist-packages/pyalex/api.py", line 225, in __getitem__
    return self._get_from_url(
  File "/usr/local/lib/python3.10/dist-packages/pyalex/api.py", line 257, in _get_from_url
    res = _get_requests_session().get(url, auth=OpenAlexAuth(config))
  File "/usr/lib/python3/dist-packages/requests/sessions.py", line 557, in get
    return self.request('GET', url, **kwargs)
  File "/usr/lib/python3/dist-packages/requests/sessions.py", line 544, in request
    resp = self.send(prep, **send_kwargs)
  File "/usr/lib/python3/dist-packages/requests/sessions.py", line 657, in send
    r = adapter.send(request, **kwargs)
  File "/usr/lib/python3/dist-packages/requests/adapters.py", line 516, in send
    raise ConnectionError(e, request=request)
requests.exceptions.ConnectionError: HTTPSConnectionPool(host='api.openalex.org', port=443): Max retries exceeded with url: /works/W2013741932 (Caused by NewConnectionError('<urllib3.connection.HTTPSConnection object at 0x7f6748895a20>: Failed to establish a new connection: [Errno -2] Name or service not known'))

[Fri Mar 29 14:28:12 2024] Problem with getting article with id = W2118020384
Traceback (most recent call last):
  File "/usr/lib/python3/dist-packages/urllib3/connection.py", line 169, in _new_conn
    conn = connection.create_connection(
  File "/usr/lib/python3/dist-packages/urllib3/util/connection.py", line 73, in create_connection
    for res in socket.getaddrinfo(host, port, family, socket.SOCK_STREAM):
  File "/usr/lib/python3.10/socket.py", line 955, in getaddrinfo
    for res in _socket.getaddrinfo(host, port, family, type, proto, flags):
socket.gaierror: [Errno -2] Name or service not known

During handling of the above exception, another exception occurred:

Traceback (most recent call last):
  File "/usr/lib/python3/dist-packages/urllib3/connectionpool.py", line 700, in urlopen
    httplib_response = self._make_request(
  File "/usr/lib/python3/dist-packages/urllib3/connectionpool.py", line 383, in _make_request
    self._validate_conn(conn)
  File "/usr/lib/python3/dist-packages/urllib3/connectionpool.py", line 1017, in _validate_conn
    conn.connect()
  File "/usr/lib/python3/dist-packages/urllib3/connection.py", line 353, in connect
    conn = self._new_conn()
  File "/usr/lib/python3/dist-packages/urllib3/connection.py", line 181, in _new_conn
    raise NewConnectionError(
urllib3.exceptions.NewConnectionError: <urllib3.connection.HTTPSConnection object at 0x7f67487a4520>: Failed to establish a new connection: [Errno -2] Name or service not known

During handling of the above exception, another exception occurred:

Traceback (most recent call last):
  File "/usr/lib/python3/dist-packages/requests/adapters.py", line 439, in send
    resp = conn.urlopen(
  File "/usr/lib/python3/dist-packages/urllib3/connectionpool.py", line 756, in urlopen
    retries = retries.increment(
  File "/usr/lib/python3/dist-packages/urllib3/util/retry.py", line 574, in increment
    raise MaxRetryError(_pool, url, error or ResponseError(cause))
urllib3.exceptions.MaxRetryError: HTTPSConnectionPool(host='api.openalex.org', port=443): Max retries exceeded with url: /works/W2118020384 (Caused by NewConnectionError('<urllib3.connection.HTTPSConnection object at 0x7f67487a4520>: Failed to establish a new connection: [Errno -2] Name or service not known'))

During handling of the above exception, another exception occurred:

Traceback (most recent call last):
  File "/home/george/Документы/harddrive/articles-analysis/programs/downloading_referenced_works.py", line 357, in download_work_by_id
    work = Works()[id_]
  File "/usr/local/lib/python3.10/dist-packages/pyalex/api.py", line 225, in __getitem__
    return self._get_from_url(
  File "/usr/local/lib/python3.10/dist-packages/pyalex/api.py", line 257, in _get_from_url
    res = _get_requests_session().get(url, auth=OpenAlexAuth(config))
  File "/usr/lib/python3/dist-packages/requests/sessions.py", line 557, in get
    return self.request('GET', url, **kwargs)
  File "/usr/lib/python3/dist-packages/requests/sessions.py", line 544, in request
    resp = self.send(prep, **send_kwargs)
  File "/usr/lib/python3/dist-packages/requests/sessions.py", line 657, in send
    r = adapter.send(request, **kwargs)
  File "/usr/lib/python3/dist-packages/requests/adapters.py", line 516, in send
    raise ConnectionError(e, request=request)
requests.exceptions.ConnectionError: HTTPSConnectionPool(host='api.openalex.org', port=443): Max retries exceeded with url: /works/W2118020384 (Caused by NewConnectionError('<urllib3.connection.HTTPSConnection object at 0x7f67487a4520>: Failed to establish a new connection: [Errno -2] Name or service not known'))

[Fri Mar 29 14:28:12 2024] Problem with getting article with id = W1986387518
Traceback (most recent call last):
  File "/usr/lib/python3/dist-packages/urllib3/connection.py", line 169, in _new_conn
    conn = connection.create_connection(
  File "/usr/lib/python3/dist-packages/urllib3/util/connection.py", line 73, in create_connection
    for res in socket.getaddrinfo(host, port, family, socket.SOCK_STREAM):
  File "/usr/lib/python3.10/socket.py", line 955, in getaddrinfo
    for res in _socket.getaddrinfo(host, port, family, type, proto, flags):
socket.gaierror: [Errno -2] Name or service not known

During handling of the above exception, another exception occurred:

Traceback (most recent call last):
  File "/usr/lib/python3/dist-packages/urllib3/connectionpool.py", line 700, in urlopen
    httplib_response = self._make_request(
  File "/usr/lib/python3/dist-packages/urllib3/connectionpool.py", line 383, in _make_request
    self._validate_conn(conn)
  File "/usr/lib/python3/dist-packages/urllib3/connectionpool.py", line 1017, in _validate_conn
    conn.connect()
  File "/usr/lib/python3/dist-packages/urllib3/connection.py", line 353, in connect
    conn = self._new_conn()
  File "/usr/lib/python3/dist-packages/urllib3/connection.py", line 181, in _new_conn
    raise NewConnectionError(
urllib3.exceptions.NewConnectionError: <urllib3.connection.HTTPSConnection object at 0x7f6748897820>: Failed to establish a new connection: [Errno -2] Name or service not known

During handling of the above exception, another exception occurred:

Traceback (most recent call last):
  File "/usr/lib/python3/dist-packages/requests/adapters.py", line 439, in send
    resp = conn.urlopen(
  File "/usr/lib/python3/dist-packages/urllib3/connectionpool.py", line 756, in urlopen
    retries = retries.increment(
  File "/usr/lib/python3/dist-packages/urllib3/util/retry.py", line 574, in increment
    raise MaxRetryError(_pool, url, error or ResponseError(cause))
urllib3.exceptions.MaxRetryError: HTTPSConnectionPool(host='api.openalex.org', port=443): Max retries exceeded with url: /works/W1986387518 (Caused by NewConnectionError('<urllib3.connection.HTTPSConnection object at 0x7f6748897820>: Failed to establish a new connection: [Errno -2] Name or service not known'))

During handling of the above exception, another exception occurred:

Traceback (most recent call last):
  File "/home/george/Документы/harddrive/articles-analysis/programs/downloading_referenced_works.py", line 357, in download_work_by_id
    work = Works()[id_]
  File "/usr/local/lib/python3.10/dist-packages/pyalex/api.py", line 225, in __getitem__
    return self._get_from_url(
  File "/usr/local/lib/python3.10/dist-packages/pyalex/api.py", line 257, in _get_from_url
    res = _get_requests_session().get(url, auth=OpenAlexAuth(config))
  File "/usr/lib/python3/dist-packages/requests/sessions.py", line 557, in get
    return self.request('GET', url, **kwargs)
  File "/usr/lib/python3/dist-packages/requests/sessions.py", line 544, in request
    resp = self.send(prep, **send_kwargs)
  File "/usr/lib/python3/dist-packages/requests/sessions.py", line 657, in send
    r = adapter.send(request, **kwargs)
  File "/usr/lib/python3/dist-packages/requests/adapters.py", line 516, in send
    raise ConnectionError(e, request=request)
requests.exceptions.ConnectionError: HTTPSConnectionPool(host='api.openalex.org', port=443): Max retries exceeded with url: /works/W1986387518 (Caused by NewConnectionError('<urllib3.connection.HTTPSConnection object at 0x7f6748897820>: Failed to establish a new connection: [Errno -2] Name or service not known'))

[Fri Mar 29 14:28:12 2024] Problem with getting article with id = W2332041576
Traceback (most recent call last):
  File "/usr/lib/python3/dist-packages/urllib3/connection.py", line 169, in _new_conn
    conn = connection.create_connection(
  File "/usr/lib/python3/dist-packages/urllib3/util/connection.py", line 73, in create_connection
    for res in socket.getaddrinfo(host, port, family, socket.SOCK_STREAM):
  File "/usr/lib/python3.10/socket.py", line 955, in getaddrinfo
    for res in _socket.getaddrinfo(host, port, family, type, proto, flags):
socket.gaierror: [Errno -2] Name or service not known

During handling of the above exception, another exception occurred:

Traceback (most recent call last):
  File "/usr/lib/python3/dist-packages/urllib3/connectionpool.py", line 700, in urlopen
    httplib_response = self._make_request(
  File "/usr/lib/python3/dist-packages/urllib3/connectionpool.py", line 383, in _make_request
    self._validate_conn(conn)
  File "/usr/lib/python3/dist-packages/urllib3/connectionpool.py", line 1017, in _validate_conn
    conn.connect()
  File "/usr/lib/python3/dist-packages/urllib3/connection.py", line 353, in connect
    conn = self._new_conn()
  File "/usr/lib/python3/dist-packages/urllib3/connection.py", line 181, in _new_conn
    raise NewConnectionError(
urllib3.exceptions.NewConnectionError: <urllib3.connection.HTTPSConnection object at 0x7f6748897f70>: Failed to establish a new connection: [Errno -2] Name or service not known

During handling of the above exception, another exception occurred:

Traceback (most recent call last):
  File "/usr/lib/python3/dist-packages/requests/adapters.py", line 439, in send
    resp = conn.urlopen(
  File "/usr/lib/python3/dist-packages/urllib3/connectionpool.py", line 756, in urlopen
    retries = retries.increment(
  File "/usr/lib/python3/dist-packages/urllib3/util/retry.py", line 574, in increment
    raise MaxRetryError(_pool, url, error or ResponseError(cause))
urllib3.exceptions.MaxRetryError: HTTPSConnectionPool(host='api.openalex.org', port=443): Max retries exceeded with url: /works/W2332041576 (Caused by NewConnectionError('<urllib3.connection.HTTPSConnection object at 0x7f6748897f70>: Failed to establish a new connection: [Errno -2] Name or service not known'))

During handling of the above exception, another exception occurred:

Traceback (most recent call last):
  File "/home/george/Документы/harddrive/articles-analysis/programs/downloading_referenced_works.py", line 357, in download_work_by_id
    work = Works()[id_]
  File "/usr/local/lib/python3.10/dist-packages/pyalex/api.py", line 225, in __getitem__
    return self._get_from_url(
  File "/usr/local/lib/python3.10/dist-packages/pyalex/api.py", line 257, in _get_from_url
    res = _get_requests_session().get(url, auth=OpenAlexAuth(config))
  File "/usr/lib/python3/dist-packages/requests/sessions.py", line 557, in get
    return self.request('GET', url, **kwargs)
  File "/usr/lib/python3/dist-packages/requests/sessions.py", line 544, in request
    resp = self.send(prep, **send_kwargs)
  File "/usr/lib/python3/dist-packages/requests/sessions.py", line 657, in send
    r = adapter.send(request, **kwargs)
  File "/usr/lib/python3/dist-packages/requests/adapters.py", line 516, in send
    raise ConnectionError(e, request=request)
requests.exceptions.ConnectionError: HTTPSConnectionPool(host='api.openalex.org', port=443): Max retries exceeded with url: /works/W2332041576 (Caused by NewConnectionError('<urllib3.connection.HTTPSConnection object at 0x7f6748897f70>: Failed to establish a new connection: [Errno -2] Name or service not known'))

[Fri Mar 29 14:28:12 2024] Problem with getting article with id = W2034755174
Traceback (most recent call last):
  File "/usr/lib/python3/dist-packages/urllib3/connection.py", line 169, in _new_conn
    conn = connection.create_connection(
  File "/usr/lib/python3/dist-packages/urllib3/util/connection.py", line 73, in create_connection
    for res in socket.getaddrinfo(host, port, family, socket.SOCK_STREAM):
  File "/usr/lib/python3.10/socket.py", line 955, in getaddrinfo
    for res in _socket.getaddrinfo(host, port, family, type, proto, flags):
socket.gaierror: [Errno -2] Name or service not known

During handling of the above exception, another exception occurred:

Traceback (most recent call last):
  File "/usr/lib/python3/dist-packages/urllib3/connectionpool.py", line 700, in urlopen
    httplib_response = self._make_request(
  File "/usr/lib/python3/dist-packages/urllib3/connectionpool.py", line 383, in _make_request
    self._validate_conn(conn)
  File "/usr/lib/python3/dist-packages/urllib3/connectionpool.py", line 1017, in _validate_conn
    conn.connect()
  File "/usr/lib/python3/dist-packages/urllib3/connection.py", line 353, in connect
    conn = self._new_conn()
  File "/usr/lib/python3/dist-packages/urllib3/connection.py", line 181, in _new_conn
    raise NewConnectionError(
urllib3.exceptions.NewConnectionError: <urllib3.connection.HTTPSConnection object at 0x7f6748897820>: Failed to establish a new connection: [Errno -2] Name or service not known

During handling of the above exception, another exception occurred:

Traceback (most recent call last):
  File "/usr/lib/python3/dist-packages/requests/adapters.py", line 439, in send
    resp = conn.urlopen(
  File "/usr/lib/python3/dist-packages/urllib3/connectionpool.py", line 756, in urlopen
    retries = retries.increment(
  File "/usr/lib/python3/dist-packages/urllib3/util/retry.py", line 574, in increment
    raise MaxRetryError(_pool, url, error or ResponseError(cause))
urllib3.exceptions.MaxRetryError: HTTPSConnectionPool(host='api.openalex.org', port=443): Max retries exceeded with url: /works/W2034755174 (Caused by NewConnectionError('<urllib3.connection.HTTPSConnection object at 0x7f6748897820>: Failed to establish a new connection: [Errno -2] Name or service not known'))

During handling of the above exception, another exception occurred:

Traceback (most recent call last):
  File "/home/george/Документы/harddrive/articles-analysis/programs/downloading_referenced_works.py", line 357, in download_work_by_id
    work = Works()[id_]
  File "/usr/local/lib/python3.10/dist-packages/pyalex/api.py", line 225, in __getitem__
    return self._get_from_url(
  File "/usr/local/lib/python3.10/dist-packages/pyalex/api.py", line 257, in _get_from_url
    res = _get_requests_session().get(url, auth=OpenAlexAuth(config))
  File "/usr/lib/python3/dist-packages/requests/sessions.py", line 557, in get
    return self.request('GET', url, **kwargs)
  File "/usr/lib/python3/dist-packages/requests/sessions.py", line 544, in request
    resp = self.send(prep, **send_kwargs)
  File "/usr/lib/python3/dist-packages/requests/sessions.py", line 657, in send
    r = adapter.send(request, **kwargs)
  File "/usr/lib/python3/dist-packages/requests/adapters.py", line 516, in send
    raise ConnectionError(e, request=request)
requests.exceptions.ConnectionError: HTTPSConnectionPool(host='api.openalex.org', port=443): Max retries exceeded with url: /works/W2034755174 (Caused by NewConnectionError('<urllib3.connection.HTTPSConnection object at 0x7f6748897820>: Failed to establish a new connection: [Errno -2] Name or service not known'))

[Fri Mar 29 14:28:12 2024] Problem with getting article with id = W2130695750
Traceback (most recent call last):
  File "/usr/lib/python3/dist-packages/urllib3/connection.py", line 169, in _new_conn
    conn = connection.create_connection(
  File "/usr/lib/python3/dist-packages/urllib3/util/connection.py", line 73, in create_connection
    for res in socket.getaddrinfo(host, port, family, socket.SOCK_STREAM):
  File "/usr/lib/python3.10/socket.py", line 955, in getaddrinfo
    for res in _socket.getaddrinfo(host, port, family, type, proto, flags):
socket.gaierror: [Errno -2] Name or service not known

During handling of the above exception, another exception occurred:

Traceback (most recent call last):
  File "/usr/lib/python3/dist-packages/urllib3/connectionpool.py", line 700, in urlopen
    httplib_response = self._make_request(
  File "/usr/lib/python3/dist-packages/urllib3/connectionpool.py", line 383, in _make_request
    self._validate_conn(conn)
  File "/usr/lib/python3/dist-packages/urllib3/connectionpool.py", line 1017, in _validate_conn
    conn.connect()
  File "/usr/lib/python3/dist-packages/urllib3/connection.py", line 353, in connect
    conn = self._new_conn()
  File "/usr/lib/python3/dist-packages/urllib3/connection.py", line 181, in _new_conn
    raise NewConnectionError(
urllib3.exceptions.NewConnectionError: <urllib3.connection.HTTPSConnection object at 0x7f67488970a0>: Failed to establish a new connection: [Errno -2] Name or service not known

During handling of the above exception, another exception occurred:

Traceback (most recent call last):
  File "/usr/lib/python3/dist-packages/requests/adapters.py", line 439, in send
    resp = conn.urlopen(
  File "/usr/lib/python3/dist-packages/urllib3/connectionpool.py", line 756, in urlopen
    retries = retries.increment(
  File "/usr/lib/python3/dist-packages/urllib3/util/retry.py", line 574, in increment
    raise MaxRetryError(_pool, url, error or ResponseError(cause))
urllib3.exceptions.MaxRetryError: HTTPSConnectionPool(host='api.openalex.org', port=443): Max retries exceeded with url: /works/W2130695750 (Caused by NewConnectionError('<urllib3.connection.HTTPSConnection object at 0x7f67488970a0>: Failed to establish a new connection: [Errno -2] Name or service not known'))

During handling of the above exception, another exception occurred:

Traceback (most recent call last):
  File "/home/george/Документы/harddrive/articles-analysis/programs/downloading_referenced_works.py", line 357, in download_work_by_id
    work = Works()[id_]
  File "/usr/local/lib/python3.10/dist-packages/pyalex/api.py", line 225, in __getitem__
    return self._get_from_url(
  File "/usr/local/lib/python3.10/dist-packages/pyalex/api.py", line 257, in _get_from_url
    res = _get_requests_session().get(url, auth=OpenAlexAuth(config))
  File "/usr/lib/python3/dist-packages/requests/sessions.py", line 557, in get
    return self.request('GET', url, **kwargs)
  File "/usr/lib/python3/dist-packages/requests/sessions.py", line 544, in request
    resp = self.send(prep, **send_kwargs)
  File "/usr/lib/python3/dist-packages/requests/sessions.py", line 657, in send
    r = adapter.send(request, **kwargs)
  File "/usr/lib/python3/dist-packages/requests/adapters.py", line 516, in send
    raise ConnectionError(e, request=request)
requests.exceptions.ConnectionError: HTTPSConnectionPool(host='api.openalex.org', port=443): Max retries exceeded with url: /works/W2130695750 (Caused by NewConnectionError('<urllib3.connection.HTTPSConnection object at 0x7f67488970a0>: Failed to establish a new connection: [Errno -2] Name or service not known'))

[Fri Mar 29 14:28:12 2024] Problem with getting article with id = W2514959201
Traceback (most recent call last):
  File "/usr/lib/python3/dist-packages/urllib3/connection.py", line 169, in _new_conn
    conn = connection.create_connection(
  File "/usr/lib/python3/dist-packages/urllib3/util/connection.py", line 73, in create_connection
    for res in socket.getaddrinfo(host, port, family, socket.SOCK_STREAM):
  File "/usr/lib/python3.10/socket.py", line 955, in getaddrinfo
    for res in _socket.getaddrinfo(host, port, family, type, proto, flags):
socket.gaierror: [Errno -2] Name or service not known

During handling of the above exception, another exception occurred:

Traceback (most recent call last):
  File "/usr/lib/python3/dist-packages/urllib3/connectionpool.py", line 700, in urlopen
    httplib_response = self._make_request(
  File "/usr/lib/python3/dist-packages/urllib3/connectionpool.py", line 383, in _make_request
    self._validate_conn(conn)
  File "/usr/lib/python3/dist-packages/urllib3/connectionpool.py", line 1017, in _validate_conn
    conn.connect()
  File "/usr/lib/python3/dist-packages/urllib3/connection.py", line 353, in connect
    conn = self._new_conn()
  File "/usr/lib/python3/dist-packages/urllib3/connection.py", line 181, in _new_conn
    raise NewConnectionError(
urllib3.exceptions.NewConnectionError: <urllib3.connection.HTTPSConnection object at 0x7f67487a4040>: Failed to establish a new connection: [Errno -2] Name or service not known

During handling of the above exception, another exception occurred:

Traceback (most recent call last):
  File "/usr/lib/python3/dist-packages/requests/adapters.py", line 439, in send
    resp = conn.urlopen(
  File "/usr/lib/python3/dist-packages/urllib3/connectionpool.py", line 756, in urlopen
    retries = retries.increment(
  File "/usr/lib/python3/dist-packages/urllib3/util/retry.py", line 574, in increment
    raise MaxRetryError(_pool, url, error or ResponseError(cause))
urllib3.exceptions.MaxRetryError: HTTPSConnectionPool(host='api.openalex.org', port=443): Max retries exceeded with url: /works/W2514959201 (Caused by NewConnectionError('<urllib3.connection.HTTPSConnection object at 0x7f67487a4040>: Failed to establish a new connection: [Errno -2] Name or service not known'))

During handling of the above exception, another exception occurred:

Traceback (most recent call last):
  File "/home/george/Документы/harddrive/articles-analysis/programs/downloading_referenced_works.py", line 357, in download_work_by_id
    work = Works()[id_]
  File "/usr/local/lib/python3.10/dist-packages/pyalex/api.py", line 225, in __getitem__
    return self._get_from_url(
  File "/usr/local/lib/python3.10/dist-packages/pyalex/api.py", line 257, in _get_from_url
    res = _get_requests_session().get(url, auth=OpenAlexAuth(config))
  File "/usr/lib/python3/dist-packages/requests/sessions.py", line 557, in get
    return self.request('GET', url, **kwargs)
  File "/usr/lib/python3/dist-packages/requests/sessions.py", line 544, in request
    resp = self.send(prep, **send_kwargs)
  File "/usr/lib/python3/dist-packages/requests/sessions.py", line 657, in send
    r = adapter.send(request, **kwargs)
  File "/usr/lib/python3/dist-packages/requests/adapters.py", line 516, in send
    raise ConnectionError(e, request=request)
requests.exceptions.ConnectionError: HTTPSConnectionPool(host='api.openalex.org', port=443): Max retries exceeded with url: /works/W2514959201 (Caused by NewConnectionError('<urllib3.connection.HTTPSConnection object at 0x7f67487a4040>: Failed to establish a new connection: [Errno -2] Name or service not known'))

[Fri Mar 29 14:28:12 2024] Problem with getting article with id = W1975116587
Traceback (most recent call last):
  File "/usr/lib/python3/dist-packages/urllib3/connection.py", line 169, in _new_conn
    conn = connection.create_connection(
  File "/usr/lib/python3/dist-packages/urllib3/util/connection.py", line 73, in create_connection
    for res in socket.getaddrinfo(host, port, family, socket.SOCK_STREAM):
  File "/usr/lib/python3.10/socket.py", line 955, in getaddrinfo
    for res in _socket.getaddrinfo(host, port, family, type, proto, flags):
socket.gaierror: [Errno -2] Name or service not known

During handling of the above exception, another exception occurred:

Traceback (most recent call last):
  File "/usr/lib/python3/dist-packages/urllib3/connectionpool.py", line 700, in urlopen
    httplib_response = self._make_request(
  File "/usr/lib/python3/dist-packages/urllib3/connectionpool.py", line 383, in _make_request
    self._validate_conn(conn)
  File "/usr/lib/python3/dist-packages/urllib3/connectionpool.py", line 1017, in _validate_conn
    conn.connect()
  File "/usr/lib/python3/dist-packages/urllib3/connection.py", line 353, in connect
    conn = self._new_conn()
  File "/usr/lib/python3/dist-packages/urllib3/connection.py", line 181, in _new_conn
    raise NewConnectionError(
urllib3.exceptions.NewConnectionError: <urllib3.connection.HTTPSConnection object at 0x7f6748896200>: Failed to establish a new connection: [Errno -2] Name or service not known

During handling of the above exception, another exception occurred:

Traceback (most recent call last):
  File "/usr/lib/python3/dist-packages/requests/adapters.py", line 439, in send
    resp = conn.urlopen(
  File "/usr/lib/python3/dist-packages/urllib3/connectionpool.py", line 756, in urlopen
    retries = retries.increment(
  File "/usr/lib/python3/dist-packages/urllib3/util/retry.py", line 574, in increment
    raise MaxRetryError(_pool, url, error or ResponseError(cause))
urllib3.exceptions.MaxRetryError: HTTPSConnectionPool(host='api.openalex.org', port=443): Max retries exceeded with url: /works/W1975116587 (Caused by NewConnectionError('<urllib3.connection.HTTPSConnection object at 0x7f6748896200>: Failed to establish a new connection: [Errno -2] Name or service not known'))

During handling of the above exception, another exception occurred:

Traceback (most recent call last):
  File "/home/george/Документы/harddrive/articles-analysis/programs/downloading_referenced_works.py", line 357, in download_work_by_id
    work = Works()[id_]
  File "/usr/local/lib/python3.10/dist-packages/pyalex/api.py", line 225, in __getitem__
    return self._get_from_url(
  File "/usr/local/lib/python3.10/dist-packages/pyalex/api.py", line 257, in _get_from_url
    res = _get_requests_session().get(url, auth=OpenAlexAuth(config))
  File "/usr/lib/python3/dist-packages/requests/sessions.py", line 557, in get
    return self.request('GET', url, **kwargs)
  File "/usr/lib/python3/dist-packages/requests/sessions.py", line 544, in request
    resp = self.send(prep, **send_kwargs)
  File "/usr/lib/python3/dist-packages/requests/sessions.py", line 657, in send
    r = adapter.send(request, **kwargs)
  File "/usr/lib/python3/dist-packages/requests/adapters.py", line 516, in send
    raise ConnectionError(e, request=request)
requests.exceptions.ConnectionError: HTTPSConnectionPool(host='api.openalex.org', port=443): Max retries exceeded with url: /works/W1975116587 (Caused by NewConnectionError('<urllib3.connection.HTTPSConnection object at 0x7f6748896200>: Failed to establish a new connection: [Errno -2] Name or service not known'))

[Fri Mar 29 14:28:12 2024] Problem with getting article with id = W2026431840
Traceback (most recent call last):
  File "/usr/lib/python3/dist-packages/urllib3/connection.py", line 169, in _new_conn
    conn = connection.create_connection(
  File "/usr/lib/python3/dist-packages/urllib3/util/connection.py", line 73, in create_connection
    for res in socket.getaddrinfo(host, port, family, socket.SOCK_STREAM):
  File "/usr/lib/python3.10/socket.py", line 955, in getaddrinfo
    for res in _socket.getaddrinfo(host, port, family, type, proto, flags):
socket.gaierror: [Errno -2] Name or service not known

During handling of the above exception, another exception occurred:

Traceback (most recent call last):
  File "/usr/lib/python3/dist-packages/urllib3/connectionpool.py", line 700, in urlopen
    httplib_response = self._make_request(
  File "/usr/lib/python3/dist-packages/urllib3/connectionpool.py", line 383, in _make_request
    self._validate_conn(conn)
  File "/usr/lib/python3/dist-packages/urllib3/connectionpool.py", line 1017, in _validate_conn
    conn.connect()
  File "/usr/lib/python3/dist-packages/urllib3/connection.py", line 353, in connect
    conn = self._new_conn()
  File "/usr/lib/python3/dist-packages/urllib3/connection.py", line 181, in _new_conn
    raise NewConnectionError(
urllib3.exceptions.NewConnectionError: <urllib3.connection.HTTPSConnection object at 0x7f6748895510>: Failed to establish a new connection: [Errno -2] Name or service not known

During handling of the above exception, another exception occurred:

Traceback (most recent call last):
  File "/usr/lib/python3/dist-packages/requests/adapters.py", line 439, in send
    resp = conn.urlopen(
  File "/usr/lib/python3/dist-packages/urllib3/connectionpool.py", line 756, in urlopen
    retries = retries.increment(
  File "/usr/lib/python3/dist-packages/urllib3/util/retry.py", line 574, in increment
    raise MaxRetryError(_pool, url, error or ResponseError(cause))
urllib3.exceptions.MaxRetryError: HTTPSConnectionPool(host='api.openalex.org', port=443): Max retries exceeded with url: /works/W2026431840 (Caused by NewConnectionError('<urllib3.connection.HTTPSConnection object at 0x7f6748895510>: Failed to establish a new connection: [Errno -2] Name or service not known'))

During handling of the above exception, another exception occurred:

Traceback (most recent call last):
  File "/home/george/Документы/harddrive/articles-analysis/programs/downloading_referenced_works.py", line 357, in download_work_by_id
    work = Works()[id_]
  File "/usr/local/lib/python3.10/dist-packages/pyalex/api.py", line 225, in __getitem__
    return self._get_from_url(
  File "/usr/local/lib/python3.10/dist-packages/pyalex/api.py", line 257, in _get_from_url
    res = _get_requests_session().get(url, auth=OpenAlexAuth(config))
  File "/usr/lib/python3/dist-packages/requests/sessions.py", line 557, in get
    return self.request('GET', url, **kwargs)
  File "/usr/lib/python3/dist-packages/requests/sessions.py", line 544, in request
    resp = self.send(prep, **send_kwargs)
  File "/usr/lib/python3/dist-packages/requests/sessions.py", line 657, in send
    r = adapter.send(request, **kwargs)
  File "/usr/lib/python3/dist-packages/requests/adapters.py", line 516, in send
    raise ConnectionError(e, request=request)
requests.exceptions.ConnectionError: HTTPSConnectionPool(host='api.openalex.org', port=443): Max retries exceeded with url: /works/W2026431840 (Caused by NewConnectionError('<urllib3.connection.HTTPSConnection object at 0x7f6748895510>: Failed to establish a new connection: [Errno -2] Name or service not known'))

[Fri Mar 29 14:28:12 2024] Problem with getting article with id = W4296816736
Traceback (most recent call last):
  File "/usr/lib/python3/dist-packages/urllib3/connection.py", line 169, in _new_conn
    conn = connection.create_connection(
  File "/usr/lib/python3/dist-packages/urllib3/util/connection.py", line 73, in create_connection
    for res in socket.getaddrinfo(host, port, family, socket.SOCK_STREAM):
  File "/usr/lib/python3.10/socket.py", line 955, in getaddrinfo
    for res in _socket.getaddrinfo(host, port, family, type, proto, flags):
socket.gaierror: [Errno -2] Name or service not known

During handling of the above exception, another exception occurred:

Traceback (most recent call last):
  File "/usr/lib/python3/dist-packages/urllib3/connectionpool.py", line 700, in urlopen
    httplib_response = self._make_request(
  File "/usr/lib/python3/dist-packages/urllib3/connectionpool.py", line 383, in _make_request
    self._validate_conn(conn)
  File "/usr/lib/python3/dist-packages/urllib3/connectionpool.py", line 1017, in _validate_conn
    conn.connect()
  File "/usr/lib/python3/dist-packages/urllib3/connection.py", line 353, in connect
    conn = self._new_conn()
  File "/usr/lib/python3/dist-packages/urllib3/connection.py", line 181, in _new_conn
    raise NewConnectionError(
urllib3.exceptions.NewConnectionError: <urllib3.connection.HTTPSConnection object at 0x7f67487a4820>: Failed to establish a new connection: [Errno -2] Name or service not known

During handling of the above exception, another exception occurred:

Traceback (most recent call last):
  File "/usr/lib/python3/dist-packages/requests/adapters.py", line 439, in send
    resp = conn.urlopen(
  File "/usr/lib/python3/dist-packages/urllib3/connectionpool.py", line 756, in urlopen
    retries = retries.increment(
  File "/usr/lib/python3/dist-packages/urllib3/util/retry.py", line 574, in increment
    raise MaxRetryError(_pool, url, error or ResponseError(cause))
urllib3.exceptions.MaxRetryError: HTTPSConnectionPool(host='api.openalex.org', port=443): Max retries exceeded with url: /works/W4296816736 (Caused by NewConnectionError('<urllib3.connection.HTTPSConnection object at 0x7f67487a4820>: Failed to establish a new connection: [Errno -2] Name or service not known'))

During handling of the above exception, another exception occurred:

Traceback (most recent call last):
  File "/home/george/Документы/harddrive/articles-analysis/programs/downloading_referenced_works.py", line 357, in download_work_by_id
    work = Works()[id_]
  File "/usr/local/lib/python3.10/dist-packages/pyalex/api.py", line 225, in __getitem__
    return self._get_from_url(
  File "/usr/local/lib/python3.10/dist-packages/pyalex/api.py", line 257, in _get_from_url
    res = _get_requests_session().get(url, auth=OpenAlexAuth(config))
  File "/usr/lib/python3/dist-packages/requests/sessions.py", line 557, in get
    return self.request('GET', url, **kwargs)
  File "/usr/lib/python3/dist-packages/requests/sessions.py", line 544, in request
    resp = self.send(prep, **send_kwargs)
  File "/usr/lib/python3/dist-packages/requests/sessions.py", line 657, in send
    r = adapter.send(request, **kwargs)
  File "/usr/lib/python3/dist-packages/requests/adapters.py", line 516, in send
    raise ConnectionError(e, request=request)
requests.exceptions.ConnectionError: HTTPSConnectionPool(host='api.openalex.org', port=443): Max retries exceeded with url: /works/W4296816736 (Caused by NewConnectionError('<urllib3.connection.HTTPSConnection object at 0x7f67487a4820>: Failed to establish a new connection: [Errno -2] Name or service not known'))

[Fri Mar 29 14:28:12 2024] Problem with getting article with id = W2618064051
Traceback (most recent call last):
  File "/usr/lib/python3/dist-packages/urllib3/connection.py", line 169, in _new_conn
    conn = connection.create_connection(
  File "/usr/lib/python3/dist-packages/urllib3/util/connection.py", line 73, in create_connection
    for res in socket.getaddrinfo(host, port, family, socket.SOCK_STREAM):
  File "/usr/lib/python3.10/socket.py", line 955, in getaddrinfo
    for res in _socket.getaddrinfo(host, port, family, type, proto, flags):
socket.gaierror: [Errno -2] Name or service not known

During handling of the above exception, another exception occurred:

Traceback (most recent call last):
  File "/usr/lib/python3/dist-packages/urllib3/connectionpool.py", line 700, in urlopen
    httplib_response = self._make_request(
  File "/usr/lib/python3/dist-packages/urllib3/connectionpool.py", line 383, in _make_request
    self._validate_conn(conn)
  File "/usr/lib/python3/dist-packages/urllib3/connectionpool.py", line 1017, in _validate_conn
    conn.connect()
  File "/usr/lib/python3/dist-packages/urllib3/connection.py", line 353, in connect
    conn = self._new_conn()
  File "/usr/lib/python3/dist-packages/urllib3/connection.py", line 181, in _new_conn
    raise NewConnectionError(
urllib3.exceptions.NewConnectionError: <urllib3.connection.HTTPSConnection object at 0x7f67488957b0>: Failed to establish a new connection: [Errno -2] Name or service not known

During handling of the above exception, another exception occurred:

Traceback (most recent call last):
  File "/usr/lib/python3/dist-packages/requests/adapters.py", line 439, in send
    resp = conn.urlopen(
  File "/usr/lib/python3/dist-packages/urllib3/connectionpool.py", line 756, in urlopen
    retries = retries.increment(
  File "/usr/lib/python3/dist-packages/urllib3/util/retry.py", line 574, in increment
    raise MaxRetryError(_pool, url, error or ResponseError(cause))
urllib3.exceptions.MaxRetryError: HTTPSConnectionPool(host='api.openalex.org', port=443): Max retries exceeded with url: /works/W2618064051 (Caused by NewConnectionError('<urllib3.connection.HTTPSConnection object at 0x7f67488957b0>: Failed to establish a new connection: [Errno -2] Name or service not known'))

During handling of the above exception, another exception occurred:

Traceback (most recent call last):
  File "/home/george/Документы/harddrive/articles-analysis/programs/downloading_referenced_works.py", line 357, in download_work_by_id
    work = Works()[id_]
  File "/usr/local/lib/python3.10/dist-packages/pyalex/api.py", line 225, in __getitem__
    return self._get_from_url(
  File "/usr/local/lib/python3.10/dist-packages/pyalex/api.py", line 257, in _get_from_url
    res = _get_requests_session().get(url, auth=OpenAlexAuth(config))
  File "/usr/lib/python3/dist-packages/requests/sessions.py", line 557, in get
    return self.request('GET', url, **kwargs)
  File "/usr/lib/python3/dist-packages/requests/sessions.py", line 544, in request
    resp = self.send(prep, **send_kwargs)
  File "/usr/lib/python3/dist-packages/requests/sessions.py", line 657, in send
    r = adapter.send(request, **kwargs)
  File "/usr/lib/python3/dist-packages/requests/adapters.py", line 516, in send
    raise ConnectionError(e, request=request)
requests.exceptions.ConnectionError: HTTPSConnectionPool(host='api.openalex.org', port=443): Max retries exceeded with url: /works/W2618064051 (Caused by NewConnectionError('<urllib3.connection.HTTPSConnection object at 0x7f67488957b0>: Failed to establish a new connection: [Errno -2] Name or service not known'))

[Fri Mar 29 14:28:12 2024] Problem with getting article with id = W2400668397
Traceback (most recent call last):
  File "/usr/lib/python3/dist-packages/urllib3/connection.py", line 169, in _new_conn
    conn = connection.create_connection(
  File "/usr/lib/python3/dist-packages/urllib3/util/connection.py", line 73, in create_connection
    for res in socket.getaddrinfo(host, port, family, socket.SOCK_STREAM):
  File "/usr/lib/python3.10/socket.py", line 955, in getaddrinfo
    for res in _socket.getaddrinfo(host, port, family, type, proto, flags):
socket.gaierror: [Errno -2] Name or service not known

During handling of the above exception, another exception occurred:

Traceback (most recent call last):
  File "/usr/lib/python3/dist-packages/urllib3/connectionpool.py", line 700, in urlopen
    httplib_response = self._make_request(
  File "/usr/lib/python3/dist-packages/urllib3/connectionpool.py", line 383, in _make_request
    self._validate_conn(conn)
  File "/usr/lib/python3/dist-packages/urllib3/connectionpool.py", line 1017, in _validate_conn
    conn.connect()
  File "/usr/lib/python3/dist-packages/urllib3/connection.py", line 353, in connect
    conn = self._new_conn()
  File "/usr/lib/python3/dist-packages/urllib3/connection.py", line 181, in _new_conn
    raise NewConnectionError(
urllib3.exceptions.NewConnectionError: <urllib3.connection.HTTPSConnection object at 0x7f6748895d20>: Failed to establish a new connection: [Errno -2] Name or service not known

During handling of the above exception, another exception occurred:

Traceback (most recent call last):
  File "/usr/lib/python3/dist-packages/requests/adapters.py", line 439, in send
    resp = conn.urlopen(
  File "/usr/lib/python3/dist-packages/urllib3/connectionpool.py", line 756, in urlopen
    retries = retries.increment(
  File "/usr/lib/python3/dist-packages/urllib3/util/retry.py", line 574, in increment
    raise MaxRetryError(_pool, url, error or ResponseError(cause))
urllib3.exceptions.MaxRetryError: HTTPSConnectionPool(host='api.openalex.org', port=443): Max retries exceeded with url: /works/W2400668397 (Caused by NewConnectionError('<urllib3.connection.HTTPSConnection object at 0x7f6748895d20>: Failed to establish a new connection: [Errno -2] Name or service not known'))

During handling of the above exception, another exception occurred:

Traceback (most recent call last):
  File "/home/george/Документы/harddrive/articles-analysis/programs/downloading_referenced_works.py", line 357, in download_work_by_id
    work = Works()[id_]
  File "/usr/local/lib/python3.10/dist-packages/pyalex/api.py", line 225, in __getitem__
    return self._get_from_url(
  File "/usr/local/lib/python3.10/dist-packages/pyalex/api.py", line 257, in _get_from_url
    res = _get_requests_session().get(url, auth=OpenAlexAuth(config))
  File "/usr/lib/python3/dist-packages/requests/sessions.py", line 557, in get
    return self.request('GET', url, **kwargs)
  File "/usr/lib/python3/dist-packages/requests/sessions.py", line 544, in request
    resp = self.send(prep, **send_kwargs)
  File "/usr/lib/python3/dist-packages/requests/sessions.py", line 657, in send
    r = adapter.send(request, **kwargs)
  File "/usr/lib/python3/dist-packages/requests/adapters.py", line 516, in send
    raise ConnectionError(e, request=request)
requests.exceptions.ConnectionError: HTTPSConnectionPool(host='api.openalex.org', port=443): Max retries exceeded with url: /works/W2400668397 (Caused by NewConnectionError('<urllib3.connection.HTTPSConnection object at 0x7f6748895d20>: Failed to establish a new connection: [Errno -2] Name or service not known'))

[Fri Mar 29 14:28:12 2024] Problem with getting article with id = W2087811204
Traceback (most recent call last):
  File "/usr/lib/python3/dist-packages/urllib3/connection.py", line 169, in _new_conn
    conn = connection.create_connection(
  File "/usr/lib/python3/dist-packages/urllib3/util/connection.py", line 73, in create_connection
    for res in socket.getaddrinfo(host, port, family, socket.SOCK_STREAM):
  File "/usr/lib/python3.10/socket.py", line 955, in getaddrinfo
    for res in _socket.getaddrinfo(host, port, family, type, proto, flags):
socket.gaierror: [Errno -2] Name or service not known

During handling of the above exception, another exception occurred:

Traceback (most recent call last):
  File "/usr/lib/python3/dist-packages/urllib3/connectionpool.py", line 700, in urlopen
    httplib_response = self._make_request(
  File "/usr/lib/python3/dist-packages/urllib3/connectionpool.py", line 383, in _make_request
    self._validate_conn(conn)
  File "/usr/lib/python3/dist-packages/urllib3/connectionpool.py", line 1017, in _validate_conn
    conn.connect()
  File "/usr/lib/python3/dist-packages/urllib3/connection.py", line 353, in connect
    conn = self._new_conn()
  File "/usr/lib/python3/dist-packages/urllib3/connection.py", line 181, in _new_conn
    raise NewConnectionError(
urllib3.exceptions.NewConnectionError: <urllib3.connection.HTTPSConnection object at 0x7f67487a41c0>: Failed to establish a new connection: [Errno -2] Name or service not known

During handling of the above exception, another exception occurred:

Traceback (most recent call last):
  File "/usr/lib/python3/dist-packages/requests/adapters.py", line 439, in send
    resp = conn.urlopen(
  File "/usr/lib/python3/dist-packages/urllib3/connectionpool.py", line 756, in urlopen
    retries = retries.increment(
  File "/usr/lib/python3/dist-packages/urllib3/util/retry.py", line 574, in increment
    raise MaxRetryError(_pool, url, error or ResponseError(cause))
urllib3.exceptions.MaxRetryError: HTTPSConnectionPool(host='api.openalex.org', port=443): Max retries exceeded with url: /works/W2087811204 (Caused by NewConnectionError('<urllib3.connection.HTTPSConnection object at 0x7f67487a41c0>: Failed to establish a new connection: [Errno -2] Name or service not known'))

During handling of the above exception, another exception occurred:

Traceback (most recent call last):
  File "/home/george/Документы/harddrive/articles-analysis/programs/downloading_referenced_works.py", line 357, in download_work_by_id
    work = Works()[id_]
  File "/usr/local/lib/python3.10/dist-packages/pyalex/api.py", line 225, in __getitem__
    return self._get_from_url(
  File "/usr/local/lib/python3.10/dist-packages/pyalex/api.py", line 257, in _get_from_url
    res = _get_requests_session().get(url, auth=OpenAlexAuth(config))
  File "/usr/lib/python3/dist-packages/requests/sessions.py", line 557, in get
    return self.request('GET', url, **kwargs)
  File "/usr/lib/python3/dist-packages/requests/sessions.py", line 544, in request
    resp = self.send(prep, **send_kwargs)
  File "/usr/lib/python3/dist-packages/requests/sessions.py", line 657, in send
    r = adapter.send(request, **kwargs)
  File "/usr/lib/python3/dist-packages/requests/adapters.py", line 516, in send
    raise ConnectionError(e, request=request)
requests.exceptions.ConnectionError: HTTPSConnectionPool(host='api.openalex.org', port=443): Max retries exceeded with url: /works/W2087811204 (Caused by NewConnectionError('<urllib3.connection.HTTPSConnection object at 0x7f67487a41c0>: Failed to establish a new connection: [Errno -2] Name or service not known'))

[Fri Mar 29 14:28:13 2024] Problem with getting article with id = W2132014790
Traceback (most recent call last):
  File "/usr/lib/python3/dist-packages/urllib3/connection.py", line 169, in _new_conn
    conn = connection.create_connection(
  File "/usr/lib/python3/dist-packages/urllib3/util/connection.py", line 73, in create_connection
    for res in socket.getaddrinfo(host, port, family, socket.SOCK_STREAM):
  File "/usr/lib/python3.10/socket.py", line 955, in getaddrinfo
    for res in _socket.getaddrinfo(host, port, family, type, proto, flags):
socket.gaierror: [Errno -2] Name or service not known

During handling of the above exception, another exception occurred:

Traceback (most recent call last):
  File "/usr/lib/python3/dist-packages/urllib3/connectionpool.py", line 700, in urlopen
    httplib_response = self._make_request(
  File "/usr/lib/python3/dist-packages/urllib3/connectionpool.py", line 383, in _make_request
    self._validate_conn(conn)
  File "/usr/lib/python3/dist-packages/urllib3/connectionpool.py", line 1017, in _validate_conn
    conn.connect()
  File "/usr/lib/python3/dist-packages/urllib3/connection.py", line 353, in connect
    conn = self._new_conn()
  File "/usr/lib/python3/dist-packages/urllib3/connection.py", line 181, in _new_conn
    raise NewConnectionError(
urllib3.exceptions.NewConnectionError: <urllib3.connection.HTTPSConnection object at 0x7f6748897370>: Failed to establish a new connection: [Errno -2] Name or service not known

During handling of the above exception, another exception occurred:

Traceback (most recent call last):
  File "/usr/lib/python3/dist-packages/requests/adapters.py", line 439, in send
    resp = conn.urlopen(
  File "/usr/lib/python3/dist-packages/urllib3/connectionpool.py", line 756, in urlopen
    retries = retries.increment(
  File "/usr/lib/python3/dist-packages/urllib3/util/retry.py", line 574, in increment
    raise MaxRetryError(_pool, url, error or ResponseError(cause))
urllib3.exceptions.MaxRetryError: HTTPSConnectionPool(host='api.openalex.org', port=443): Max retries exceeded with url: /works/W2132014790 (Caused by NewConnectionError('<urllib3.connection.HTTPSConnection object at 0x7f6748897370>: Failed to establish a new connection: [Errno -2] Name or service not known'))

During handling of the above exception, another exception occurred:

Traceback (most recent call last):
  File "/home/george/Документы/harddrive/articles-analysis/programs/downloading_referenced_works.py", line 357, in download_work_by_id
    work = Works()[id_]
  File "/usr/local/lib/python3.10/dist-packages/pyalex/api.py", line 225, in __getitem__
    return self._get_from_url(
  File "/usr/local/lib/python3.10/dist-packages/pyalex/api.py", line 257, in _get_from_url
    res = _get_requests_session().get(url, auth=OpenAlexAuth(config))
  File "/usr/lib/python3/dist-packages/requests/sessions.py", line 557, in get
    return self.request('GET', url, **kwargs)
  File "/usr/lib/python3/dist-packages/requests/sessions.py", line 544, in request
    resp = self.send(prep, **send_kwargs)
  File "/usr/lib/python3/dist-packages/requests/sessions.py", line 657, in send
    r = adapter.send(request, **kwargs)
  File "/usr/lib/python3/dist-packages/requests/adapters.py", line 516, in send
    raise ConnectionError(e, request=request)
requests.exceptions.ConnectionError: HTTPSConnectionPool(host='api.openalex.org', port=443): Max retries exceeded with url: /works/W2132014790 (Caused by NewConnectionError('<urllib3.connection.HTTPSConnection object at 0x7f6748897370>: Failed to establish a new connection: [Errno -2] Name or service not known'))

[Fri Mar 29 14:28:13 2024] Problem with getting article with id = W2065097626
Traceback (most recent call last):
  File "/usr/lib/python3/dist-packages/urllib3/connection.py", line 169, in _new_conn
    conn = connection.create_connection(
  File "/usr/lib/python3/dist-packages/urllib3/util/connection.py", line 73, in create_connection
    for res in socket.getaddrinfo(host, port, family, socket.SOCK_STREAM):
  File "/usr/lib/python3.10/socket.py", line 955, in getaddrinfo
    for res in _socket.getaddrinfo(host, port, family, type, proto, flags):
socket.gaierror: [Errno -2] Name or service not known

During handling of the above exception, another exception occurred:

Traceback (most recent call last):
  File "/usr/lib/python3/dist-packages/urllib3/connectionpool.py", line 700, in urlopen
    httplib_response = self._make_request(
  File "/usr/lib/python3/dist-packages/urllib3/connectionpool.py", line 383, in _make_request
    self._validate_conn(conn)
  File "/usr/lib/python3/dist-packages/urllib3/connectionpool.py", line 1017, in _validate_conn
    conn.connect()
  File "/usr/lib/python3/dist-packages/urllib3/connection.py", line 353, in connect
    conn = self._new_conn()
  File "/usr/lib/python3/dist-packages/urllib3/connection.py", line 181, in _new_conn
    raise NewConnectionError(
urllib3.exceptions.NewConnectionError: <urllib3.connection.HTTPSConnection object at 0x7f6748897700>: Failed to establish a new connection: [Errno -2] Name or service not known

During handling of the above exception, another exception occurred:

Traceback (most recent call last):
  File "/usr/lib/python3/dist-packages/requests/adapters.py", line 439, in send
    resp = conn.urlopen(
  File "/usr/lib/python3/dist-packages/urllib3/connectionpool.py", line 756, in urlopen
    retries = retries.increment(
  File "/usr/lib/python3/dist-packages/urllib3/util/retry.py", line 574, in increment
    raise MaxRetryError(_pool, url, error or ResponseError(cause))
urllib3.exceptions.MaxRetryError: HTTPSConnectionPool(host='api.openalex.org', port=443): Max retries exceeded with url: /works/W2065097626 (Caused by NewConnectionError('<urllib3.connection.HTTPSConnection object at 0x7f6748897700>: Failed to establish a new connection: [Errno -2] Name or service not known'))

During handling of the above exception, another exception occurred:

Traceback (most recent call last):
  File "/home/george/Документы/harddrive/articles-analysis/programs/downloading_referenced_works.py", line 357, in download_work_by_id
    work = Works()[id_]
  File "/usr/local/lib/python3.10/dist-packages/pyalex/api.py", line 225, in __getitem__
    return self._get_from_url(
  File "/usr/local/lib/python3.10/dist-packages/pyalex/api.py", line 257, in _get_from_url
    res = _get_requests_session().get(url, auth=OpenAlexAuth(config))
  File "/usr/lib/python3/dist-packages/requests/sessions.py", line 557, in get
    return self.request('GET', url, **kwargs)
  File "/usr/lib/python3/dist-packages/requests/sessions.py", line 544, in request
    resp = self.send(prep, **send_kwargs)
  File "/usr/lib/python3/dist-packages/requests/sessions.py", line 657, in send
    r = adapter.send(request, **kwargs)
  File "/usr/lib/python3/dist-packages/requests/adapters.py", line 516, in send
    raise ConnectionError(e, request=request)
requests.exceptions.ConnectionError: HTTPSConnectionPool(host='api.openalex.org', port=443): Max retries exceeded with url: /works/W2065097626 (Caused by NewConnectionError('<urllib3.connection.HTTPSConnection object at 0x7f6748897700>: Failed to establish a new connection: [Errno -2] Name or service not known'))

[Fri Mar 29 14:28:13 2024] Problem with getting article with id = W2099692099
Traceback (most recent call last):
  File "/usr/lib/python3/dist-packages/urllib3/connection.py", line 169, in _new_conn
    conn = connection.create_connection(
  File "/usr/lib/python3/dist-packages/urllib3/util/connection.py", line 73, in create_connection
    for res in socket.getaddrinfo(host, port, family, socket.SOCK_STREAM):
  File "/usr/lib/python3.10/socket.py", line 955, in getaddrinfo
    for res in _socket.getaddrinfo(host, port, family, type, proto, flags):
socket.gaierror: [Errno -2] Name or service not known

During handling of the above exception, another exception occurred:

Traceback (most recent call last):
  File "/usr/lib/python3/dist-packages/urllib3/connectionpool.py", line 700, in urlopen
    httplib_response = self._make_request(
  File "/usr/lib/python3/dist-packages/urllib3/connectionpool.py", line 383, in _make_request
    self._validate_conn(conn)
  File "/usr/lib/python3/dist-packages/urllib3/connectionpool.py", line 1017, in _validate_conn
    conn.connect()
  File "/usr/lib/python3/dist-packages/urllib3/connection.py", line 353, in connect
    conn = self._new_conn()
  File "/usr/lib/python3/dist-packages/urllib3/connection.py", line 181, in _new_conn
    raise NewConnectionError(
urllib3.exceptions.NewConnectionError: <urllib3.connection.HTTPSConnection object at 0x7f67487a4a90>: Failed to establish a new connection: [Errno -2] Name or service not known

During handling of the above exception, another exception occurred:

Traceback (most recent call last):
  File "/usr/lib/python3/dist-packages/requests/adapters.py", line 439, in send
    resp = conn.urlopen(
  File "/usr/lib/python3/dist-packages/urllib3/connectionpool.py", line 756, in urlopen
    retries = retries.increment(
  File "/usr/lib/python3/dist-packages/urllib3/util/retry.py", line 574, in increment
    raise MaxRetryError(_pool, url, error or ResponseError(cause))
urllib3.exceptions.MaxRetryError: HTTPSConnectionPool(host='api.openalex.org', port=443): Max retries exceeded with url: /works/W2099692099 (Caused by NewConnectionError('<urllib3.connection.HTTPSConnection object at 0x7f67487a4a90>: Failed to establish a new connection: [Errno -2] Name or service not known'))

During handling of the above exception, another exception occurred:

Traceback (most recent call last):
  File "/home/george/Документы/harddrive/articles-analysis/programs/downloading_referenced_works.py", line 357, in download_work_by_id
    work = Works()[id_]
  File "/usr/local/lib/python3.10/dist-packages/pyalex/api.py", line 225, in __getitem__
    return self._get_from_url(
  File "/usr/local/lib/python3.10/dist-packages/pyalex/api.py", line 257, in _get_from_url
    res = _get_requests_session().get(url, auth=OpenAlexAuth(config))
  File "/usr/lib/python3/dist-packages/requests/sessions.py", line 557, in get
    return self.request('GET', url, **kwargs)
  File "/usr/lib/python3/dist-packages/requests/sessions.py", line 544, in request
    resp = self.send(prep, **send_kwargs)
  File "/usr/lib/python3/dist-packages/requests/sessions.py", line 657, in send
    r = adapter.send(request, **kwargs)
  File "/usr/lib/python3/dist-packages/requests/adapters.py", line 516, in send
    raise ConnectionError(e, request=request)
requests.exceptions.ConnectionError: HTTPSConnectionPool(host='api.openalex.org', port=443): Max retries exceeded with url: /works/W2099692099 (Caused by NewConnectionError('<urllib3.connection.HTTPSConnection object at 0x7f67487a4a90>: Failed to establish a new connection: [Errno -2] Name or service not known'))

[Fri Mar 29 14:28:13 2024] Problem with getting article with id = W2005055640
Traceback (most recent call last):
  File "/usr/lib/python3/dist-packages/urllib3/connection.py", line 169, in _new_conn
    conn = connection.create_connection(
  File "/usr/lib/python3/dist-packages/urllib3/util/connection.py", line 73, in create_connection
    for res in socket.getaddrinfo(host, port, family, socket.SOCK_STREAM):
  File "/usr/lib/python3.10/socket.py", line 955, in getaddrinfo
    for res in _socket.getaddrinfo(host, port, family, type, proto, flags):
socket.gaierror: [Errno -2] Name or service not known

During handling of the above exception, another exception occurred:

Traceback (most recent call last):
  File "/usr/lib/python3/dist-packages/urllib3/connectionpool.py", line 700, in urlopen
    httplib_response = self._make_request(
  File "/usr/lib/python3/dist-packages/urllib3/connectionpool.py", line 383, in _make_request
    self._validate_conn(conn)
  File "/usr/lib/python3/dist-packages/urllib3/connectionpool.py", line 1017, in _validate_conn
    conn.connect()
  File "/usr/lib/python3/dist-packages/urllib3/connection.py", line 353, in connect
    conn = self._new_conn()
  File "/usr/lib/python3/dist-packages/urllib3/connection.py", line 181, in _new_conn
    raise NewConnectionError(
urllib3.exceptions.NewConnectionError: <urllib3.connection.HTTPSConnection object at 0x7f6748c99f90>: Failed to establish a new connection: [Errno -2] Name or service not known

During handling of the above exception, another exception occurred:

Traceback (most recent call last):
  File "/usr/lib/python3/dist-packages/requests/adapters.py", line 439, in send
    resp = conn.urlopen(
  File "/usr/lib/python3/dist-packages/urllib3/connectionpool.py", line 756, in urlopen
    retries = retries.increment(
  File "/usr/lib/python3/dist-packages/urllib3/util/retry.py", line 574, in increment
    raise MaxRetryError(_pool, url, error or ResponseError(cause))
urllib3.exceptions.MaxRetryError: HTTPSConnectionPool(host='api.openalex.org', port=443): Max retries exceeded with url: /works/W2005055640 (Caused by NewConnectionError('<urllib3.connection.HTTPSConnection object at 0x7f6748c99f90>: Failed to establish a new connection: [Errno -2] Name or service not known'))

During handling of the above exception, another exception occurred:

Traceback (most recent call last):
  File "/home/george/Документы/harddrive/articles-analysis/programs/downloading_referenced_works.py", line 357, in download_work_by_id
    work = Works()[id_]
  File "/usr/local/lib/python3.10/dist-packages/pyalex/api.py", line 225, in __getitem__
    return self._get_from_url(
  File "/usr/local/lib/python3.10/dist-packages/pyalex/api.py", line 257, in _get_from_url
    res = _get_requests_session().get(url, auth=OpenAlexAuth(config))
  File "/usr/lib/python3/dist-packages/requests/sessions.py", line 557, in get
    return self.request('GET', url, **kwargs)
  File "/usr/lib/python3/dist-packages/requests/sessions.py", line 544, in request
    resp = self.send(prep, **send_kwargs)
  File "/usr/lib/python3/dist-packages/requests/sessions.py", line 657, in send
    r = adapter.send(request, **kwargs)
  File "/usr/lib/python3/dist-packages/requests/adapters.py", line 516, in send
    raise ConnectionError(e, request=request)
requests.exceptions.ConnectionError: HTTPSConnectionPool(host='api.openalex.org', port=443): Max retries exceeded with url: /works/W2005055640 (Caused by NewConnectionError('<urllib3.connection.HTTPSConnection object at 0x7f6748c99f90>: Failed to establish a new connection: [Errno -2] Name or service not known'))

[Fri Mar 29 14:28:13 2024] Problem with getting article with id = W2022136552
Traceback (most recent call last):
  File "/usr/lib/python3/dist-packages/urllib3/connection.py", line 169, in _new_conn
    conn = connection.create_connection(
  File "/usr/lib/python3/dist-packages/urllib3/util/connection.py", line 73, in create_connection
    for res in socket.getaddrinfo(host, port, family, socket.SOCK_STREAM):
  File "/usr/lib/python3.10/socket.py", line 955, in getaddrinfo
    for res in _socket.getaddrinfo(host, port, family, type, proto, flags):
socket.gaierror: [Errno -2] Name or service not known

During handling of the above exception, another exception occurred:

Traceback (most recent call last):
  File "/usr/lib/python3/dist-packages/urllib3/connectionpool.py", line 700, in urlopen
    httplib_response = self._make_request(
  File "/usr/lib/python3/dist-packages/urllib3/connectionpool.py", line 383, in _make_request
    self._validate_conn(conn)
  File "/usr/lib/python3/dist-packages/urllib3/connectionpool.py", line 1017, in _validate_conn
    conn.connect()
  File "/usr/lib/python3/dist-packages/urllib3/connection.py", line 353, in connect
    conn = self._new_conn()
  File "/usr/lib/python3/dist-packages/urllib3/connection.py", line 181, in _new_conn
    raise NewConnectionError(
urllib3.exceptions.NewConnectionError: <urllib3.connection.HTTPSConnection object at 0x7f6748895420>: Failed to establish a new connection: [Errno -2] Name or service not known

During handling of the above exception, another exception occurred:

Traceback (most recent call last):
  File "/usr/lib/python3/dist-packages/requests/adapters.py", line 439, in send
    resp = conn.urlopen(
  File "/usr/lib/python3/dist-packages/urllib3/connectionpool.py", line 756, in urlopen
    retries = retries.increment(
  File "/usr/lib/python3/dist-packages/urllib3/util/retry.py", line 574, in increment
    raise MaxRetryError(_pool, url, error or ResponseError(cause))
urllib3.exceptions.MaxRetryError: HTTPSConnectionPool(host='api.openalex.org', port=443): Max retries exceeded with url: /works/W2022136552 (Caused by NewConnectionError('<urllib3.connection.HTTPSConnection object at 0x7f6748895420>: Failed to establish a new connection: [Errno -2] Name or service not known'))

During handling of the above exception, another exception occurred:

Traceback (most recent call last):
  File "/home/george/Документы/harddrive/articles-analysis/programs/downloading_referenced_works.py", line 357, in download_work_by_id
    work = Works()[id_]
  File "/usr/local/lib/python3.10/dist-packages/pyalex/api.py", line 225, in __getitem__
    return self._get_from_url(
  File "/usr/local/lib/python3.10/dist-packages/pyalex/api.py", line 257, in _get_from_url
    res = _get_requests_session().get(url, auth=OpenAlexAuth(config))
  File "/usr/lib/python3/dist-packages/requests/sessions.py", line 557, in get
    return self.request('GET', url, **kwargs)
  File "/usr/lib/python3/dist-packages/requests/sessions.py", line 544, in request
    resp = self.send(prep, **send_kwargs)
  File "/usr/lib/python3/dist-packages/requests/sessions.py", line 657, in send
    r = adapter.send(request, **kwargs)
  File "/usr/lib/python3/dist-packages/requests/adapters.py", line 516, in send
    raise ConnectionError(e, request=request)
requests.exceptions.ConnectionError: HTTPSConnectionPool(host='api.openalex.org', port=443): Max retries exceeded with url: /works/W2022136552 (Caused by NewConnectionError('<urllib3.connection.HTTPSConnection object at 0x7f6748895420>: Failed to establish a new connection: [Errno -2] Name or service not known'))



Traceback (most recent call last):
  File "/home/george/Документы/harddrive/articles-analysis/programs/downloading_referenced_works.py", line 534, in download_ref_works
    download_works_by_ids_global(ids, level)
  File "/home/george/Документы/harddrive/articles-analysis/programs/downloading_referenced_works.py", line 453, in download_works_by_ids_global
    stopping_thread.join()
  File "/usr/lib/python3.10/threading.py", line 1096, in join
    self._wait_for_tstate_lock()
  File "/usr/lib/python3.10/threading.py", line 1116, in _wait_for_tstate_lock
    if lock.acquire(block, timeout):
KeyboardInterrupt

Restarting..
