


Start downloading works_by_ids in 4 thread(s) at [Fri Mar 29 16:37:55 2024]



[Fri Mar 29 16:37:57 2024] Problem with adding article with id = W2343422114
Traceback (most recent call last):
  File "/home/george/Документы/harddrive/articles-analysis/programs/downloading_referenced_works.py", line 383, in download_work_by_id
    cursor.execute(f"""
sqlite3.IntegrityError: UNIQUE constraint failed: articles.id

[Fri Mar 29 16:37:57 2024] Problem with adding article with id = W2337772853
Traceback (most recent call last):
  File "/home/george/Документы/harddrive/articles-analysis/programs/downloading_referenced_works.py", line 383, in download_work_by_id
    cursor.execute(f"""
sqlite3.IntegrityError: UNIQUE constraint failed: articles.id

[Fri Mar 29 16:37:57 2024] Problem with adding article with id = W2513624866
Traceback (most recent call last):
  File "/home/george/Документы/harddrive/articles-analysis/programs/downloading_referenced_works.py", line 383, in download_work_by_id
    cursor.execute(f"""
sqlite3.IntegrityError: UNIQUE constraint failed: articles.id

[Fri Mar 29 16:37:57 2024] Problem with adding article with id = W2501079829
Traceback (most recent call last):
  File "/home/george/Документы/harddrive/articles-analysis/programs/downloading_referenced_works.py", line 383, in download_work_by_id
    cursor.execute(f"""
sqlite3.IntegrityError: UNIQUE constraint failed: articles.id

[Fri Mar 29 16:37:58 2024] Problem with adding article with id = W2982141910
Traceback (most recent call last):
  File "/home/george/Документы/harddrive/articles-analysis/programs/downloading_referenced_works.py", line 383, in download_work_by_id
    cursor.execute(f"""
sqlite3.IntegrityError: UNIQUE constraint failed: articles.id

[Fri Mar 29 16:37:58 2024] Problem with adding article with id = W2484638082
Traceback (most recent call last):
  File "/home/george/Документы/harddrive/articles-analysis/programs/downloading_referenced_works.py", line 383, in download_work_by_id
    cursor.execute(f"""
sqlite3.IntegrityError: UNIQUE constraint failed: articles.id

[Fri Mar 29 16:37:58 2024] Problem with adding article with id = W1993647687
Traceback (most recent call last):
  File "/home/george/Документы/harddrive/articles-analysis/programs/downloading_referenced_works.py", line 383, in download_work_by_id
    cursor.execute(f"""
sqlite3.IntegrityError: UNIQUE constraint failed: articles.id

[Fri Mar 29 16:37:58 2024] Problem with adding article with id = W2326720652
Traceback (most recent call last):
  File "/home/george/Документы/harddrive/articles-analysis/programs/downloading_referenced_works.py", line 383, in download_work_by_id
    cursor.execute(f"""
sqlite3.IntegrityError: UNIQUE constraint failed: articles.id

[Fri Mar 29 16:37:59 2024] Problem with adding article with id = W2999932758
Traceback (most recent call last):
  File "/home/george/Документы/harddrive/articles-analysis/programs/downloading_referenced_works.py", line 383, in download_work_by_id
    cursor.execute(f"""
sqlite3.IntegrityError: UNIQUE constraint failed: articles.id

[Fri Mar 29 16:37:59 2024] Problem with adding article with id = W2579051612
Traceback (most recent call last):
  File "/home/george/Документы/harddrive/articles-analysis/programs/downloading_referenced_works.py", line 383, in download_work_by_id
    cursor.execute(f"""
sqlite3.IntegrityError: UNIQUE constraint failed: articles.id

[Fri Mar 29 16:37:59 2024] Problem with getting article with id = W1577677458
Traceback (most recent call last):
  File "/home/george/Документы/harddrive/articles-analysis/programs/downloading_referenced_works.py", line 357, in download_work_by_id
    work = Works()[id_]
  File "/usr/local/lib/python3.10/dist-packages/pyalex/api.py", line 225, in __getitem__
    return self._get_from_url(
  File "/usr/local/lib/python3.10/dist-packages/pyalex/api.py", line 267, in _get_from_url
    res.raise_for_status()
  File "/usr/lib/python3/dist-packages/requests/models.py", line 943, in raise_for_status
    raise HTTPError(http_error_msg, response=self)
requests.exceptions.HTTPError: 404 Client Error: NOT FOUND for url: https://api.openalex.org/works/W1577677458

[Fri Mar 29 16:37:59 2024] Problem with adding article with id = W151371647
Traceback (most recent call last):
  File "/home/george/Документы/harddrive/articles-analysis/programs/downloading_referenced_works.py", line 383, in download_work_by_id
    cursor.execute(f"""
sqlite3.IntegrityError: UNIQUE constraint failed: articles.id

[Fri Mar 29 16:38:00 2024] Problem with adding article with id = W3111982893
Traceback (most recent call last):
  File "/home/george/Документы/harddrive/articles-analysis/programs/downloading_referenced_works.py", line 383, in download_work_by_id
    cursor.execute(f"""
sqlite3.IntegrityError: UNIQUE constraint failed: articles.id

[Fri Mar 29 16:38:00 2024] Problem with adding article with id = W2183457235
Traceback (most recent call last):
  File "/home/george/Документы/harddrive/articles-analysis/programs/downloading_referenced_works.py", line 383, in download_work_by_id
    cursor.execute(f"""
sqlite3.IntegrityError: UNIQUE constraint failed: articles.id

[Fri Mar 29 16:38:00 2024] Problem with adding article with id = W2124945130
Traceback (most recent call last):
  File "/home/george/Документы/harddrive/articles-analysis/programs/downloading_referenced_works.py", line 383, in download_work_by_id
    cursor.execute(f"""
sqlite3.IntegrityError: UNIQUE constraint failed: articles.id

[Fri Mar 29 16:38:00 2024] Problem with adding article with id = W2527474788
Traceback (most recent call last):
  File "/home/george/Документы/harddrive/articles-analysis/programs/downloading_referenced_works.py", line 383, in download_work_by_id
    cursor.execute(f"""
sqlite3.IntegrityError: UNIQUE constraint failed: articles.id

[Fri Mar 29 16:38:01 2024] Problem with adding article with id = W1972301574
Traceback (most recent call last):
  File "/home/george/Документы/harddrive/articles-analysis/programs/downloading_referenced_works.py", line 383, in download_work_by_id
    cursor.execute(f"""
sqlite3.IntegrityError: UNIQUE constraint failed: articles.id

[Fri Mar 29 16:38:01 2024] Problem with adding article with id = W1982646440
Traceback (most recent call last):
  File "/home/george/Документы/harddrive/articles-analysis/programs/downloading_referenced_works.py", line 383, in download_work_by_id
    cursor.execute(f"""
sqlite3.IntegrityError: UNIQUE constraint failed: articles.id

[Fri Mar 29 16:38:01 2024] Problem with adding article with id = W2336149088
Traceback (most recent call last):
  File "/home/george/Документы/harddrive/articles-analysis/programs/downloading_referenced_works.py", line 383, in download_work_by_id
    cursor.execute(f"""
sqlite3.IntegrityError: UNIQUE constraint failed: articles.id

[Fri Mar 29 16:38:02 2024] Problem with adding article with id = W3141088523
Traceback (most recent call last):
  File "/home/george/Документы/harddrive/articles-analysis/programs/downloading_referenced_works.py", line 383, in download_work_by_id
    cursor.execute(f"""
sqlite3.IntegrityError: UNIQUE constraint failed: articles.id

[Fri Mar 29 16:38:02 2024] Problem with getting article with id = W2134938943
Traceback (most recent call last):
  File "/home/george/Документы/harddrive/articles-analysis/programs/downloading_referenced_works.py", line 357, in download_work_by_id
    work = Works()[id_]
  File "/usr/local/lib/python3.10/dist-packages/pyalex/api.py", line 225, in __getitem__
    return self._get_from_url(
  File "/usr/local/lib/python3.10/dist-packages/pyalex/api.py", line 267, in _get_from_url
    res.raise_for_status()
  File "/usr/lib/python3/dist-packages/requests/models.py", line 943, in raise_for_status
    raise HTTPError(http_error_msg, response=self)
requests.exceptions.HTTPError: 404 Client Error: NOT FOUND for url: https://api.openalex.org/works/W2134938943

[Fri Mar 29 16:38:02 2024] Problem with adding article with id = W2571924100
Traceback (most recent call last):
  File "/home/george/Документы/harddrive/articles-analysis/programs/downloading_referenced_works.py", line 383, in download_work_by_id
    cursor.execute(f"""
sqlite3.IntegrityError: UNIQUE constraint failed: articles.id

[Fri Mar 29 16:38:02 2024] Problem with getting article with id = W2163749592
Traceback (most recent call last):
  File "/home/george/Документы/harddrive/articles-analysis/programs/downloading_referenced_works.py", line 357, in download_work_by_id
    work = Works()[id_]
  File "/usr/local/lib/python3.10/dist-packages/pyalex/api.py", line 225, in __getitem__
    return self._get_from_url(
  File "/usr/local/lib/python3.10/dist-packages/pyalex/api.py", line 267, in _get_from_url
    res.raise_for_status()
  File "/usr/lib/python3/dist-packages/requests/models.py", line 943, in raise_for_status
    raise HTTPError(http_error_msg, response=self)
requests.exceptions.HTTPError: 404 Client Error: NOT FOUND for url: https://api.openalex.org/works/W2163749592

[Fri Mar 29 16:38:02 2024] Problem with adding article with id = W2522660690
Traceback (most recent call last):
  File "/home/george/Документы/harddrive/articles-analysis/programs/downloading_referenced_works.py", line 383, in download_work_by_id
    cursor.execute(f"""
sqlite3.IntegrityError: UNIQUE constraint failed: articles.id

[Fri Mar 29 16:38:03 2024] Problem with adding article with id = W2372458883
Traceback (most recent call last):
  File "/home/george/Документы/harddrive/articles-analysis/programs/downloading_referenced_works.py", line 383, in download_work_by_id
    cursor.execute(f"""
sqlite3.IntegrityError: UNIQUE constraint failed: articles.id

[Fri Mar 29 16:38:03 2024] Problem with getting article with id = W2125203621
Traceback (most recent call last):
  File "/home/george/Документы/harddrive/articles-analysis/programs/downloading_referenced_works.py", line 357, in download_work_by_id
    work = Works()[id_]
  File "/usr/local/lib/python3.10/dist-packages/pyalex/api.py", line 225, in __getitem__
    return self._get_from_url(
  File "/usr/local/lib/python3.10/dist-packages/pyalex/api.py", line 267, in _get_from_url
    res.raise_for_status()
  File "/usr/lib/python3/dist-packages/requests/models.py", line 943, in raise_for_status
    raise HTTPError(http_error_msg, response=self)
requests.exceptions.HTTPError: 404 Client Error: NOT FOUND for url: https://api.openalex.org/works/W2125203621

[Fri Mar 29 16:38:03 2024] Problem with adding article with id = W2950272449
Traceback (most recent call last):
  File "/home/george/Документы/harddrive/articles-analysis/programs/downloading_referenced_works.py", line 383, in download_work_by_id
    cursor.execute(f"""
sqlite3.IntegrityError: UNIQUE constraint failed: articles.id

[Fri Mar 29 16:38:04 2024] Problem with adding article with id = W2517496203
Traceback (most recent call last):
  File "/home/george/Документы/harddrive/articles-analysis/programs/downloading_referenced_works.py", line 383, in download_work_by_id
    cursor.execute(f"""
sqlite3.IntegrityError: UNIQUE constraint failed: articles.id

[Fri Mar 29 16:38:04 2024] Problem with adding article with id = W2469949535
Traceback (most recent call last):
  File "/home/george/Документы/harddrive/articles-analysis/programs/downloading_referenced_works.py", line 383, in download_work_by_id
    cursor.execute(f"""
sqlite3.IntegrityError: UNIQUE constraint failed: articles.id

[Fri Mar 29 16:38:04 2024] Problem with getting article with id = W2273810905
Traceback (most recent call last):
  File "/home/george/Документы/harddrive/articles-analysis/programs/downloading_referenced_works.py", line 357, in download_work_by_id
    work = Works()[id_]
  File "/usr/local/lib/python3.10/dist-packages/pyalex/api.py", line 225, in __getitem__
    return self._get_from_url(
  File "/usr/local/lib/python3.10/dist-packages/pyalex/api.py", line 267, in _get_from_url
    res.raise_for_status()
  File "/usr/lib/python3/dist-packages/requests/models.py", line 943, in raise_for_status
    raise HTTPError(http_error_msg, response=self)
requests.exceptions.HTTPError: 404 Client Error: NOT FOUND for url: https://api.openalex.org/works/W2273810905

[Fri Mar 29 16:38:05 2024] Problem with adding article with id = W1963911648
Traceback (most recent call last):
  File "/home/george/Документы/harddrive/articles-analysis/programs/downloading_referenced_works.py", line 383, in download_work_by_id
    cursor.execute(f"""
sqlite3.IntegrityError: UNIQUE constraint failed: articles.id

[Fri Mar 29 16:38:05 2024] Problem with adding article with id = W2509086513
Traceback (most recent call last):
  File "/home/george/Документы/harddrive/articles-analysis/programs/downloading_referenced_works.py", line 383, in download_work_by_id
    cursor.execute(f"""
sqlite3.IntegrityError: UNIQUE constraint failed: articles.id

[Fri Mar 29 16:38:05 2024] Problem with getting article with id = W2132222794
Traceback (most recent call last):
  File "/home/george/Документы/harddrive/articles-analysis/programs/downloading_referenced_works.py", line 357, in download_work_by_id
    work = Works()[id_]
  File "/usr/local/lib/python3.10/dist-packages/pyalex/api.py", line 225, in __getitem__
    return self._get_from_url(
  File "/usr/local/lib/python3.10/dist-packages/pyalex/api.py", line 267, in _get_from_url
    res.raise_for_status()
  File "/usr/lib/python3/dist-packages/requests/models.py", line 943, in raise_for_status
    raise HTTPError(http_error_msg, response=self)
requests.exceptions.HTTPError: 404 Client Error: NOT FOUND for url: https://api.openalex.org/works/W2132222794

[Fri Mar 29 16:38:06 2024] Problem with adding article with id = W2047920195
Traceback (most recent call last):
  File "/home/george/Документы/harddrive/articles-analysis/programs/downloading_referenced_works.py", line 383, in download_work_by_id
    cursor.execute(f"""
sqlite3.IntegrityError: UNIQUE constraint failed: articles.id

[Fri Mar 29 16:38:06 2024] Problem with adding article with id = W2088442715
Traceback (most recent call last):
  File "/home/george/Документы/harddrive/articles-analysis/programs/downloading_referenced_works.py", line 383, in download_work_by_id
    cursor.execute(f"""
sqlite3.IntegrityError: UNIQUE constraint failed: articles.id

[Fri Mar 29 16:38:06 2024] Problem with adding article with id = W2533832761
Traceback (most recent call last):
  File "/home/george/Документы/harddrive/articles-analysis/programs/downloading_referenced_works.py", line 383, in download_work_by_id
    cursor.execute(f"""
sqlite3.IntegrityError: UNIQUE constraint failed: articles.id

[Fri Mar 29 16:38:06 2024] Problem with adding article with id = W274441265
Traceback (most recent call last):
  File "/home/george/Документы/harddrive/articles-analysis/programs/downloading_referenced_works.py", line 383, in download_work_by_id
    cursor.execute(f"""
sqlite3.IntegrityError: UNIQUE constraint failed: articles.id

[Fri Mar 29 16:38:07 2024] Problem with adding article with id = W2463375402
Traceback (most recent call last):
  File "/home/george/Документы/harddrive/articles-analysis/programs/downloading_referenced_works.py", line 383, in download_work_by_id
    cursor.execute(f"""
sqlite3.IntegrityError: UNIQUE constraint failed: articles.id

[Fri Mar 29 16:38:07 2024] Problem with adding article with id = W2129728917
Traceback (most recent call last):
  File "/home/george/Документы/harddrive/articles-analysis/programs/downloading_referenced_works.py", line 383, in download_work_by_id
    cursor.execute(f"""
sqlite3.IntegrityError: UNIQUE constraint failed: articles.id

[Fri Mar 29 16:38:07 2024] Problem with adding article with id = W2577191929
Traceback (most recent call last):
  File "/home/george/Документы/harddrive/articles-analysis/programs/downloading_referenced_works.py", line 383, in download_work_by_id
    cursor.execute(f"""
sqlite3.IntegrityError: UNIQUE constraint failed: articles.id

[Fri Mar 29 16:38:07 2024] Problem with adding article with id = W2004551127
Traceback (most recent call last):
  File "/home/george/Документы/harddrive/articles-analysis/programs/downloading_referenced_works.py", line 383, in download_work_by_id
    cursor.execute(f"""
sqlite3.IntegrityError: UNIQUE constraint failed: articles.id

[Fri Mar 29 16:38:08 2024] Problem with getting article with id = W1527317788
Traceback (most recent call last):
  File "/home/george/Документы/harddrive/articles-analysis/programs/downloading_referenced_works.py", line 357, in download_work_by_id
    work = Works()[id_]
  File "/usr/local/lib/python3.10/dist-packages/pyalex/api.py", line 225, in __getitem__
    return self._get_from_url(
  File "/usr/local/lib/python3.10/dist-packages/pyalex/api.py", line 267, in _get_from_url
    res.raise_for_status()
  File "/usr/lib/python3/dist-packages/requests/models.py", line 943, in raise_for_status
    raise HTTPError(http_error_msg, response=self)
requests.exceptions.HTTPError: 404 Client Error: NOT FOUND for url: https://api.openalex.org/works/W1527317788

[Fri Mar 29 16:38:08 2024] Problem with adding article with id = W2478845612
Traceback (most recent call last):
  File "/home/george/Документы/harddrive/articles-analysis/programs/downloading_referenced_works.py", line 383, in download_work_by_id
    cursor.execute(f"""
sqlite3.IntegrityError: UNIQUE constraint failed: articles.id

[Fri Mar 29 16:38:08 2024] Problem with adding article with id = W3009849473
Traceback (most recent call last):
  File "/home/george/Документы/harddrive/articles-analysis/programs/downloading_referenced_works.py", line 383, in download_work_by_id
    cursor.execute(f"""
sqlite3.IntegrityError: UNIQUE constraint failed: articles.id

[Fri Mar 29 16:38:08 2024] Problem with adding article with id = W3036377857
Traceback (most recent call last):
  File "/home/george/Документы/harddrive/articles-analysis/programs/downloading_referenced_works.py", line 383, in download_work_by_id
    cursor.execute(f"""
sqlite3.IntegrityError: UNIQUE constraint failed: articles.id

[Fri Mar 29 16:38:09 2024] Problem with adding article with id = W2475690250
Traceback (most recent call last):
  File "/home/george/Документы/harddrive/articles-analysis/programs/downloading_referenced_works.py", line 383, in download_work_by_id
    cursor.execute(f"""
sqlite3.IntegrityError: UNIQUE constraint failed: articles.id

[Fri Mar 29 16:38:09 2024] Problem with adding article with id = W2480363210
Traceback (most recent call last):
  File "/home/george/Документы/harddrive/articles-analysis/programs/downloading_referenced_works.py", line 383, in download_work_by_id
    cursor.execute(f"""
sqlite3.IntegrityError: UNIQUE constraint failed: articles.id

[Fri Mar 29 16:38:09 2024] Problem with adding article with id = W2511258903
Traceback (most recent call last):
  File "/home/george/Документы/harddrive/articles-analysis/programs/downloading_referenced_works.py", line 383, in download_work_by_id
    cursor.execute(f"""
sqlite3.IntegrityError: UNIQUE constraint failed: articles.id

[Fri Mar 29 16:38:10 2024] Problem with adding article with id = W2520966375
Traceback (most recent call last):
  File "/home/george/Документы/harddrive/articles-analysis/programs/downloading_referenced_works.py", line 383, in download_work_by_id
    cursor.execute(f"""
sqlite3.IntegrityError: UNIQUE constraint failed: articles.id

[Fri Mar 29 16:38:10 2024] Problem with adding article with id = W1483979954
Traceback (most recent call last):
  File "/home/george/Документы/harddrive/articles-analysis/programs/downloading_referenced_works.py", line 383, in download_work_by_id
    cursor.execute(f"""
sqlite3.IntegrityError: UNIQUE constraint failed: articles.id

[Fri Mar 29 16:38:10 2024] Problem with adding article with id = W2613753425
Traceback (most recent call last):
  File "/home/george/Документы/harddrive/articles-analysis/programs/downloading_referenced_works.py", line 383, in download_work_by_id
    cursor.execute(f"""
sqlite3.IntegrityError: UNIQUE constraint failed: articles.id

[Fri Mar 29 16:38:11 2024] Problem with adding article with id = W2473144805
Traceback (most recent call last):
  File "/home/george/Документы/harddrive/articles-analysis/programs/downloading_referenced_works.py", line 383, in download_work_by_id
    cursor.execute(f"""
sqlite3.IntegrityError: UNIQUE constraint failed: articles.id

[Fri Mar 29 16:38:11 2024] Problem with adding article with id = W3091565661
Traceback (most recent call last):
  File "/home/george/Документы/harddrive/articles-analysis/programs/downloading_referenced_works.py", line 383, in download_work_by_id
    cursor.execute(f"""
sqlite3.IntegrityError: UNIQUE constraint failed: articles.id

[Fri Mar 29 16:38:11 2024] Problem with adding article with id = W2329492296
Traceback (most recent call last):
  File "/home/george/Документы/harddrive/articles-analysis/programs/downloading_referenced_works.py", line 383, in download_work_by_id
    cursor.execute(f"""
sqlite3.IntegrityError: UNIQUE constraint failed: articles.id

[Fri Mar 29 16:38:11 2024] Problem with adding article with id = W1504778332
Traceback (most recent call last):
  File "/home/george/Документы/harddrive/articles-analysis/programs/downloading_referenced_works.py", line 383, in download_work_by_id
    cursor.execute(f"""
sqlite3.IntegrityError: UNIQUE constraint failed: articles.id

[Fri Mar 29 16:38:12 2024] Problem with adding article with id = W2497598214
Traceback (most recent call last):
  File "/home/george/Документы/harddrive/articles-analysis/programs/downloading_referenced_works.py", line 383, in download_work_by_id
    cursor.execute(f"""
sqlite3.IntegrityError: UNIQUE constraint failed: articles.id



Traceback (most recent call last):
  File "/home/george/Документы/harddrive/articles-analysis/programs/downloading_referenced_works.py", line 534, in download_ref_works
    download_works_by_ids_global(ids, level)
  File "/home/george/Документы/harddrive/articles-analysis/programs/downloading_referenced_works.py", line 453, in download_works_by_ids_global
    stopping_thread.join()
  File "/usr/lib/python3.10/threading.py", line 1096, in join
    self._wait_for_tstate_lock()
  File "/usr/lib/python3.10/threading.py", line 1116, in _wait_for_tstate_lock
    if lock.acquire(block, timeout):
KeyboardInterrupt

Restarting..
